{
 "cells": [
  {
   "cell_type": "code",
   "execution_count": 2,
   "metadata": {},
   "outputs": [],
   "source": [
    "#https://www.kaggle.com/ronitf/heart-disease-uci\n",
    "\n",
    "import gradio as gr"
   ]
  },
  {
   "cell_type": "code",
   "execution_count": 3,
   "metadata": {},
   "outputs": [
    {
     "name": "stdout",
     "output_type": "stream",
     "text": [
      "Running locally at: http://127.0.0.1:7882/\n",
      "This share link will expire in 24 hours. If you need a permanent link, visit: https://gradio.app/introducing-hosted (NEW!)\n",
      "Running on External URL: https://17280.gradio.app\n",
      "Interface loading below...\n"
     ]
    },
    {
     "data": {
      "text/html": [
       "\n",
       "        <iframe\n",
       "            width=\"900\"\n",
       "            height=\"500\"\n",
       "            src=\"https://17280.gradio.app\"\n",
       "            frameborder=\"0\"\n",
       "            allowfullscreen\n",
       "        ></iframe>\n",
       "        "
      ],
      "text/plain": [
       "<IPython.lib.display.IFrame at 0x1f17f6bd4c0>"
      ]
     },
     "metadata": {},
     "output_type": "display_data"
    },
    {
     "data": {
      "text/plain": [
       "(<Flask 'gradio.networking'>,\n",
       " 'http://127.0.0.1:7882/',\n",
       " 'https://17280.gradio.app')"
      ]
     },
     "execution_count": 3,
     "metadata": {},
     "output_type": "execute_result"
    },
    {
     "name": "stderr",
     "output_type": "stream",
     "text": [
      "[2021-09-12 11:30:19,350] ERROR in app: Exception on /api/predict/ [POST]\n",
      "Traceback (most recent call last):\n",
      "  File \"C:\\Users\\Lenovo\\anaconda3\\lib\\site-packages\\flask\\app.py\", line 2447, in wsgi_app\n",
      "    response = self.full_dispatch_request()\n",
      "  File \"C:\\Users\\Lenovo\\anaconda3\\lib\\site-packages\\flask\\app.py\", line 1952, in full_dispatch_request\n",
      "    rv = self.handle_user_exception(e)\n",
      "  File \"C:\\Users\\Lenovo\\anaconda3\\lib\\site-packages\\flask_cors\\extension.py\", line 165, in wrapped_function\n",
      "    return cors_after_request(app.make_response(f(*args, **kwargs)))\n",
      "  File \"C:\\Users\\Lenovo\\anaconda3\\lib\\site-packages\\flask\\app.py\", line 1821, in handle_user_exception\n",
      "    reraise(exc_type, exc_value, tb)\n",
      "  File \"C:\\Users\\Lenovo\\anaconda3\\lib\\site-packages\\flask\\_compat.py\", line 39, in reraise\n",
      "    raise value\n",
      "  File \"C:\\Users\\Lenovo\\anaconda3\\lib\\site-packages\\flask\\app.py\", line 1950, in full_dispatch_request\n",
      "    rv = self.dispatch_request()\n",
      "  File \"C:\\Users\\Lenovo\\anaconda3\\lib\\site-packages\\flask\\app.py\", line 1936, in dispatch_request\n",
      "    return self.view_functions[rule.endpoint](**req.view_args)\n",
      "  File \"C:\\Users\\Lenovo\\anaconda3\\lib\\site-packages\\gradio\\networking.py\", line 92, in wrapper\n",
      "    return func(*args, **kwargs)\n",
      "  File \"C:\\Users\\Lenovo\\anaconda3\\lib\\site-packages\\gradio\\networking.py\", line 180, in predict\n",
      "    prediction, durations = app.interface.process(raw_input)\n",
      "  File \"C:\\Users\\Lenovo\\anaconda3\\lib\\site-packages\\gradio\\interface.py\", line 334, in process\n",
      "    predictions, durations = self.run_prediction(processed_input, return_duration=True)\n",
      "  File \"C:\\Users\\Lenovo\\anaconda3\\lib\\site-packages\\gradio\\interface.py\", line 307, in run_prediction\n",
      "    prediction = predict_fn(*processed_input)\n",
      "  File \"<ipython-input-3-f9d94fe16654>\", line 3, in inference\n",
      "    df = pd.DataFrame([[age, s, ch, cardio]],\n",
      "NameError: name 'pd' is not defined\n",
      "[2021-09-12 11:30:19,373] ERROR in app: Exception on /api/predict/ [POST]\n",
      "Traceback (most recent call last):\n",
      "  File \"C:\\Users\\Lenovo\\anaconda3\\lib\\site-packages\\flask\\app.py\", line 2447, in wsgi_app\n",
      "    response = self.full_dispatch_request()\n",
      "  File \"C:\\Users\\Lenovo\\anaconda3\\lib\\site-packages\\flask\\app.py\", line 1952, in full_dispatch_request\n",
      "    rv = self.handle_user_exception(e)\n",
      "  File \"C:\\Users\\Lenovo\\anaconda3\\lib\\site-packages\\flask_cors\\extension.py\", line 165, in wrapped_function\n",
      "    return cors_after_request(app.make_response(f(*args, **kwargs)))\n",
      "  File \"C:\\Users\\Lenovo\\anaconda3\\lib\\site-packages\\flask\\app.py\", line 1821, in handle_user_exception\n",
      "    reraise(exc_type, exc_value, tb)\n",
      "  File \"C:\\Users\\Lenovo\\anaconda3\\lib\\site-packages\\flask\\_compat.py\", line 39, in reraise\n",
      "    raise value\n",
      "  File \"C:\\Users\\Lenovo\\anaconda3\\lib\\site-packages\\flask\\app.py\", line 1950, in full_dispatch_request\n",
      "    rv = self.dispatch_request()\n",
      "  File \"C:\\Users\\Lenovo\\anaconda3\\lib\\site-packages\\flask\\app.py\", line 1936, in dispatch_request\n",
      "    return self.view_functions[rule.endpoint](**req.view_args)\n",
      "  File \"C:\\Users\\Lenovo\\anaconda3\\lib\\site-packages\\gradio\\networking.py\", line 92, in wrapper\n",
      "    return func(*args, **kwargs)\n",
      "  File \"C:\\Users\\Lenovo\\anaconda3\\lib\\site-packages\\gradio\\networking.py\", line 180, in predict\n",
      "    prediction, durations = app.interface.process(raw_input)\n",
      "  File \"C:\\Users\\Lenovo\\anaconda3\\lib\\site-packages\\gradio\\interface.py\", line 334, in process\n",
      "    predictions, durations = self.run_prediction(processed_input, return_duration=True)\n",
      "  File \"C:\\Users\\Lenovo\\anaconda3\\lib\\site-packages\\gradio\\interface.py\", line 307, in run_prediction\n",
      "    prediction = predict_fn(*processed_input)\n",
      "  File \"<ipython-input-3-f9d94fe16654>\", line 3, in inference\n",
      "    df = pd.DataFrame([[age, s, ch, cardio]],\n",
      "NameError: name 'pd' is not defined\n",
      "[2021-09-12 11:30:19,383] ERROR in app: Exception on /api/predict/ [POST]\n",
      "Traceback (most recent call last):\n",
      "  File \"C:\\Users\\Lenovo\\anaconda3\\lib\\site-packages\\flask\\app.py\", line 2447, in wsgi_app\n",
      "    response = self.full_dispatch_request()\n",
      "  File \"C:\\Users\\Lenovo\\anaconda3\\lib\\site-packages\\flask\\app.py\", line 1952, in full_dispatch_request\n",
      "    rv = self.handle_user_exception(e)\n",
      "  File \"C:\\Users\\Lenovo\\anaconda3\\lib\\site-packages\\flask_cors\\extension.py\", line 165, in wrapped_function\n",
      "    return cors_after_request(app.make_response(f(*args, **kwargs)))\n",
      "  File \"C:\\Users\\Lenovo\\anaconda3\\lib\\site-packages\\flask\\app.py\", line 1821, in handle_user_exception\n",
      "    reraise(exc_type, exc_value, tb)\n",
      "  File \"C:\\Users\\Lenovo\\anaconda3\\lib\\site-packages\\flask\\_compat.py\", line 39, in reraise\n",
      "    raise value\n",
      "  File \"C:\\Users\\Lenovo\\anaconda3\\lib\\site-packages\\flask\\app.py\", line 1950, in full_dispatch_request\n",
      "    rv = self.dispatch_request()\n",
      "  File \"C:\\Users\\Lenovo\\anaconda3\\lib\\site-packages\\flask\\app.py\", line 1936, in dispatch_request\n",
      "    return self.view_functions[rule.endpoint](**req.view_args)\n",
      "  File \"C:\\Users\\Lenovo\\anaconda3\\lib\\site-packages\\gradio\\networking.py\", line 92, in wrapper\n",
      "    return func(*args, **kwargs)\n",
      "  File \"C:\\Users\\Lenovo\\anaconda3\\lib\\site-packages\\gradio\\networking.py\", line 180, in predict\n",
      "    prediction, durations = app.interface.process(raw_input)\n",
      "  File \"C:\\Users\\Lenovo\\anaconda3\\lib\\site-packages\\gradio\\interface.py\", line 334, in process\n",
      "    predictions, durations = self.run_prediction(processed_input, return_duration=True)\n",
      "  File \"C:\\Users\\Lenovo\\anaconda3\\lib\\site-packages\\gradio\\interface.py\", line 307, in run_prediction\n",
      "    prediction = predict_fn(*processed_input)\n",
      "  File \"<ipython-input-3-f9d94fe16654>\", line 3, in inference\n",
      "    df = pd.DataFrame([[age, s, ch, cardio]],\n",
      "NameError: name 'pd' is not defined\n",
      "[2021-09-12 11:30:19,390] ERROR in app: Exception on /api/predict/ [POST]\n",
      "Traceback (most recent call last):\n",
      "  File \"C:\\Users\\Lenovo\\anaconda3\\lib\\site-packages\\flask\\app.py\", line 2447, in wsgi_app\n",
      "    response = self.full_dispatch_request()\n",
      "  File \"C:\\Users\\Lenovo\\anaconda3\\lib\\site-packages\\flask\\app.py\", line 1952, in full_dispatch_request\n",
      "    rv = self.handle_user_exception(e)\n",
      "  File \"C:\\Users\\Lenovo\\anaconda3\\lib\\site-packages\\flask_cors\\extension.py\", line 165, in wrapped_function\n",
      "    return cors_after_request(app.make_response(f(*args, **kwargs)))\n",
      "  File \"C:\\Users\\Lenovo\\anaconda3\\lib\\site-packages\\flask\\app.py\", line 1821, in handle_user_exception\n",
      "    reraise(exc_type, exc_value, tb)\n",
      "  File \"C:\\Users\\Lenovo\\anaconda3\\lib\\site-packages\\flask\\_compat.py\", line 39, in reraise\n",
      "    raise value\n",
      "  File \"C:\\Users\\Lenovo\\anaconda3\\lib\\site-packages\\flask\\app.py\", line 1950, in full_dispatch_request\n",
      "    rv = self.dispatch_request()\n",
      "  File \"C:\\Users\\Lenovo\\anaconda3\\lib\\site-packages\\flask\\app.py\", line 1936, in dispatch_request\n",
      "    return self.view_functions[rule.endpoint](**req.view_args)\n",
      "  File \"C:\\Users\\Lenovo\\anaconda3\\lib\\site-packages\\gradio\\networking.py\", line 92, in wrapper\n",
      "    return func(*args, **kwargs)\n",
      "  File \"C:\\Users\\Lenovo\\anaconda3\\lib\\site-packages\\gradio\\networking.py\", line 180, in predict\n",
      "    prediction, durations = app.interface.process(raw_input)\n",
      "  File \"C:\\Users\\Lenovo\\anaconda3\\lib\\site-packages\\gradio\\interface.py\", line 334, in process\n",
      "    predictions, durations = self.run_prediction(processed_input, return_duration=True)\n",
      "  File \"C:\\Users\\Lenovo\\anaconda3\\lib\\site-packages\\gradio\\interface.py\", line 307, in run_prediction\n",
      "    prediction = predict_fn(*processed_input)\n",
      "  File \"<ipython-input-3-f9d94fe16654>\", line 3, in inference\n",
      "    df = pd.DataFrame([[age, s, ch, cardio]],\n",
      "NameError: name 'pd' is not defined\n",
      "[2021-09-12 11:30:19,397] ERROR in app: Exception on /api/predict/ [POST]\n",
      "Traceback (most recent call last):\n",
      "  File \"C:\\Users\\Lenovo\\anaconda3\\lib\\site-packages\\flask\\app.py\", line 2447, in wsgi_app\n",
      "    response = self.full_dispatch_request()\n",
      "  File \"C:\\Users\\Lenovo\\anaconda3\\lib\\site-packages\\flask\\app.py\", line 1952, in full_dispatch_request\n",
      "    rv = self.handle_user_exception(e)\n",
      "  File \"C:\\Users\\Lenovo\\anaconda3\\lib\\site-packages\\flask_cors\\extension.py\", line 165, in wrapped_function\n",
      "    return cors_after_request(app.make_response(f(*args, **kwargs)))\n",
      "  File \"C:\\Users\\Lenovo\\anaconda3\\lib\\site-packages\\flask\\app.py\", line 1821, in handle_user_exception\n",
      "    reraise(exc_type, exc_value, tb)\n",
      "  File \"C:\\Users\\Lenovo\\anaconda3\\lib\\site-packages\\flask\\_compat.py\", line 39, in reraise\n",
      "    raise value\n",
      "  File \"C:\\Users\\Lenovo\\anaconda3\\lib\\site-packages\\flask\\app.py\", line 1950, in full_dispatch_request\n",
      "    rv = self.dispatch_request()\n",
      "  File \"C:\\Users\\Lenovo\\anaconda3\\lib\\site-packages\\flask\\app.py\", line 1936, in dispatch_request\n",
      "    return self.view_functions[rule.endpoint](**req.view_args)\n",
      "  File \"C:\\Users\\Lenovo\\anaconda3\\lib\\site-packages\\gradio\\networking.py\", line 92, in wrapper\n",
      "    return func(*args, **kwargs)\n",
      "  File \"C:\\Users\\Lenovo\\anaconda3\\lib\\site-packages\\gradio\\networking.py\", line 180, in predict\n",
      "    prediction, durations = app.interface.process(raw_input)\n",
      "  File \"C:\\Users\\Lenovo\\anaconda3\\lib\\site-packages\\gradio\\interface.py\", line 334, in process\n",
      "    predictions, durations = self.run_prediction(processed_input, return_duration=True)\n",
      "  File \"C:\\Users\\Lenovo\\anaconda3\\lib\\site-packages\\gradio\\interface.py\", line 307, in run_prediction\n",
      "    prediction = predict_fn(*processed_input)\n",
      "  File \"<ipython-input-3-f9d94fe16654>\", line 3, in inference\n",
      "    df = pd.DataFrame([[age, s, ch, cardio]],\n",
      "NameError: name 'pd' is not defined\n"
     ]
    },
    {
     "name": "stderr",
     "output_type": "stream",
     "text": [
      "[2021-09-12 11:30:19,415] ERROR in app: Exception on /api/predict/ [POST]\n",
      "Traceback (most recent call last):\n",
      "  File \"C:\\Users\\Lenovo\\anaconda3\\lib\\site-packages\\flask\\app.py\", line 2447, in wsgi_app\n",
      "    response = self.full_dispatch_request()\n",
      "  File \"C:\\Users\\Lenovo\\anaconda3\\lib\\site-packages\\flask\\app.py\", line 1952, in full_dispatch_request\n",
      "    rv = self.handle_user_exception(e)\n",
      "  File \"C:\\Users\\Lenovo\\anaconda3\\lib\\site-packages\\flask_cors\\extension.py\", line 165, in wrapped_function\n",
      "    return cors_after_request(app.make_response(f(*args, **kwargs)))\n",
      "  File \"C:\\Users\\Lenovo\\anaconda3\\lib\\site-packages\\flask\\app.py\", line 1821, in handle_user_exception\n",
      "    reraise(exc_type, exc_value, tb)\n",
      "  File \"C:\\Users\\Lenovo\\anaconda3\\lib\\site-packages\\flask\\_compat.py\", line 39, in reraise\n",
      "    raise value\n",
      "  File \"C:\\Users\\Lenovo\\anaconda3\\lib\\site-packages\\flask\\app.py\", line 1950, in full_dispatch_request\n",
      "    rv = self.dispatch_request()\n",
      "  File \"C:\\Users\\Lenovo\\anaconda3\\lib\\site-packages\\flask\\app.py\", line 1936, in dispatch_request\n",
      "    return self.view_functions[rule.endpoint](**req.view_args)\n",
      "  File \"C:\\Users\\Lenovo\\anaconda3\\lib\\site-packages\\gradio\\networking.py\", line 92, in wrapper\n",
      "    return func(*args, **kwargs)\n",
      "  File \"C:\\Users\\Lenovo\\anaconda3\\lib\\site-packages\\gradio\\networking.py\", line 180, in predict\n",
      "    prediction, durations = app.interface.process(raw_input)\n",
      "  File \"C:\\Users\\Lenovo\\anaconda3\\lib\\site-packages\\gradio\\interface.py\", line 334, in process\n",
      "    predictions, durations = self.run_prediction(processed_input, return_duration=True)\n",
      "  File \"C:\\Users\\Lenovo\\anaconda3\\lib\\site-packages\\gradio\\interface.py\", line 307, in run_prediction\n",
      "    prediction = predict_fn(*processed_input)\n",
      "  File \"<ipython-input-3-f9d94fe16654>\", line 3, in inference\n",
      "    df = pd.DataFrame([[age, s, ch, cardio]],\n",
      "NameError: name 'pd' is not defined\n",
      "[2021-09-12 11:30:19,425] ERROR in app: Exception on /api/predict/ [POST]\n",
      "Traceback (most recent call last):\n",
      "  File \"C:\\Users\\Lenovo\\anaconda3\\lib\\site-packages\\flask\\app.py\", line 2447, in wsgi_app\n",
      "    response = self.full_dispatch_request()\n",
      "  File \"C:\\Users\\Lenovo\\anaconda3\\lib\\site-packages\\flask\\app.py\", line 1952, in full_dispatch_request\n",
      "    rv = self.handle_user_exception(e)\n",
      "  File \"C:\\Users\\Lenovo\\anaconda3\\lib\\site-packages\\flask_cors\\extension.py\", line 165, in wrapped_function\n",
      "    return cors_after_request(app.make_response(f(*args, **kwargs)))\n",
      "  File \"C:\\Users\\Lenovo\\anaconda3\\lib\\site-packages\\flask\\app.py\", line 1821, in handle_user_exception\n",
      "    reraise(exc_type, exc_value, tb)\n",
      "  File \"C:\\Users\\Lenovo\\anaconda3\\lib\\site-packages\\flask\\_compat.py\", line 39, in reraise\n",
      "    raise value\n",
      "  File \"C:\\Users\\Lenovo\\anaconda3\\lib\\site-packages\\flask\\app.py\", line 1950, in full_dispatch_request\n",
      "    rv = self.dispatch_request()\n",
      "  File \"C:\\Users\\Lenovo\\anaconda3\\lib\\site-packages\\flask\\app.py\", line 1936, in dispatch_request\n",
      "    return self.view_functions[rule.endpoint](**req.view_args)\n",
      "  File \"C:\\Users\\Lenovo\\anaconda3\\lib\\site-packages\\gradio\\networking.py\", line 92, in wrapper\n",
      "    return func(*args, **kwargs)\n",
      "  File \"C:\\Users\\Lenovo\\anaconda3\\lib\\site-packages\\gradio\\networking.py\", line 180, in predict\n",
      "    prediction, durations = app.interface.process(raw_input)\n",
      "  File \"C:\\Users\\Lenovo\\anaconda3\\lib\\site-packages\\gradio\\interface.py\", line 334, in process\n",
      "    predictions, durations = self.run_prediction(processed_input, return_duration=True)\n",
      "  File \"C:\\Users\\Lenovo\\anaconda3\\lib\\site-packages\\gradio\\interface.py\", line 307, in run_prediction\n",
      "    prediction = predict_fn(*processed_input)\n",
      "  File \"<ipython-input-3-f9d94fe16654>\", line 3, in inference\n",
      "    df = pd.DataFrame([[age, s, ch, cardio]],\n",
      "NameError: name 'pd' is not defined\n",
      "[2021-09-12 11:30:19,446] ERROR in app: Exception on /api/predict/ [POST]\n",
      "Traceback (most recent call last):\n",
      "  File \"C:\\Users\\Lenovo\\anaconda3\\lib\\site-packages\\flask\\app.py\", line 2447, in wsgi_app\n",
      "    response = self.full_dispatch_request()\n",
      "  File \"C:\\Users\\Lenovo\\anaconda3\\lib\\site-packages\\flask\\app.py\", line 1952, in full_dispatch_request\n",
      "    rv = self.handle_user_exception(e)\n",
      "  File \"C:\\Users\\Lenovo\\anaconda3\\lib\\site-packages\\flask_cors\\extension.py\", line 165, in wrapped_function\n",
      "    return cors_after_request(app.make_response(f(*args, **kwargs)))\n",
      "  File \"C:\\Users\\Lenovo\\anaconda3\\lib\\site-packages\\flask\\app.py\", line 1821, in handle_user_exception\n",
      "    reraise(exc_type, exc_value, tb)\n",
      "  File \"C:\\Users\\Lenovo\\anaconda3\\lib\\site-packages\\flask\\_compat.py\", line 39, in reraise\n",
      "    raise value\n",
      "  File \"C:\\Users\\Lenovo\\anaconda3\\lib\\site-packages\\flask\\app.py\", line 1950, in full_dispatch_request\n",
      "    rv = self.dispatch_request()\n",
      "  File \"C:\\Users\\Lenovo\\anaconda3\\lib\\site-packages\\flask\\app.py\", line 1936, in dispatch_request\n",
      "    return self.view_functions[rule.endpoint](**req.view_args)\n",
      "  File \"C:\\Users\\Lenovo\\anaconda3\\lib\\site-packages\\gradio\\networking.py\", line 92, in wrapper\n",
      "    return func(*args, **kwargs)\n",
      "  File \"C:\\Users\\Lenovo\\anaconda3\\lib\\site-packages\\gradio\\networking.py\", line 180, in predict\n",
      "    prediction, durations = app.interface.process(raw_input)\n",
      "  File \"C:\\Users\\Lenovo\\anaconda3\\lib\\site-packages\\gradio\\interface.py\", line 334, in process\n",
      "    predictions, durations = self.run_prediction(processed_input, return_duration=True)\n",
      "  File \"C:\\Users\\Lenovo\\anaconda3\\lib\\site-packages\\gradio\\interface.py\", line 307, in run_prediction\n",
      "    prediction = predict_fn(*processed_input)\n",
      "  File \"<ipython-input-3-f9d94fe16654>\", line 3, in inference\n",
      "    df = pd.DataFrame([[age, s, ch, cardio]],\n",
      "NameError: name 'pd' is not defined\n",
      "[2021-09-12 11:30:19,466] ERROR in app: Exception on /api/predict/ [POST]\n",
      "Traceback (most recent call last):\n",
      "  File \"C:\\Users\\Lenovo\\anaconda3\\lib\\site-packages\\flask\\app.py\", line 2447, in wsgi_app\n",
      "    response = self.full_dispatch_request()\n",
      "  File \"C:\\Users\\Lenovo\\anaconda3\\lib\\site-packages\\flask\\app.py\", line 1952, in full_dispatch_request\n",
      "    rv = self.handle_user_exception(e)\n",
      "  File \"C:\\Users\\Lenovo\\anaconda3\\lib\\site-packages\\flask_cors\\extension.py\", line 165, in wrapped_function\n",
      "    return cors_after_request(app.make_response(f(*args, **kwargs)))\n",
      "  File \"C:\\Users\\Lenovo\\anaconda3\\lib\\site-packages\\flask\\app.py\", line 1821, in handle_user_exception\n",
      "    reraise(exc_type, exc_value, tb)\n",
      "  File \"C:\\Users\\Lenovo\\anaconda3\\lib\\site-packages\\flask\\_compat.py\", line 39, in reraise\n",
      "    raise value\n",
      "  File \"C:\\Users\\Lenovo\\anaconda3\\lib\\site-packages\\flask\\app.py\", line 1950, in full_dispatch_request\n",
      "    rv = self.dispatch_request()\n",
      "  File \"C:\\Users\\Lenovo\\anaconda3\\lib\\site-packages\\flask\\app.py\", line 1936, in dispatch_request\n",
      "    return self.view_functions[rule.endpoint](**req.view_args)\n",
      "  File \"C:\\Users\\Lenovo\\anaconda3\\lib\\site-packages\\gradio\\networking.py\", line 92, in wrapper\n",
      "    return func(*args, **kwargs)\n",
      "  File \"C:\\Users\\Lenovo\\anaconda3\\lib\\site-packages\\gradio\\networking.py\", line 180, in predict\n",
      "    prediction, durations = app.interface.process(raw_input)\n",
      "  File \"C:\\Users\\Lenovo\\anaconda3\\lib\\site-packages\\gradio\\interface.py\", line 334, in process\n",
      "    predictions, durations = self.run_prediction(processed_input, return_duration=True)\n",
      "  File \"C:\\Users\\Lenovo\\anaconda3\\lib\\site-packages\\gradio\\interface.py\", line 307, in run_prediction\n",
      "    prediction = predict_fn(*processed_input)\n",
      "  File \"<ipython-input-3-f9d94fe16654>\", line 3, in inference\n",
      "    df = pd.DataFrame([[age, s, ch, cardio]],\n",
      "NameError: name 'pd' is not defined\n",
      "[2021-09-12 11:30:19,473] ERROR in app: Exception on /api/predict/ [POST]\n",
      "Traceback (most recent call last):\n",
      "  File \"C:\\Users\\Lenovo\\anaconda3\\lib\\site-packages\\flask\\app.py\", line 2447, in wsgi_app\n",
      "    response = self.full_dispatch_request()\n",
      "  File \"C:\\Users\\Lenovo\\anaconda3\\lib\\site-packages\\flask\\app.py\", line 1952, in full_dispatch_request\n",
      "    rv = self.handle_user_exception(e)\n",
      "  File \"C:\\Users\\Lenovo\\anaconda3\\lib\\site-packages\\flask_cors\\extension.py\", line 165, in wrapped_function\n",
      "    return cors_after_request(app.make_response(f(*args, **kwargs)))\n",
      "  File \"C:\\Users\\Lenovo\\anaconda3\\lib\\site-packages\\flask\\app.py\", line 1821, in handle_user_exception\n",
      "    reraise(exc_type, exc_value, tb)\n",
      "  File \"C:\\Users\\Lenovo\\anaconda3\\lib\\site-packages\\flask\\_compat.py\", line 39, in reraise\n",
      "    raise value\n",
      "  File \"C:\\Users\\Lenovo\\anaconda3\\lib\\site-packages\\flask\\app.py\", line 1950, in full_dispatch_request\n",
      "    rv = self.dispatch_request()\n",
      "  File \"C:\\Users\\Lenovo\\anaconda3\\lib\\site-packages\\flask\\app.py\", line 1936, in dispatch_request\n",
      "    return self.view_functions[rule.endpoint](**req.view_args)\n",
      "  File \"C:\\Users\\Lenovo\\anaconda3\\lib\\site-packages\\gradio\\networking.py\", line 92, in wrapper\n",
      "    return func(*args, **kwargs)\n",
      "  File \"C:\\Users\\Lenovo\\anaconda3\\lib\\site-packages\\gradio\\networking.py\", line 180, in predict\n",
      "    prediction, durations = app.interface.process(raw_input)\n",
      "  File \"C:\\Users\\Lenovo\\anaconda3\\lib\\site-packages\\gradio\\interface.py\", line 334, in process\n",
      "    predictions, durations = self.run_prediction(processed_input, return_duration=True)\n",
      "  File \"C:\\Users\\Lenovo\\anaconda3\\lib\\site-packages\\gradio\\interface.py\", line 307, in run_prediction\n",
      "    prediction = predict_fn(*processed_input)\n",
      "  File \"<ipython-input-3-f9d94fe16654>\", line 3, in inference\n",
      "    df = pd.DataFrame([[age, s, ch, cardio]],\n",
      "NameError: name 'pd' is not defined\n"
     ]
    },
    {
     "name": "stderr",
     "output_type": "stream",
     "text": [
      "[2021-09-12 11:30:19,480] ERROR in app: Exception on /api/predict/ [POST]\n",
      "Traceback (most recent call last):\n",
      "  File \"C:\\Users\\Lenovo\\anaconda3\\lib\\site-packages\\flask\\app.py\", line 2447, in wsgi_app\n",
      "    response = self.full_dispatch_request()\n",
      "  File \"C:\\Users\\Lenovo\\anaconda3\\lib\\site-packages\\flask\\app.py\", line 1952, in full_dispatch_request\n",
      "    rv = self.handle_user_exception(e)\n",
      "  File \"C:\\Users\\Lenovo\\anaconda3\\lib\\site-packages\\flask_cors\\extension.py\", line 165, in wrapped_function\n",
      "    return cors_after_request(app.make_response(f(*args, **kwargs)))\n",
      "  File \"C:\\Users\\Lenovo\\anaconda3\\lib\\site-packages\\flask\\app.py\", line 1821, in handle_user_exception\n",
      "    reraise(exc_type, exc_value, tb)\n",
      "  File \"C:\\Users\\Lenovo\\anaconda3\\lib\\site-packages\\flask\\_compat.py\", line 39, in reraise\n",
      "    raise value\n",
      "  File \"C:\\Users\\Lenovo\\anaconda3\\lib\\site-packages\\flask\\app.py\", line 1950, in full_dispatch_request\n",
      "    rv = self.dispatch_request()\n",
      "  File \"C:\\Users\\Lenovo\\anaconda3\\lib\\site-packages\\flask\\app.py\", line 1936, in dispatch_request\n",
      "    return self.view_functions[rule.endpoint](**req.view_args)\n",
      "  File \"C:\\Users\\Lenovo\\anaconda3\\lib\\site-packages\\gradio\\networking.py\", line 92, in wrapper\n",
      "    return func(*args, **kwargs)\n",
      "  File \"C:\\Users\\Lenovo\\anaconda3\\lib\\site-packages\\gradio\\networking.py\", line 180, in predict\n",
      "    prediction, durations = app.interface.process(raw_input)\n",
      "  File \"C:\\Users\\Lenovo\\anaconda3\\lib\\site-packages\\gradio\\interface.py\", line 334, in process\n",
      "    predictions, durations = self.run_prediction(processed_input, return_duration=True)\n",
      "  File \"C:\\Users\\Lenovo\\anaconda3\\lib\\site-packages\\gradio\\interface.py\", line 307, in run_prediction\n",
      "    prediction = predict_fn(*processed_input)\n",
      "  File \"<ipython-input-3-f9d94fe16654>\", line 3, in inference\n",
      "    df = pd.DataFrame([[age, s, ch, cardio]],\n",
      "NameError: name 'pd' is not defined\n",
      "[2021-09-12 11:30:19,487] ERROR in app: Exception on /api/predict/ [POST]\n",
      "Traceback (most recent call last):\n",
      "  File \"C:\\Users\\Lenovo\\anaconda3\\lib\\site-packages\\flask\\app.py\", line 2447, in wsgi_app\n",
      "    response = self.full_dispatch_request()\n",
      "  File \"C:\\Users\\Lenovo\\anaconda3\\lib\\site-packages\\flask\\app.py\", line 1952, in full_dispatch_request\n",
      "    rv = self.handle_user_exception(e)\n",
      "  File \"C:\\Users\\Lenovo\\anaconda3\\lib\\site-packages\\flask_cors\\extension.py\", line 165, in wrapped_function\n",
      "    return cors_after_request(app.make_response(f(*args, **kwargs)))\n",
      "  File \"C:\\Users\\Lenovo\\anaconda3\\lib\\site-packages\\flask\\app.py\", line 1821, in handle_user_exception\n",
      "    reraise(exc_type, exc_value, tb)\n",
      "  File \"C:\\Users\\Lenovo\\anaconda3\\lib\\site-packages\\flask\\_compat.py\", line 39, in reraise\n",
      "    raise value\n",
      "  File \"C:\\Users\\Lenovo\\anaconda3\\lib\\site-packages\\flask\\app.py\", line 1950, in full_dispatch_request\n",
      "    rv = self.dispatch_request()\n",
      "  File \"C:\\Users\\Lenovo\\anaconda3\\lib\\site-packages\\flask\\app.py\", line 1936, in dispatch_request\n",
      "    return self.view_functions[rule.endpoint](**req.view_args)\n",
      "  File \"C:\\Users\\Lenovo\\anaconda3\\lib\\site-packages\\gradio\\networking.py\", line 92, in wrapper\n",
      "    return func(*args, **kwargs)\n",
      "  File \"C:\\Users\\Lenovo\\anaconda3\\lib\\site-packages\\gradio\\networking.py\", line 180, in predict\n",
      "    prediction, durations = app.interface.process(raw_input)\n",
      "  File \"C:\\Users\\Lenovo\\anaconda3\\lib\\site-packages\\gradio\\interface.py\", line 334, in process\n",
      "    predictions, durations = self.run_prediction(processed_input, return_duration=True)\n",
      "  File \"C:\\Users\\Lenovo\\anaconda3\\lib\\site-packages\\gradio\\interface.py\", line 307, in run_prediction\n",
      "    prediction = predict_fn(*processed_input)\n",
      "  File \"<ipython-input-3-f9d94fe16654>\", line 3, in inference\n",
      "    df = pd.DataFrame([[age, s, ch, cardio]],\n",
      "NameError: name 'pd' is not defined\n",
      "[2021-09-12 11:30:19,494] ERROR in app: Exception on /api/predict/ [POST]\n",
      "Traceback (most recent call last):\n",
      "  File \"C:\\Users\\Lenovo\\anaconda3\\lib\\site-packages\\flask\\app.py\", line 2447, in wsgi_app\n",
      "    response = self.full_dispatch_request()\n",
      "  File \"C:\\Users\\Lenovo\\anaconda3\\lib\\site-packages\\flask\\app.py\", line 1952, in full_dispatch_request\n",
      "    rv = self.handle_user_exception(e)\n",
      "  File \"C:\\Users\\Lenovo\\anaconda3\\lib\\site-packages\\flask_cors\\extension.py\", line 165, in wrapped_function\n",
      "    return cors_after_request(app.make_response(f(*args, **kwargs)))\n",
      "  File \"C:\\Users\\Lenovo\\anaconda3\\lib\\site-packages\\flask\\app.py\", line 1821, in handle_user_exception\n",
      "    reraise(exc_type, exc_value, tb)\n",
      "  File \"C:\\Users\\Lenovo\\anaconda3\\lib\\site-packages\\flask\\_compat.py\", line 39, in reraise\n",
      "    raise value\n",
      "  File \"C:\\Users\\Lenovo\\anaconda3\\lib\\site-packages\\flask\\app.py\", line 1950, in full_dispatch_request\n",
      "    rv = self.dispatch_request()\n",
      "  File \"C:\\Users\\Lenovo\\anaconda3\\lib\\site-packages\\flask\\app.py\", line 1936, in dispatch_request\n",
      "    return self.view_functions[rule.endpoint](**req.view_args)\n",
      "  File \"C:\\Users\\Lenovo\\anaconda3\\lib\\site-packages\\gradio\\networking.py\", line 92, in wrapper\n",
      "    return func(*args, **kwargs)\n",
      "  File \"C:\\Users\\Lenovo\\anaconda3\\lib\\site-packages\\gradio\\networking.py\", line 180, in predict\n",
      "    prediction, durations = app.interface.process(raw_input)\n",
      "  File \"C:\\Users\\Lenovo\\anaconda3\\lib\\site-packages\\gradio\\interface.py\", line 334, in process\n",
      "    predictions, durations = self.run_prediction(processed_input, return_duration=True)\n",
      "  File \"C:\\Users\\Lenovo\\anaconda3\\lib\\site-packages\\gradio\\interface.py\", line 307, in run_prediction\n",
      "    prediction = predict_fn(*processed_input)\n",
      "  File \"<ipython-input-3-f9d94fe16654>\", line 3, in inference\n",
      "    df = pd.DataFrame([[age, s, ch, cardio]],\n",
      "NameError: name 'pd' is not defined\n",
      "[2021-09-12 11:30:19,501] ERROR in app: Exception on /api/predict/ [POST]\n",
      "Traceback (most recent call last):\n",
      "  File \"C:\\Users\\Lenovo\\anaconda3\\lib\\site-packages\\flask\\app.py\", line 2447, in wsgi_app\n",
      "    response = self.full_dispatch_request()\n",
      "  File \"C:\\Users\\Lenovo\\anaconda3\\lib\\site-packages\\flask\\app.py\", line 1952, in full_dispatch_request\n",
      "    rv = self.handle_user_exception(e)\n",
      "  File \"C:\\Users\\Lenovo\\anaconda3\\lib\\site-packages\\flask_cors\\extension.py\", line 165, in wrapped_function\n",
      "    return cors_after_request(app.make_response(f(*args, **kwargs)))\n",
      "  File \"C:\\Users\\Lenovo\\anaconda3\\lib\\site-packages\\flask\\app.py\", line 1821, in handle_user_exception\n",
      "    reraise(exc_type, exc_value, tb)\n",
      "  File \"C:\\Users\\Lenovo\\anaconda3\\lib\\site-packages\\flask\\_compat.py\", line 39, in reraise\n",
      "    raise value\n",
      "  File \"C:\\Users\\Lenovo\\anaconda3\\lib\\site-packages\\flask\\app.py\", line 1950, in full_dispatch_request\n",
      "    rv = self.dispatch_request()\n",
      "  File \"C:\\Users\\Lenovo\\anaconda3\\lib\\site-packages\\flask\\app.py\", line 1936, in dispatch_request\n",
      "    return self.view_functions[rule.endpoint](**req.view_args)\n",
      "  File \"C:\\Users\\Lenovo\\anaconda3\\lib\\site-packages\\gradio\\networking.py\", line 92, in wrapper\n",
      "    return func(*args, **kwargs)\n",
      "  File \"C:\\Users\\Lenovo\\anaconda3\\lib\\site-packages\\gradio\\networking.py\", line 180, in predict\n",
      "    prediction, durations = app.interface.process(raw_input)\n",
      "  File \"C:\\Users\\Lenovo\\anaconda3\\lib\\site-packages\\gradio\\interface.py\", line 334, in process\n",
      "    predictions, durations = self.run_prediction(processed_input, return_duration=True)\n",
      "  File \"C:\\Users\\Lenovo\\anaconda3\\lib\\site-packages\\gradio\\interface.py\", line 307, in run_prediction\n",
      "    prediction = predict_fn(*processed_input)\n",
      "  File \"<ipython-input-3-f9d94fe16654>\", line 3, in inference\n",
      "    df = pd.DataFrame([[age, s, ch, cardio]],\n",
      "NameError: name 'pd' is not defined\n",
      "[2021-09-12 11:30:19,515] ERROR in app: Exception on /api/predict/ [POST]\n",
      "Traceback (most recent call last):\n",
      "  File \"C:\\Users\\Lenovo\\anaconda3\\lib\\site-packages\\flask\\app.py\", line 2447, in wsgi_app\n",
      "    response = self.full_dispatch_request()\n",
      "  File \"C:\\Users\\Lenovo\\anaconda3\\lib\\site-packages\\flask\\app.py\", line 1952, in full_dispatch_request\n",
      "    rv = self.handle_user_exception(e)\n",
      "  File \"C:\\Users\\Lenovo\\anaconda3\\lib\\site-packages\\flask_cors\\extension.py\", line 165, in wrapped_function\n",
      "    return cors_after_request(app.make_response(f(*args, **kwargs)))\n",
      "  File \"C:\\Users\\Lenovo\\anaconda3\\lib\\site-packages\\flask\\app.py\", line 1821, in handle_user_exception\n",
      "    reraise(exc_type, exc_value, tb)\n",
      "  File \"C:\\Users\\Lenovo\\anaconda3\\lib\\site-packages\\flask\\_compat.py\", line 39, in reraise\n",
      "    raise value\n",
      "  File \"C:\\Users\\Lenovo\\anaconda3\\lib\\site-packages\\flask\\app.py\", line 1950, in full_dispatch_request\n",
      "    rv = self.dispatch_request()\n",
      "  File \"C:\\Users\\Lenovo\\anaconda3\\lib\\site-packages\\flask\\app.py\", line 1936, in dispatch_request\n",
      "    return self.view_functions[rule.endpoint](**req.view_args)\n",
      "  File \"C:\\Users\\Lenovo\\anaconda3\\lib\\site-packages\\gradio\\networking.py\", line 92, in wrapper\n",
      "    return func(*args, **kwargs)\n",
      "  File \"C:\\Users\\Lenovo\\anaconda3\\lib\\site-packages\\gradio\\networking.py\", line 180, in predict\n",
      "    prediction, durations = app.interface.process(raw_input)\n",
      "  File \"C:\\Users\\Lenovo\\anaconda3\\lib\\site-packages\\gradio\\interface.py\", line 334, in process\n",
      "    predictions, durations = self.run_prediction(processed_input, return_duration=True)\n",
      "  File \"C:\\Users\\Lenovo\\anaconda3\\lib\\site-packages\\gradio\\interface.py\", line 307, in run_prediction\n",
      "    prediction = predict_fn(*processed_input)\n",
      "  File \"<ipython-input-3-f9d94fe16654>\", line 3, in inference\n",
      "    df = pd.DataFrame([[age, s, ch, cardio]],\n",
      "NameError: name 'pd' is not defined\n"
     ]
    },
    {
     "name": "stderr",
     "output_type": "stream",
     "text": [
      "[2021-09-12 11:30:19,523] ERROR in app: Exception on /api/predict/ [POST]\n",
      "Traceback (most recent call last):\n",
      "  File \"C:\\Users\\Lenovo\\anaconda3\\lib\\site-packages\\flask\\app.py\", line 2447, in wsgi_app\n",
      "    response = self.full_dispatch_request()\n",
      "  File \"C:\\Users\\Lenovo\\anaconda3\\lib\\site-packages\\flask\\app.py\", line 1952, in full_dispatch_request\n",
      "    rv = self.handle_user_exception(e)\n",
      "  File \"C:\\Users\\Lenovo\\anaconda3\\lib\\site-packages\\flask_cors\\extension.py\", line 165, in wrapped_function\n",
      "    return cors_after_request(app.make_response(f(*args, **kwargs)))\n",
      "  File \"C:\\Users\\Lenovo\\anaconda3\\lib\\site-packages\\flask\\app.py\", line 1821, in handle_user_exception\n",
      "    reraise(exc_type, exc_value, tb)\n",
      "  File \"C:\\Users\\Lenovo\\anaconda3\\lib\\site-packages\\flask\\_compat.py\", line 39, in reraise\n",
      "    raise value\n",
      "  File \"C:\\Users\\Lenovo\\anaconda3\\lib\\site-packages\\flask\\app.py\", line 1950, in full_dispatch_request\n",
      "    rv = self.dispatch_request()\n",
      "  File \"C:\\Users\\Lenovo\\anaconda3\\lib\\site-packages\\flask\\app.py\", line 1936, in dispatch_request\n",
      "    return self.view_functions[rule.endpoint](**req.view_args)\n",
      "  File \"C:\\Users\\Lenovo\\anaconda3\\lib\\site-packages\\gradio\\networking.py\", line 92, in wrapper\n",
      "    return func(*args, **kwargs)\n",
      "  File \"C:\\Users\\Lenovo\\anaconda3\\lib\\site-packages\\gradio\\networking.py\", line 180, in predict\n",
      "    prediction, durations = app.interface.process(raw_input)\n",
      "  File \"C:\\Users\\Lenovo\\anaconda3\\lib\\site-packages\\gradio\\interface.py\", line 334, in process\n",
      "    predictions, durations = self.run_prediction(processed_input, return_duration=True)\n",
      "  File \"C:\\Users\\Lenovo\\anaconda3\\lib\\site-packages\\gradio\\interface.py\", line 307, in run_prediction\n",
      "    prediction = predict_fn(*processed_input)\n",
      "  File \"<ipython-input-3-f9d94fe16654>\", line 3, in inference\n",
      "    df = pd.DataFrame([[age, s, ch, cardio]],\n",
      "NameError: name 'pd' is not defined\n",
      "[2021-09-12 11:30:19,536] ERROR in app: Exception on /api/predict/ [POST]\n",
      "Traceback (most recent call last):\n",
      "  File \"C:\\Users\\Lenovo\\anaconda3\\lib\\site-packages\\flask\\app.py\", line 2447, in wsgi_app\n",
      "    response = self.full_dispatch_request()\n",
      "  File \"C:\\Users\\Lenovo\\anaconda3\\lib\\site-packages\\flask\\app.py\", line 1952, in full_dispatch_request\n",
      "    rv = self.handle_user_exception(e)\n",
      "  File \"C:\\Users\\Lenovo\\anaconda3\\lib\\site-packages\\flask_cors\\extension.py\", line 165, in wrapped_function\n",
      "    return cors_after_request(app.make_response(f(*args, **kwargs)))\n",
      "  File \"C:\\Users\\Lenovo\\anaconda3\\lib\\site-packages\\flask\\app.py\", line 1821, in handle_user_exception\n",
      "    reraise(exc_type, exc_value, tb)\n",
      "  File \"C:\\Users\\Lenovo\\anaconda3\\lib\\site-packages\\flask\\_compat.py\", line 39, in reraise\n",
      "    raise value\n",
      "  File \"C:\\Users\\Lenovo\\anaconda3\\lib\\site-packages\\flask\\app.py\", line 1950, in full_dispatch_request\n",
      "    rv = self.dispatch_request()\n",
      "  File \"C:\\Users\\Lenovo\\anaconda3\\lib\\site-packages\\flask\\app.py\", line 1936, in dispatch_request\n",
      "    return self.view_functions[rule.endpoint](**req.view_args)\n",
      "  File \"C:\\Users\\Lenovo\\anaconda3\\lib\\site-packages\\gradio\\networking.py\", line 92, in wrapper\n",
      "    return func(*args, **kwargs)\n",
      "  File \"C:\\Users\\Lenovo\\anaconda3\\lib\\site-packages\\gradio\\networking.py\", line 180, in predict\n",
      "    prediction, durations = app.interface.process(raw_input)\n",
      "  File \"C:\\Users\\Lenovo\\anaconda3\\lib\\site-packages\\gradio\\interface.py\", line 334, in process\n",
      "    predictions, durations = self.run_prediction(processed_input, return_duration=True)\n",
      "  File \"C:\\Users\\Lenovo\\anaconda3\\lib\\site-packages\\gradio\\interface.py\", line 307, in run_prediction\n",
      "    prediction = predict_fn(*processed_input)\n",
      "  File \"<ipython-input-3-f9d94fe16654>\", line 3, in inference\n",
      "    df = pd.DataFrame([[age, s, ch, cardio]],\n",
      "NameError: name 'pd' is not defined\n",
      "[2021-09-12 11:30:19,590] ERROR in app: Exception on /api/predict/ [POST]\n",
      "Traceback (most recent call last):\n",
      "  File \"C:\\Users\\Lenovo\\anaconda3\\lib\\site-packages\\flask\\app.py\", line 2447, in wsgi_app\n",
      "    response = self.full_dispatch_request()\n",
      "  File \"C:\\Users\\Lenovo\\anaconda3\\lib\\site-packages\\flask\\app.py\", line 1952, in full_dispatch_request\n",
      "    rv = self.handle_user_exception(e)\n",
      "  File \"C:\\Users\\Lenovo\\anaconda3\\lib\\site-packages\\flask_cors\\extension.py\", line 165, in wrapped_function\n",
      "    return cors_after_request(app.make_response(f(*args, **kwargs)))\n",
      "  File \"C:\\Users\\Lenovo\\anaconda3\\lib\\site-packages\\flask\\app.py\", line 1821, in handle_user_exception\n",
      "    reraise(exc_type, exc_value, tb)\n",
      "  File \"C:\\Users\\Lenovo\\anaconda3\\lib\\site-packages\\flask\\_compat.py\", line 39, in reraise\n",
      "    raise value\n",
      "  File \"C:\\Users\\Lenovo\\anaconda3\\lib\\site-packages\\flask\\app.py\", line 1950, in full_dispatch_request\n",
      "    rv = self.dispatch_request()\n",
      "  File \"C:\\Users\\Lenovo\\anaconda3\\lib\\site-packages\\flask\\app.py\", line 1936, in dispatch_request\n",
      "    return self.view_functions[rule.endpoint](**req.view_args)\n",
      "  File \"C:\\Users\\Lenovo\\anaconda3\\lib\\site-packages\\gradio\\networking.py\", line 92, in wrapper\n",
      "    return func(*args, **kwargs)\n",
      "  File \"C:\\Users\\Lenovo\\anaconda3\\lib\\site-packages\\gradio\\networking.py\", line 180, in predict\n",
      "    prediction, durations = app.interface.process(raw_input)\n",
      "  File \"C:\\Users\\Lenovo\\anaconda3\\lib\\site-packages\\gradio\\interface.py\", line 334, in process\n",
      "    predictions, durations = self.run_prediction(processed_input, return_duration=True)\n",
      "  File \"C:\\Users\\Lenovo\\anaconda3\\lib\\site-packages\\gradio\\interface.py\", line 307, in run_prediction\n",
      "    prediction = predict_fn(*processed_input)\n",
      "  File \"<ipython-input-3-f9d94fe16654>\", line 3, in inference\n",
      "    df = pd.DataFrame([[age, s, ch, cardio]],\n",
      "NameError: name 'pd' is not defined\n",
      "[2021-09-12 11:30:19,606] ERROR in app: Exception on /api/predict/ [POST]\n",
      "Traceback (most recent call last):\n",
      "  File \"C:\\Users\\Lenovo\\anaconda3\\lib\\site-packages\\flask\\app.py\", line 2447, in wsgi_app\n",
      "    response = self.full_dispatch_request()\n",
      "  File \"C:\\Users\\Lenovo\\anaconda3\\lib\\site-packages\\flask\\app.py\", line 1952, in full_dispatch_request\n",
      "    rv = self.handle_user_exception(e)\n",
      "  File \"C:\\Users\\Lenovo\\anaconda3\\lib\\site-packages\\flask_cors\\extension.py\", line 165, in wrapped_function\n",
      "    return cors_after_request(app.make_response(f(*args, **kwargs)))\n",
      "  File \"C:\\Users\\Lenovo\\anaconda3\\lib\\site-packages\\flask\\app.py\", line 1821, in handle_user_exception\n",
      "    reraise(exc_type, exc_value, tb)\n",
      "  File \"C:\\Users\\Lenovo\\anaconda3\\lib\\site-packages\\flask\\_compat.py\", line 39, in reraise\n",
      "    raise value\n",
      "  File \"C:\\Users\\Lenovo\\anaconda3\\lib\\site-packages\\flask\\app.py\", line 1950, in full_dispatch_request\n",
      "    rv = self.dispatch_request()\n",
      "  File \"C:\\Users\\Lenovo\\anaconda3\\lib\\site-packages\\flask\\app.py\", line 1936, in dispatch_request\n",
      "    return self.view_functions[rule.endpoint](**req.view_args)\n",
      "  File \"C:\\Users\\Lenovo\\anaconda3\\lib\\site-packages\\gradio\\networking.py\", line 92, in wrapper\n",
      "    return func(*args, **kwargs)\n",
      "  File \"C:\\Users\\Lenovo\\anaconda3\\lib\\site-packages\\gradio\\networking.py\", line 180, in predict\n",
      "    prediction, durations = app.interface.process(raw_input)\n",
      "  File \"C:\\Users\\Lenovo\\anaconda3\\lib\\site-packages\\gradio\\interface.py\", line 334, in process\n",
      "    predictions, durations = self.run_prediction(processed_input, return_duration=True)\n",
      "  File \"C:\\Users\\Lenovo\\anaconda3\\lib\\site-packages\\gradio\\interface.py\", line 307, in run_prediction\n",
      "    prediction = predict_fn(*processed_input)\n",
      "  File \"<ipython-input-3-f9d94fe16654>\", line 3, in inference\n",
      "    df = pd.DataFrame([[age, s, ch, cardio]],\n",
      "NameError: name 'pd' is not defined\n",
      "[2021-09-12 11:30:19,626] ERROR in app: Exception on /api/predict/ [POST]\n",
      "Traceback (most recent call last):\n",
      "  File \"C:\\Users\\Lenovo\\anaconda3\\lib\\site-packages\\flask\\app.py\", line 2447, in wsgi_app\n",
      "    response = self.full_dispatch_request()\n",
      "  File \"C:\\Users\\Lenovo\\anaconda3\\lib\\site-packages\\flask\\app.py\", line 1952, in full_dispatch_request\n",
      "    rv = self.handle_user_exception(e)\n",
      "  File \"C:\\Users\\Lenovo\\anaconda3\\lib\\site-packages\\flask_cors\\extension.py\", line 165, in wrapped_function\n",
      "    return cors_after_request(app.make_response(f(*args, **kwargs)))\n",
      "  File \"C:\\Users\\Lenovo\\anaconda3\\lib\\site-packages\\flask\\app.py\", line 1821, in handle_user_exception\n",
      "    reraise(exc_type, exc_value, tb)\n",
      "  File \"C:\\Users\\Lenovo\\anaconda3\\lib\\site-packages\\flask\\_compat.py\", line 39, in reraise\n",
      "    raise value\n",
      "  File \"C:\\Users\\Lenovo\\anaconda3\\lib\\site-packages\\flask\\app.py\", line 1950, in full_dispatch_request\n",
      "    rv = self.dispatch_request()\n",
      "  File \"C:\\Users\\Lenovo\\anaconda3\\lib\\site-packages\\flask\\app.py\", line 1936, in dispatch_request\n",
      "    return self.view_functions[rule.endpoint](**req.view_args)\n",
      "  File \"C:\\Users\\Lenovo\\anaconda3\\lib\\site-packages\\gradio\\networking.py\", line 92, in wrapper\n",
      "    return func(*args, **kwargs)\n",
      "  File \"C:\\Users\\Lenovo\\anaconda3\\lib\\site-packages\\gradio\\networking.py\", line 180, in predict\n",
      "    prediction, durations = app.interface.process(raw_input)\n",
      "  File \"C:\\Users\\Lenovo\\anaconda3\\lib\\site-packages\\gradio\\interface.py\", line 334, in process\n",
      "    predictions, durations = self.run_prediction(processed_input, return_duration=True)\n",
      "  File \"C:\\Users\\Lenovo\\anaconda3\\lib\\site-packages\\gradio\\interface.py\", line 307, in run_prediction\n",
      "    prediction = predict_fn(*processed_input)\n",
      "  File \"<ipython-input-3-f9d94fe16654>\", line 3, in inference\n",
      "    df = pd.DataFrame([[age, s, ch, cardio]],\n",
      "NameError: name 'pd' is not defined\n"
     ]
    },
    {
     "name": "stderr",
     "output_type": "stream",
     "text": [
      "[2021-09-12 11:30:19,633] ERROR in app: Exception on /api/predict/ [POST]\n",
      "Traceback (most recent call last):\n",
      "  File \"C:\\Users\\Lenovo\\anaconda3\\lib\\site-packages\\flask\\app.py\", line 2447, in wsgi_app\n",
      "    response = self.full_dispatch_request()\n",
      "  File \"C:\\Users\\Lenovo\\anaconda3\\lib\\site-packages\\flask\\app.py\", line 1952, in full_dispatch_request\n",
      "    rv = self.handle_user_exception(e)\n",
      "  File \"C:\\Users\\Lenovo\\anaconda3\\lib\\site-packages\\flask_cors\\extension.py\", line 165, in wrapped_function\n",
      "    return cors_after_request(app.make_response(f(*args, **kwargs)))\n",
      "  File \"C:\\Users\\Lenovo\\anaconda3\\lib\\site-packages\\flask\\app.py\", line 1821, in handle_user_exception\n",
      "    reraise(exc_type, exc_value, tb)\n",
      "  File \"C:\\Users\\Lenovo\\anaconda3\\lib\\site-packages\\flask\\_compat.py\", line 39, in reraise\n",
      "    raise value\n",
      "  File \"C:\\Users\\Lenovo\\anaconda3\\lib\\site-packages\\flask\\app.py\", line 1950, in full_dispatch_request\n",
      "    rv = self.dispatch_request()\n",
      "  File \"C:\\Users\\Lenovo\\anaconda3\\lib\\site-packages\\flask\\app.py\", line 1936, in dispatch_request\n",
      "    return self.view_functions[rule.endpoint](**req.view_args)\n",
      "  File \"C:\\Users\\Lenovo\\anaconda3\\lib\\site-packages\\gradio\\networking.py\", line 92, in wrapper\n",
      "    return func(*args, **kwargs)\n",
      "  File \"C:\\Users\\Lenovo\\anaconda3\\lib\\site-packages\\gradio\\networking.py\", line 180, in predict\n",
      "    prediction, durations = app.interface.process(raw_input)\n",
      "  File \"C:\\Users\\Lenovo\\anaconda3\\lib\\site-packages\\gradio\\interface.py\", line 334, in process\n",
      "    predictions, durations = self.run_prediction(processed_input, return_duration=True)\n",
      "  File \"C:\\Users\\Lenovo\\anaconda3\\lib\\site-packages\\gradio\\interface.py\", line 307, in run_prediction\n",
      "    prediction = predict_fn(*processed_input)\n",
      "  File \"<ipython-input-3-f9d94fe16654>\", line 3, in inference\n",
      "    df = pd.DataFrame([[age, s, ch, cardio]],\n",
      "NameError: name 'pd' is not defined\n",
      "[2021-09-12 11:30:19,640] ERROR in app: Exception on /api/predict/ [POST]\n",
      "Traceback (most recent call last):\n",
      "  File \"C:\\Users\\Lenovo\\anaconda3\\lib\\site-packages\\flask\\app.py\", line 2447, in wsgi_app\n",
      "    response = self.full_dispatch_request()\n",
      "  File \"C:\\Users\\Lenovo\\anaconda3\\lib\\site-packages\\flask\\app.py\", line 1952, in full_dispatch_request\n",
      "    rv = self.handle_user_exception(e)\n",
      "  File \"C:\\Users\\Lenovo\\anaconda3\\lib\\site-packages\\flask_cors\\extension.py\", line 165, in wrapped_function\n",
      "    return cors_after_request(app.make_response(f(*args, **kwargs)))\n",
      "  File \"C:\\Users\\Lenovo\\anaconda3\\lib\\site-packages\\flask\\app.py\", line 1821, in handle_user_exception\n",
      "    reraise(exc_type, exc_value, tb)\n",
      "  File \"C:\\Users\\Lenovo\\anaconda3\\lib\\site-packages\\flask\\_compat.py\", line 39, in reraise\n",
      "    raise value\n",
      "  File \"C:\\Users\\Lenovo\\anaconda3\\lib\\site-packages\\flask\\app.py\", line 1950, in full_dispatch_request\n",
      "    rv = self.dispatch_request()\n",
      "  File \"C:\\Users\\Lenovo\\anaconda3\\lib\\site-packages\\flask\\app.py\", line 1936, in dispatch_request\n",
      "    return self.view_functions[rule.endpoint](**req.view_args)\n",
      "  File \"C:\\Users\\Lenovo\\anaconda3\\lib\\site-packages\\gradio\\networking.py\", line 92, in wrapper\n",
      "    return func(*args, **kwargs)\n",
      "  File \"C:\\Users\\Lenovo\\anaconda3\\lib\\site-packages\\gradio\\networking.py\", line 180, in predict\n",
      "    prediction, durations = app.interface.process(raw_input)\n",
      "  File \"C:\\Users\\Lenovo\\anaconda3\\lib\\site-packages\\gradio\\interface.py\", line 334, in process\n",
      "    predictions, durations = self.run_prediction(processed_input, return_duration=True)\n",
      "  File \"C:\\Users\\Lenovo\\anaconda3\\lib\\site-packages\\gradio\\interface.py\", line 307, in run_prediction\n",
      "    prediction = predict_fn(*processed_input)\n",
      "  File \"<ipython-input-3-f9d94fe16654>\", line 3, in inference\n",
      "    df = pd.DataFrame([[age, s, ch, cardio]],\n",
      "NameError: name 'pd' is not defined\n",
      "[2021-09-12 11:30:19,647] ERROR in app: Exception on /api/predict/ [POST]\n",
      "Traceback (most recent call last):\n",
      "  File \"C:\\Users\\Lenovo\\anaconda3\\lib\\site-packages\\flask\\app.py\", line 2447, in wsgi_app\n",
      "    response = self.full_dispatch_request()\n",
      "  File \"C:\\Users\\Lenovo\\anaconda3\\lib\\site-packages\\flask\\app.py\", line 1952, in full_dispatch_request\n",
      "    rv = self.handle_user_exception(e)\n",
      "  File \"C:\\Users\\Lenovo\\anaconda3\\lib\\site-packages\\flask_cors\\extension.py\", line 165, in wrapped_function\n",
      "    return cors_after_request(app.make_response(f(*args, **kwargs)))\n",
      "  File \"C:\\Users\\Lenovo\\anaconda3\\lib\\site-packages\\flask\\app.py\", line 1821, in handle_user_exception\n",
      "    reraise(exc_type, exc_value, tb)\n",
      "  File \"C:\\Users\\Lenovo\\anaconda3\\lib\\site-packages\\flask\\_compat.py\", line 39, in reraise\n",
      "    raise value\n",
      "  File \"C:\\Users\\Lenovo\\anaconda3\\lib\\site-packages\\flask\\app.py\", line 1950, in full_dispatch_request\n",
      "    rv = self.dispatch_request()\n",
      "  File \"C:\\Users\\Lenovo\\anaconda3\\lib\\site-packages\\flask\\app.py\", line 1936, in dispatch_request\n",
      "    return self.view_functions[rule.endpoint](**req.view_args)\n",
      "  File \"C:\\Users\\Lenovo\\anaconda3\\lib\\site-packages\\gradio\\networking.py\", line 92, in wrapper\n",
      "    return func(*args, **kwargs)\n",
      "  File \"C:\\Users\\Lenovo\\anaconda3\\lib\\site-packages\\gradio\\networking.py\", line 180, in predict\n",
      "    prediction, durations = app.interface.process(raw_input)\n",
      "  File \"C:\\Users\\Lenovo\\anaconda3\\lib\\site-packages\\gradio\\interface.py\", line 334, in process\n",
      "    predictions, durations = self.run_prediction(processed_input, return_duration=True)\n",
      "  File \"C:\\Users\\Lenovo\\anaconda3\\lib\\site-packages\\gradio\\interface.py\", line 307, in run_prediction\n",
      "    prediction = predict_fn(*processed_input)\n",
      "  File \"<ipython-input-3-f9d94fe16654>\", line 3, in inference\n",
      "    df = pd.DataFrame([[age, s, ch, cardio]],\n",
      "NameError: name 'pd' is not defined\n",
      "[2021-09-12 11:30:19,654] ERROR in app: Exception on /api/predict/ [POST]\n",
      "Traceback (most recent call last):\n",
      "  File \"C:\\Users\\Lenovo\\anaconda3\\lib\\site-packages\\flask\\app.py\", line 2447, in wsgi_app\n",
      "    response = self.full_dispatch_request()\n",
      "  File \"C:\\Users\\Lenovo\\anaconda3\\lib\\site-packages\\flask\\app.py\", line 1952, in full_dispatch_request\n",
      "    rv = self.handle_user_exception(e)\n",
      "  File \"C:\\Users\\Lenovo\\anaconda3\\lib\\site-packages\\flask_cors\\extension.py\", line 165, in wrapped_function\n",
      "    return cors_after_request(app.make_response(f(*args, **kwargs)))\n",
      "  File \"C:\\Users\\Lenovo\\anaconda3\\lib\\site-packages\\flask\\app.py\", line 1821, in handle_user_exception\n",
      "    reraise(exc_type, exc_value, tb)\n",
      "  File \"C:\\Users\\Lenovo\\anaconda3\\lib\\site-packages\\flask\\_compat.py\", line 39, in reraise\n",
      "    raise value\n",
      "  File \"C:\\Users\\Lenovo\\anaconda3\\lib\\site-packages\\flask\\app.py\", line 1950, in full_dispatch_request\n",
      "    rv = self.dispatch_request()\n",
      "  File \"C:\\Users\\Lenovo\\anaconda3\\lib\\site-packages\\flask\\app.py\", line 1936, in dispatch_request\n",
      "    return self.view_functions[rule.endpoint](**req.view_args)\n",
      "  File \"C:\\Users\\Lenovo\\anaconda3\\lib\\site-packages\\gradio\\networking.py\", line 92, in wrapper\n",
      "    return func(*args, **kwargs)\n",
      "  File \"C:\\Users\\Lenovo\\anaconda3\\lib\\site-packages\\gradio\\networking.py\", line 180, in predict\n",
      "    prediction, durations = app.interface.process(raw_input)\n",
      "  File \"C:\\Users\\Lenovo\\anaconda3\\lib\\site-packages\\gradio\\interface.py\", line 334, in process\n",
      "    predictions, durations = self.run_prediction(processed_input, return_duration=True)\n",
      "  File \"C:\\Users\\Lenovo\\anaconda3\\lib\\site-packages\\gradio\\interface.py\", line 307, in run_prediction\n",
      "    prediction = predict_fn(*processed_input)\n",
      "  File \"<ipython-input-3-f9d94fe16654>\", line 3, in inference\n",
      "    df = pd.DataFrame([[age, s, ch, cardio]],\n",
      "NameError: name 'pd' is not defined\n",
      "[2021-09-12 11:30:19,661] ERROR in app: Exception on /api/predict/ [POST]\n",
      "Traceback (most recent call last):\n",
      "  File \"C:\\Users\\Lenovo\\anaconda3\\lib\\site-packages\\flask\\app.py\", line 2447, in wsgi_app\n",
      "    response = self.full_dispatch_request()\n",
      "  File \"C:\\Users\\Lenovo\\anaconda3\\lib\\site-packages\\flask\\app.py\", line 1952, in full_dispatch_request\n",
      "    rv = self.handle_user_exception(e)\n",
      "  File \"C:\\Users\\Lenovo\\anaconda3\\lib\\site-packages\\flask_cors\\extension.py\", line 165, in wrapped_function\n",
      "    return cors_after_request(app.make_response(f(*args, **kwargs)))\n",
      "  File \"C:\\Users\\Lenovo\\anaconda3\\lib\\site-packages\\flask\\app.py\", line 1821, in handle_user_exception\n",
      "    reraise(exc_type, exc_value, tb)\n",
      "  File \"C:\\Users\\Lenovo\\anaconda3\\lib\\site-packages\\flask\\_compat.py\", line 39, in reraise\n",
      "    raise value\n",
      "  File \"C:\\Users\\Lenovo\\anaconda3\\lib\\site-packages\\flask\\app.py\", line 1950, in full_dispatch_request\n",
      "    rv = self.dispatch_request()\n",
      "  File \"C:\\Users\\Lenovo\\anaconda3\\lib\\site-packages\\flask\\app.py\", line 1936, in dispatch_request\n",
      "    return self.view_functions[rule.endpoint](**req.view_args)\n",
      "  File \"C:\\Users\\Lenovo\\anaconda3\\lib\\site-packages\\gradio\\networking.py\", line 92, in wrapper\n",
      "    return func(*args, **kwargs)\n",
      "  File \"C:\\Users\\Lenovo\\anaconda3\\lib\\site-packages\\gradio\\networking.py\", line 180, in predict\n",
      "    prediction, durations = app.interface.process(raw_input)\n",
      "  File \"C:\\Users\\Lenovo\\anaconda3\\lib\\site-packages\\gradio\\interface.py\", line 334, in process\n",
      "    predictions, durations = self.run_prediction(processed_input, return_duration=True)\n",
      "  File \"C:\\Users\\Lenovo\\anaconda3\\lib\\site-packages\\gradio\\interface.py\", line 307, in run_prediction\n",
      "    prediction = predict_fn(*processed_input)\n",
      "  File \"<ipython-input-3-f9d94fe16654>\", line 3, in inference\n",
      "    df = pd.DataFrame([[age, s, ch, cardio]],\n",
      "NameError: name 'pd' is not defined\n"
     ]
    },
    {
     "name": "stderr",
     "output_type": "stream",
     "text": [
      "[2021-09-12 11:30:19,718] ERROR in app: Exception on /api/predict/ [POST]\n",
      "Traceback (most recent call last):\n",
      "  File \"C:\\Users\\Lenovo\\anaconda3\\lib\\site-packages\\flask\\app.py\", line 2447, in wsgi_app\n",
      "    response = self.full_dispatch_request()\n",
      "  File \"C:\\Users\\Lenovo\\anaconda3\\lib\\site-packages\\flask\\app.py\", line 1952, in full_dispatch_request\n",
      "    rv = self.handle_user_exception(e)\n",
      "  File \"C:\\Users\\Lenovo\\anaconda3\\lib\\site-packages\\flask_cors\\extension.py\", line 165, in wrapped_function\n",
      "    return cors_after_request(app.make_response(f(*args, **kwargs)))\n",
      "  File \"C:\\Users\\Lenovo\\anaconda3\\lib\\site-packages\\flask\\app.py\", line 1821, in handle_user_exception\n",
      "    reraise(exc_type, exc_value, tb)\n",
      "  File \"C:\\Users\\Lenovo\\anaconda3\\lib\\site-packages\\flask\\_compat.py\", line 39, in reraise\n",
      "    raise value\n",
      "  File \"C:\\Users\\Lenovo\\anaconda3\\lib\\site-packages\\flask\\app.py\", line 1950, in full_dispatch_request\n",
      "    rv = self.dispatch_request()\n",
      "  File \"C:\\Users\\Lenovo\\anaconda3\\lib\\site-packages\\flask\\app.py\", line 1936, in dispatch_request\n",
      "    return self.view_functions[rule.endpoint](**req.view_args)\n",
      "  File \"C:\\Users\\Lenovo\\anaconda3\\lib\\site-packages\\gradio\\networking.py\", line 92, in wrapper\n",
      "    return func(*args, **kwargs)\n",
      "  File \"C:\\Users\\Lenovo\\anaconda3\\lib\\site-packages\\gradio\\networking.py\", line 180, in predict\n",
      "    prediction, durations = app.interface.process(raw_input)\n",
      "  File \"C:\\Users\\Lenovo\\anaconda3\\lib\\site-packages\\gradio\\interface.py\", line 334, in process\n",
      "    predictions, durations = self.run_prediction(processed_input, return_duration=True)\n",
      "  File \"C:\\Users\\Lenovo\\anaconda3\\lib\\site-packages\\gradio\\interface.py\", line 307, in run_prediction\n",
      "    prediction = predict_fn(*processed_input)\n",
      "  File \"<ipython-input-3-f9d94fe16654>\", line 3, in inference\n",
      "    df = pd.DataFrame([[age, s, ch, cardio]],\n",
      "NameError: name 'pd' is not defined\n",
      "[2021-09-12 11:30:19,738] ERROR in app: Exception on /api/predict/ [POST]\n",
      "Traceback (most recent call last):\n",
      "  File \"C:\\Users\\Lenovo\\anaconda3\\lib\\site-packages\\flask\\app.py\", line 2447, in wsgi_app\n",
      "    response = self.full_dispatch_request()\n",
      "  File \"C:\\Users\\Lenovo\\anaconda3\\lib\\site-packages\\flask\\app.py\", line 1952, in full_dispatch_request\n",
      "    rv = self.handle_user_exception(e)\n",
      "  File \"C:\\Users\\Lenovo\\anaconda3\\lib\\site-packages\\flask_cors\\extension.py\", line 165, in wrapped_function\n",
      "    return cors_after_request(app.make_response(f(*args, **kwargs)))\n",
      "  File \"C:\\Users\\Lenovo\\anaconda3\\lib\\site-packages\\flask\\app.py\", line 1821, in handle_user_exception\n",
      "    reraise(exc_type, exc_value, tb)\n",
      "  File \"C:\\Users\\Lenovo\\anaconda3\\lib\\site-packages\\flask\\_compat.py\", line 39, in reraise\n",
      "    raise value\n",
      "  File \"C:\\Users\\Lenovo\\anaconda3\\lib\\site-packages\\flask\\app.py\", line 1950, in full_dispatch_request\n",
      "    rv = self.dispatch_request()\n",
      "  File \"C:\\Users\\Lenovo\\anaconda3\\lib\\site-packages\\flask\\app.py\", line 1936, in dispatch_request\n",
      "    return self.view_functions[rule.endpoint](**req.view_args)\n",
      "  File \"C:\\Users\\Lenovo\\anaconda3\\lib\\site-packages\\gradio\\networking.py\", line 92, in wrapper\n",
      "    return func(*args, **kwargs)\n",
      "  File \"C:\\Users\\Lenovo\\anaconda3\\lib\\site-packages\\gradio\\networking.py\", line 180, in predict\n",
      "    prediction, durations = app.interface.process(raw_input)\n",
      "  File \"C:\\Users\\Lenovo\\anaconda3\\lib\\site-packages\\gradio\\interface.py\", line 334, in process\n",
      "    predictions, durations = self.run_prediction(processed_input, return_duration=True)\n",
      "  File \"C:\\Users\\Lenovo\\anaconda3\\lib\\site-packages\\gradio\\interface.py\", line 307, in run_prediction\n",
      "    prediction = predict_fn(*processed_input)\n",
      "  File \"<ipython-input-3-f9d94fe16654>\", line 3, in inference\n",
      "    df = pd.DataFrame([[age, s, ch, cardio]],\n",
      "NameError: name 'pd' is not defined\n",
      "[2021-09-12 11:30:19,751] ERROR in app: Exception on /api/predict/ [POST]\n",
      "Traceback (most recent call last):\n",
      "  File \"C:\\Users\\Lenovo\\anaconda3\\lib\\site-packages\\flask\\app.py\", line 2447, in wsgi_app\n",
      "    response = self.full_dispatch_request()\n",
      "  File \"C:\\Users\\Lenovo\\anaconda3\\lib\\site-packages\\flask\\app.py\", line 1952, in full_dispatch_request\n",
      "    rv = self.handle_user_exception(e)\n",
      "  File \"C:\\Users\\Lenovo\\anaconda3\\lib\\site-packages\\flask_cors\\extension.py\", line 165, in wrapped_function\n",
      "    return cors_after_request(app.make_response(f(*args, **kwargs)))\n",
      "  File \"C:\\Users\\Lenovo\\anaconda3\\lib\\site-packages\\flask\\app.py\", line 1821, in handle_user_exception\n",
      "    reraise(exc_type, exc_value, tb)\n",
      "  File \"C:\\Users\\Lenovo\\anaconda3\\lib\\site-packages\\flask\\_compat.py\", line 39, in reraise\n",
      "    raise value\n",
      "  File \"C:\\Users\\Lenovo\\anaconda3\\lib\\site-packages\\flask\\app.py\", line 1950, in full_dispatch_request\n",
      "    rv = self.dispatch_request()\n",
      "  File \"C:\\Users\\Lenovo\\anaconda3\\lib\\site-packages\\flask\\app.py\", line 1936, in dispatch_request\n",
      "    return self.view_functions[rule.endpoint](**req.view_args)\n",
      "  File \"C:\\Users\\Lenovo\\anaconda3\\lib\\site-packages\\gradio\\networking.py\", line 92, in wrapper\n",
      "    return func(*args, **kwargs)\n",
      "  File \"C:\\Users\\Lenovo\\anaconda3\\lib\\site-packages\\gradio\\networking.py\", line 180, in predict\n",
      "    prediction, durations = app.interface.process(raw_input)\n",
      "  File \"C:\\Users\\Lenovo\\anaconda3\\lib\\site-packages\\gradio\\interface.py\", line 334, in process\n",
      "    predictions, durations = self.run_prediction(processed_input, return_duration=True)\n",
      "  File \"C:\\Users\\Lenovo\\anaconda3\\lib\\site-packages\\gradio\\interface.py\", line 307, in run_prediction\n",
      "    prediction = predict_fn(*processed_input)\n",
      "  File \"<ipython-input-3-f9d94fe16654>\", line 3, in inference\n",
      "    df = pd.DataFrame([[age, s, ch, cardio]],\n",
      "NameError: name 'pd' is not defined\n",
      "[2021-09-12 11:30:19,758] ERROR in app: Exception on /api/predict/ [POST]\n",
      "Traceback (most recent call last):\n",
      "  File \"C:\\Users\\Lenovo\\anaconda3\\lib\\site-packages\\flask\\app.py\", line 2447, in wsgi_app\n",
      "    response = self.full_dispatch_request()\n",
      "  File \"C:\\Users\\Lenovo\\anaconda3\\lib\\site-packages\\flask\\app.py\", line 1952, in full_dispatch_request\n",
      "    rv = self.handle_user_exception(e)\n",
      "  File \"C:\\Users\\Lenovo\\anaconda3\\lib\\site-packages\\flask_cors\\extension.py\", line 165, in wrapped_function\n",
      "    return cors_after_request(app.make_response(f(*args, **kwargs)))\n",
      "  File \"C:\\Users\\Lenovo\\anaconda3\\lib\\site-packages\\flask\\app.py\", line 1821, in handle_user_exception\n",
      "    reraise(exc_type, exc_value, tb)\n",
      "  File \"C:\\Users\\Lenovo\\anaconda3\\lib\\site-packages\\flask\\_compat.py\", line 39, in reraise\n",
      "    raise value\n",
      "  File \"C:\\Users\\Lenovo\\anaconda3\\lib\\site-packages\\flask\\app.py\", line 1950, in full_dispatch_request\n",
      "    rv = self.dispatch_request()\n",
      "  File \"C:\\Users\\Lenovo\\anaconda3\\lib\\site-packages\\flask\\app.py\", line 1936, in dispatch_request\n",
      "    return self.view_functions[rule.endpoint](**req.view_args)\n",
      "  File \"C:\\Users\\Lenovo\\anaconda3\\lib\\site-packages\\gradio\\networking.py\", line 92, in wrapper\n",
      "    return func(*args, **kwargs)\n",
      "  File \"C:\\Users\\Lenovo\\anaconda3\\lib\\site-packages\\gradio\\networking.py\", line 180, in predict\n",
      "    prediction, durations = app.interface.process(raw_input)\n",
      "  File \"C:\\Users\\Lenovo\\anaconda3\\lib\\site-packages\\gradio\\interface.py\", line 334, in process\n",
      "    predictions, durations = self.run_prediction(processed_input, return_duration=True)\n",
      "  File \"C:\\Users\\Lenovo\\anaconda3\\lib\\site-packages\\gradio\\interface.py\", line 307, in run_prediction\n",
      "    prediction = predict_fn(*processed_input)\n",
      "  File \"<ipython-input-3-f9d94fe16654>\", line 3, in inference\n",
      "    df = pd.DataFrame([[age, s, ch, cardio]],\n",
      "NameError: name 'pd' is not defined\n",
      "[2021-09-12 11:30:19,765] ERROR in app: Exception on /api/predict/ [POST]\n",
      "Traceback (most recent call last):\n",
      "  File \"C:\\Users\\Lenovo\\anaconda3\\lib\\site-packages\\flask\\app.py\", line 2447, in wsgi_app\n",
      "    response = self.full_dispatch_request()\n",
      "  File \"C:\\Users\\Lenovo\\anaconda3\\lib\\site-packages\\flask\\app.py\", line 1952, in full_dispatch_request\n",
      "    rv = self.handle_user_exception(e)\n",
      "  File \"C:\\Users\\Lenovo\\anaconda3\\lib\\site-packages\\flask_cors\\extension.py\", line 165, in wrapped_function\n",
      "    return cors_after_request(app.make_response(f(*args, **kwargs)))\n",
      "  File \"C:\\Users\\Lenovo\\anaconda3\\lib\\site-packages\\flask\\app.py\", line 1821, in handle_user_exception\n",
      "    reraise(exc_type, exc_value, tb)\n",
      "  File \"C:\\Users\\Lenovo\\anaconda3\\lib\\site-packages\\flask\\_compat.py\", line 39, in reraise\n",
      "    raise value\n",
      "  File \"C:\\Users\\Lenovo\\anaconda3\\lib\\site-packages\\flask\\app.py\", line 1950, in full_dispatch_request\n",
      "    rv = self.dispatch_request()\n",
      "  File \"C:\\Users\\Lenovo\\anaconda3\\lib\\site-packages\\flask\\app.py\", line 1936, in dispatch_request\n",
      "    return self.view_functions[rule.endpoint](**req.view_args)\n",
      "  File \"C:\\Users\\Lenovo\\anaconda3\\lib\\site-packages\\gradio\\networking.py\", line 92, in wrapper\n",
      "    return func(*args, **kwargs)\n",
      "  File \"C:\\Users\\Lenovo\\anaconda3\\lib\\site-packages\\gradio\\networking.py\", line 180, in predict\n",
      "    prediction, durations = app.interface.process(raw_input)\n",
      "  File \"C:\\Users\\Lenovo\\anaconda3\\lib\\site-packages\\gradio\\interface.py\", line 334, in process\n",
      "    predictions, durations = self.run_prediction(processed_input, return_duration=True)\n",
      "  File \"C:\\Users\\Lenovo\\anaconda3\\lib\\site-packages\\gradio\\interface.py\", line 307, in run_prediction\n",
      "    prediction = predict_fn(*processed_input)\n",
      "  File \"<ipython-input-3-f9d94fe16654>\", line 3, in inference\n",
      "    df = pd.DataFrame([[age, s, ch, cardio]],\n",
      "NameError: name 'pd' is not defined\n"
     ]
    },
    {
     "name": "stderr",
     "output_type": "stream",
     "text": [
      "[2021-09-12 11:30:19,779] ERROR in app: Exception on /api/predict/ [POST]\n",
      "Traceback (most recent call last):\n",
      "  File \"C:\\Users\\Lenovo\\anaconda3\\lib\\site-packages\\flask\\app.py\", line 2447, in wsgi_app\n",
      "    response = self.full_dispatch_request()\n",
      "  File \"C:\\Users\\Lenovo\\anaconda3\\lib\\site-packages\\flask\\app.py\", line 1952, in full_dispatch_request\n",
      "    rv = self.handle_user_exception(e)\n",
      "  File \"C:\\Users\\Lenovo\\anaconda3\\lib\\site-packages\\flask_cors\\extension.py\", line 165, in wrapped_function\n",
      "    return cors_after_request(app.make_response(f(*args, **kwargs)))\n",
      "  File \"C:\\Users\\Lenovo\\anaconda3\\lib\\site-packages\\flask\\app.py\", line 1821, in handle_user_exception\n",
      "    reraise(exc_type, exc_value, tb)\n",
      "  File \"C:\\Users\\Lenovo\\anaconda3\\lib\\site-packages\\flask\\_compat.py\", line 39, in reraise\n",
      "    raise value\n",
      "  File \"C:\\Users\\Lenovo\\anaconda3\\lib\\site-packages\\flask\\app.py\", line 1950, in full_dispatch_request\n",
      "    rv = self.dispatch_request()\n",
      "  File \"C:\\Users\\Lenovo\\anaconda3\\lib\\site-packages\\flask\\app.py\", line 1936, in dispatch_request\n",
      "    return self.view_functions[rule.endpoint](**req.view_args)\n",
      "  File \"C:\\Users\\Lenovo\\anaconda3\\lib\\site-packages\\gradio\\networking.py\", line 92, in wrapper\n",
      "    return func(*args, **kwargs)\n",
      "  File \"C:\\Users\\Lenovo\\anaconda3\\lib\\site-packages\\gradio\\networking.py\", line 180, in predict\n",
      "    prediction, durations = app.interface.process(raw_input)\n",
      "  File \"C:\\Users\\Lenovo\\anaconda3\\lib\\site-packages\\gradio\\interface.py\", line 334, in process\n",
      "    predictions, durations = self.run_prediction(processed_input, return_duration=True)\n",
      "  File \"C:\\Users\\Lenovo\\anaconda3\\lib\\site-packages\\gradio\\interface.py\", line 307, in run_prediction\n",
      "    prediction = predict_fn(*processed_input)\n",
      "  File \"<ipython-input-3-f9d94fe16654>\", line 3, in inference\n",
      "    df = pd.DataFrame([[age, s, ch, cardio]],\n",
      "NameError: name 'pd' is not defined\n",
      "[2021-09-12 11:30:19,786] ERROR in app: Exception on /api/predict/ [POST]\n",
      "Traceback (most recent call last):\n",
      "  File \"C:\\Users\\Lenovo\\anaconda3\\lib\\site-packages\\flask\\app.py\", line 2447, in wsgi_app\n",
      "    response = self.full_dispatch_request()\n",
      "  File \"C:\\Users\\Lenovo\\anaconda3\\lib\\site-packages\\flask\\app.py\", line 1952, in full_dispatch_request\n",
      "    rv = self.handle_user_exception(e)\n",
      "  File \"C:\\Users\\Lenovo\\anaconda3\\lib\\site-packages\\flask_cors\\extension.py\", line 165, in wrapped_function\n",
      "    return cors_after_request(app.make_response(f(*args, **kwargs)))\n",
      "  File \"C:\\Users\\Lenovo\\anaconda3\\lib\\site-packages\\flask\\app.py\", line 1821, in handle_user_exception\n",
      "    reraise(exc_type, exc_value, tb)\n",
      "  File \"C:\\Users\\Lenovo\\anaconda3\\lib\\site-packages\\flask\\_compat.py\", line 39, in reraise\n",
      "    raise value\n",
      "  File \"C:\\Users\\Lenovo\\anaconda3\\lib\\site-packages\\flask\\app.py\", line 1950, in full_dispatch_request\n",
      "    rv = self.dispatch_request()\n",
      "  File \"C:\\Users\\Lenovo\\anaconda3\\lib\\site-packages\\flask\\app.py\", line 1936, in dispatch_request\n",
      "    return self.view_functions[rule.endpoint](**req.view_args)\n",
      "  File \"C:\\Users\\Lenovo\\anaconda3\\lib\\site-packages\\gradio\\networking.py\", line 92, in wrapper\n",
      "    return func(*args, **kwargs)\n",
      "  File \"C:\\Users\\Lenovo\\anaconda3\\lib\\site-packages\\gradio\\networking.py\", line 180, in predict\n",
      "    prediction, durations = app.interface.process(raw_input)\n",
      "  File \"C:\\Users\\Lenovo\\anaconda3\\lib\\site-packages\\gradio\\interface.py\", line 334, in process\n",
      "    predictions, durations = self.run_prediction(processed_input, return_duration=True)\n",
      "  File \"C:\\Users\\Lenovo\\anaconda3\\lib\\site-packages\\gradio\\interface.py\", line 307, in run_prediction\n",
      "    prediction = predict_fn(*processed_input)\n",
      "  File \"<ipython-input-3-f9d94fe16654>\", line 3, in inference\n",
      "    df = pd.DataFrame([[age, s, ch, cardio]],\n",
      "NameError: name 'pd' is not defined\n",
      "[2021-09-12 11:30:25,435] ERROR in app: Exception on /api/predict/ [POST]\n",
      "Traceback (most recent call last):\n",
      "  File \"C:\\Users\\Lenovo\\anaconda3\\lib\\site-packages\\flask\\app.py\", line 2447, in wsgi_app\n",
      "    response = self.full_dispatch_request()\n",
      "  File \"C:\\Users\\Lenovo\\anaconda3\\lib\\site-packages\\flask\\app.py\", line 1952, in full_dispatch_request\n",
      "    rv = self.handle_user_exception(e)\n",
      "  File \"C:\\Users\\Lenovo\\anaconda3\\lib\\site-packages\\flask_cors\\extension.py\", line 165, in wrapped_function\n",
      "    return cors_after_request(app.make_response(f(*args, **kwargs)))\n",
      "  File \"C:\\Users\\Lenovo\\anaconda3\\lib\\site-packages\\flask\\app.py\", line 1821, in handle_user_exception\n",
      "    reraise(exc_type, exc_value, tb)\n",
      "  File \"C:\\Users\\Lenovo\\anaconda3\\lib\\site-packages\\flask\\_compat.py\", line 39, in reraise\n",
      "    raise value\n",
      "  File \"C:\\Users\\Lenovo\\anaconda3\\lib\\site-packages\\flask\\app.py\", line 1950, in full_dispatch_request\n",
      "    rv = self.dispatch_request()\n",
      "  File \"C:\\Users\\Lenovo\\anaconda3\\lib\\site-packages\\flask\\app.py\", line 1936, in dispatch_request\n",
      "    return self.view_functions[rule.endpoint](**req.view_args)\n",
      "  File \"C:\\Users\\Lenovo\\anaconda3\\lib\\site-packages\\gradio\\networking.py\", line 92, in wrapper\n",
      "    return func(*args, **kwargs)\n",
      "  File \"C:\\Users\\Lenovo\\anaconda3\\lib\\site-packages\\gradio\\networking.py\", line 180, in predict\n",
      "    prediction, durations = app.interface.process(raw_input)\n",
      "  File \"C:\\Users\\Lenovo\\anaconda3\\lib\\site-packages\\gradio\\interface.py\", line 334, in process\n",
      "    predictions, durations = self.run_prediction(processed_input, return_duration=True)\n",
      "  File \"C:\\Users\\Lenovo\\anaconda3\\lib\\site-packages\\gradio\\interface.py\", line 307, in run_prediction\n",
      "    prediction = predict_fn(*processed_input)\n",
      "  File \"<ipython-input-3-f9d94fe16654>\", line 3, in inference\n",
      "    df = pd.DataFrame([[age, s, ch, cardio]],\n",
      "NameError: name 'pd' is not defined\n",
      "[2021-09-12 11:30:33,084] ERROR in app: Exception on /api/predict/ [POST]\n",
      "Traceback (most recent call last):\n",
      "  File \"C:\\Users\\Lenovo\\anaconda3\\lib\\site-packages\\flask\\app.py\", line 2447, in wsgi_app\n",
      "    response = self.full_dispatch_request()\n",
      "  File \"C:\\Users\\Lenovo\\anaconda3\\lib\\site-packages\\flask\\app.py\", line 1952, in full_dispatch_request\n",
      "    rv = self.handle_user_exception(e)\n",
      "  File \"C:\\Users\\Lenovo\\anaconda3\\lib\\site-packages\\flask_cors\\extension.py\", line 165, in wrapped_function\n",
      "    return cors_after_request(app.make_response(f(*args, **kwargs)))\n",
      "  File \"C:\\Users\\Lenovo\\anaconda3\\lib\\site-packages\\flask\\app.py\", line 1821, in handle_user_exception\n",
      "    reraise(exc_type, exc_value, tb)\n",
      "  File \"C:\\Users\\Lenovo\\anaconda3\\lib\\site-packages\\flask\\_compat.py\", line 39, in reraise\n",
      "    raise value\n",
      "  File \"C:\\Users\\Lenovo\\anaconda3\\lib\\site-packages\\flask\\app.py\", line 1950, in full_dispatch_request\n",
      "    rv = self.dispatch_request()\n",
      "  File \"C:\\Users\\Lenovo\\anaconda3\\lib\\site-packages\\flask\\app.py\", line 1936, in dispatch_request\n",
      "    return self.view_functions[rule.endpoint](**req.view_args)\n",
      "  File \"C:\\Users\\Lenovo\\anaconda3\\lib\\site-packages\\gradio\\networking.py\", line 92, in wrapper\n",
      "    return func(*args, **kwargs)\n",
      "  File \"C:\\Users\\Lenovo\\anaconda3\\lib\\site-packages\\gradio\\networking.py\", line 180, in predict\n",
      "    prediction, durations = app.interface.process(raw_input)\n",
      "  File \"C:\\Users\\Lenovo\\anaconda3\\lib\\site-packages\\gradio\\interface.py\", line 334, in process\n",
      "    predictions, durations = self.run_prediction(processed_input, return_duration=True)\n",
      "  File \"C:\\Users\\Lenovo\\anaconda3\\lib\\site-packages\\gradio\\interface.py\", line 307, in run_prediction\n",
      "    prediction = predict_fn(*processed_input)\n",
      "  File \"<ipython-input-3-f9d94fe16654>\", line 3, in inference\n",
      "    df = pd.DataFrame([[age, s, ch, cardio]],\n",
      "NameError: name 'pd' is not defined\n",
      "[2021-09-12 11:30:33,109] ERROR in app: Exception on /api/predict/ [POST]\n",
      "Traceback (most recent call last):\n",
      "  File \"C:\\Users\\Lenovo\\anaconda3\\lib\\site-packages\\flask\\app.py\", line 2447, in wsgi_app\n",
      "    response = self.full_dispatch_request()\n",
      "  File \"C:\\Users\\Lenovo\\anaconda3\\lib\\site-packages\\flask\\app.py\", line 1952, in full_dispatch_request\n",
      "    rv = self.handle_user_exception(e)\n",
      "  File \"C:\\Users\\Lenovo\\anaconda3\\lib\\site-packages\\flask_cors\\extension.py\", line 165, in wrapped_function\n",
      "    return cors_after_request(app.make_response(f(*args, **kwargs)))\n",
      "  File \"C:\\Users\\Lenovo\\anaconda3\\lib\\site-packages\\flask\\app.py\", line 1821, in handle_user_exception\n",
      "    reraise(exc_type, exc_value, tb)\n",
      "  File \"C:\\Users\\Lenovo\\anaconda3\\lib\\site-packages\\flask\\_compat.py\", line 39, in reraise\n",
      "    raise value\n",
      "  File \"C:\\Users\\Lenovo\\anaconda3\\lib\\site-packages\\flask\\app.py\", line 1950, in full_dispatch_request\n",
      "    rv = self.dispatch_request()\n",
      "  File \"C:\\Users\\Lenovo\\anaconda3\\lib\\site-packages\\flask\\app.py\", line 1936, in dispatch_request\n",
      "    return self.view_functions[rule.endpoint](**req.view_args)\n",
      "  File \"C:\\Users\\Lenovo\\anaconda3\\lib\\site-packages\\gradio\\networking.py\", line 92, in wrapper\n",
      "    return func(*args, **kwargs)\n",
      "  File \"C:\\Users\\Lenovo\\anaconda3\\lib\\site-packages\\gradio\\networking.py\", line 180, in predict\n",
      "    prediction, durations = app.interface.process(raw_input)\n",
      "  File \"C:\\Users\\Lenovo\\anaconda3\\lib\\site-packages\\gradio\\interface.py\", line 334, in process\n",
      "    predictions, durations = self.run_prediction(processed_input, return_duration=True)\n",
      "  File \"C:\\Users\\Lenovo\\anaconda3\\lib\\site-packages\\gradio\\interface.py\", line 307, in run_prediction\n",
      "    prediction = predict_fn(*processed_input)\n",
      "  File \"<ipython-input-3-f9d94fe16654>\", line 3, in inference\n",
      "    df = pd.DataFrame([[age, s, ch, cardio]],\n",
      "NameError: name 'pd' is not defined\n"
     ]
    },
    {
     "name": "stderr",
     "output_type": "stream",
     "text": [
      "[2021-09-12 11:30:33,122] ERROR in app: Exception on /api/predict/ [POST]\n",
      "Traceback (most recent call last):\n",
      "  File \"C:\\Users\\Lenovo\\anaconda3\\lib\\site-packages\\flask\\app.py\", line 2447, in wsgi_app\n",
      "    response = self.full_dispatch_request()\n",
      "  File \"C:\\Users\\Lenovo\\anaconda3\\lib\\site-packages\\flask\\app.py\", line 1952, in full_dispatch_request\n",
      "    rv = self.handle_user_exception(e)\n",
      "  File \"C:\\Users\\Lenovo\\anaconda3\\lib\\site-packages\\flask_cors\\extension.py\", line 165, in wrapped_function\n",
      "    return cors_after_request(app.make_response(f(*args, **kwargs)))\n",
      "  File \"C:\\Users\\Lenovo\\anaconda3\\lib\\site-packages\\flask\\app.py\", line 1821, in handle_user_exception\n",
      "    reraise(exc_type, exc_value, tb)\n",
      "  File \"C:\\Users\\Lenovo\\anaconda3\\lib\\site-packages\\flask\\_compat.py\", line 39, in reraise\n",
      "    raise value\n",
      "  File \"C:\\Users\\Lenovo\\anaconda3\\lib\\site-packages\\flask\\app.py\", line 1950, in full_dispatch_request\n",
      "    rv = self.dispatch_request()\n",
      "  File \"C:\\Users\\Lenovo\\anaconda3\\lib\\site-packages\\flask\\app.py\", line 1936, in dispatch_request\n",
      "    return self.view_functions[rule.endpoint](**req.view_args)\n",
      "  File \"C:\\Users\\Lenovo\\anaconda3\\lib\\site-packages\\gradio\\networking.py\", line 92, in wrapper\n",
      "    return func(*args, **kwargs)\n",
      "  File \"C:\\Users\\Lenovo\\anaconda3\\lib\\site-packages\\gradio\\networking.py\", line 180, in predict\n",
      "    prediction, durations = app.interface.process(raw_input)\n",
      "  File \"C:\\Users\\Lenovo\\anaconda3\\lib\\site-packages\\gradio\\interface.py\", line 334, in process\n",
      "    predictions, durations = self.run_prediction(processed_input, return_duration=True)\n",
      "  File \"C:\\Users\\Lenovo\\anaconda3\\lib\\site-packages\\gradio\\interface.py\", line 307, in run_prediction\n",
      "    prediction = predict_fn(*processed_input)\n",
      "  File \"<ipython-input-3-f9d94fe16654>\", line 3, in inference\n",
      "    df = pd.DataFrame([[age, s, ch, cardio]],\n",
      "NameError: name 'pd' is not defined\n",
      "[2021-09-12 11:30:33,129] ERROR in app: Exception on /api/predict/ [POST]\n",
      "Traceback (most recent call last):\n",
      "  File \"C:\\Users\\Lenovo\\anaconda3\\lib\\site-packages\\flask\\app.py\", line 2447, in wsgi_app\n",
      "    response = self.full_dispatch_request()\n",
      "  File \"C:\\Users\\Lenovo\\anaconda3\\lib\\site-packages\\flask\\app.py\", line 1952, in full_dispatch_request\n",
      "    rv = self.handle_user_exception(e)\n",
      "  File \"C:\\Users\\Lenovo\\anaconda3\\lib\\site-packages\\flask_cors\\extension.py\", line 165, in wrapped_function\n",
      "    return cors_after_request(app.make_response(f(*args, **kwargs)))\n",
      "  File \"C:\\Users\\Lenovo\\anaconda3\\lib\\site-packages\\flask\\app.py\", line 1821, in handle_user_exception\n",
      "    reraise(exc_type, exc_value, tb)\n",
      "  File \"C:\\Users\\Lenovo\\anaconda3\\lib\\site-packages\\flask\\_compat.py\", line 39, in reraise\n",
      "    raise value\n",
      "  File \"C:\\Users\\Lenovo\\anaconda3\\lib\\site-packages\\flask\\app.py\", line 1950, in full_dispatch_request\n",
      "    rv = self.dispatch_request()\n",
      "  File \"C:\\Users\\Lenovo\\anaconda3\\lib\\site-packages\\flask\\app.py\", line 1936, in dispatch_request\n",
      "    return self.view_functions[rule.endpoint](**req.view_args)\n",
      "  File \"C:\\Users\\Lenovo\\anaconda3\\lib\\site-packages\\gradio\\networking.py\", line 92, in wrapper\n",
      "    return func(*args, **kwargs)\n",
      "  File \"C:\\Users\\Lenovo\\anaconda3\\lib\\site-packages\\gradio\\networking.py\", line 180, in predict\n",
      "    prediction, durations = app.interface.process(raw_input)\n",
      "  File \"C:\\Users\\Lenovo\\anaconda3\\lib\\site-packages\\gradio\\interface.py\", line 334, in process\n",
      "    predictions, durations = self.run_prediction(processed_input, return_duration=True)\n",
      "  File \"C:\\Users\\Lenovo\\anaconda3\\lib\\site-packages\\gradio\\interface.py\", line 307, in run_prediction\n",
      "    prediction = predict_fn(*processed_input)\n",
      "  File \"<ipython-input-3-f9d94fe16654>\", line 3, in inference\n",
      "    df = pd.DataFrame([[age, s, ch, cardio]],\n",
      "NameError: name 'pd' is not defined\n",
      "[2021-09-12 11:30:33,138] ERROR in app: Exception on /api/predict/ [POST]\n",
      "Traceback (most recent call last):\n",
      "  File \"C:\\Users\\Lenovo\\anaconda3\\lib\\site-packages\\flask\\app.py\", line 2447, in wsgi_app\n",
      "    response = self.full_dispatch_request()\n",
      "  File \"C:\\Users\\Lenovo\\anaconda3\\lib\\site-packages\\flask\\app.py\", line 1952, in full_dispatch_request\n",
      "    rv = self.handle_user_exception(e)\n",
      "  File \"C:\\Users\\Lenovo\\anaconda3\\lib\\site-packages\\flask_cors\\extension.py\", line 165, in wrapped_function\n",
      "    return cors_after_request(app.make_response(f(*args, **kwargs)))\n",
      "  File \"C:\\Users\\Lenovo\\anaconda3\\lib\\site-packages\\flask\\app.py\", line 1821, in handle_user_exception\n",
      "    reraise(exc_type, exc_value, tb)\n",
      "  File \"C:\\Users\\Lenovo\\anaconda3\\lib\\site-packages\\flask\\_compat.py\", line 39, in reraise\n",
      "    raise value\n",
      "  File \"C:\\Users\\Lenovo\\anaconda3\\lib\\site-packages\\flask\\app.py\", line 1950, in full_dispatch_request\n",
      "    rv = self.dispatch_request()\n",
      "  File \"C:\\Users\\Lenovo\\anaconda3\\lib\\site-packages\\flask\\app.py\", line 1936, in dispatch_request\n",
      "    return self.view_functions[rule.endpoint](**req.view_args)\n",
      "  File \"C:\\Users\\Lenovo\\anaconda3\\lib\\site-packages\\gradio\\networking.py\", line 92, in wrapper\n",
      "    return func(*args, **kwargs)\n",
      "  File \"C:\\Users\\Lenovo\\anaconda3\\lib\\site-packages\\gradio\\networking.py\", line 180, in predict\n",
      "    prediction, durations = app.interface.process(raw_input)\n",
      "  File \"C:\\Users\\Lenovo\\anaconda3\\lib\\site-packages\\gradio\\interface.py\", line 334, in process\n",
      "    predictions, durations = self.run_prediction(processed_input, return_duration=True)\n",
      "  File \"C:\\Users\\Lenovo\\anaconda3\\lib\\site-packages\\gradio\\interface.py\", line 307, in run_prediction\n",
      "    prediction = predict_fn(*processed_input)\n",
      "  File \"<ipython-input-3-f9d94fe16654>\", line 3, in inference\n",
      "    df = pd.DataFrame([[age, s, ch, cardio]],\n",
      "NameError: name 'pd' is not defined\n",
      "[2021-09-12 11:30:33,150] ERROR in app: Exception on /api/predict/ [POST]\n",
      "Traceback (most recent call last):\n",
      "  File \"C:\\Users\\Lenovo\\anaconda3\\lib\\site-packages\\flask\\app.py\", line 2447, in wsgi_app\n",
      "    response = self.full_dispatch_request()\n",
      "  File \"C:\\Users\\Lenovo\\anaconda3\\lib\\site-packages\\flask\\app.py\", line 1952, in full_dispatch_request\n",
      "    rv = self.handle_user_exception(e)\n",
      "  File \"C:\\Users\\Lenovo\\anaconda3\\lib\\site-packages\\flask_cors\\extension.py\", line 165, in wrapped_function\n",
      "    return cors_after_request(app.make_response(f(*args, **kwargs)))\n",
      "  File \"C:\\Users\\Lenovo\\anaconda3\\lib\\site-packages\\flask\\app.py\", line 1821, in handle_user_exception\n",
      "    reraise(exc_type, exc_value, tb)\n",
      "  File \"C:\\Users\\Lenovo\\anaconda3\\lib\\site-packages\\flask\\_compat.py\", line 39, in reraise\n",
      "    raise value\n",
      "  File \"C:\\Users\\Lenovo\\anaconda3\\lib\\site-packages\\flask\\app.py\", line 1950, in full_dispatch_request\n",
      "    rv = self.dispatch_request()\n",
      "  File \"C:\\Users\\Lenovo\\anaconda3\\lib\\site-packages\\flask\\app.py\", line 1936, in dispatch_request\n",
      "    return self.view_functions[rule.endpoint](**req.view_args)\n",
      "  File \"C:\\Users\\Lenovo\\anaconda3\\lib\\site-packages\\gradio\\networking.py\", line 92, in wrapper\n",
      "    return func(*args, **kwargs)\n",
      "  File \"C:\\Users\\Lenovo\\anaconda3\\lib\\site-packages\\gradio\\networking.py\", line 180, in predict\n",
      "    prediction, durations = app.interface.process(raw_input)\n",
      "  File \"C:\\Users\\Lenovo\\anaconda3\\lib\\site-packages\\gradio\\interface.py\", line 334, in process\n",
      "    predictions, durations = self.run_prediction(processed_input, return_duration=True)\n",
      "  File \"C:\\Users\\Lenovo\\anaconda3\\lib\\site-packages\\gradio\\interface.py\", line 307, in run_prediction\n",
      "    prediction = predict_fn(*processed_input)\n",
      "  File \"<ipython-input-3-f9d94fe16654>\", line 3, in inference\n",
      "    df = pd.DataFrame([[age, s, ch, cardio]],\n",
      "NameError: name 'pd' is not defined\n",
      "[2021-09-12 11:30:33,158] ERROR in app: Exception on /api/predict/ [POST]\n",
      "Traceback (most recent call last):\n",
      "  File \"C:\\Users\\Lenovo\\anaconda3\\lib\\site-packages\\flask\\app.py\", line 2447, in wsgi_app\n",
      "    response = self.full_dispatch_request()\n",
      "  File \"C:\\Users\\Lenovo\\anaconda3\\lib\\site-packages\\flask\\app.py\", line 1952, in full_dispatch_request\n",
      "    rv = self.handle_user_exception(e)\n",
      "  File \"C:\\Users\\Lenovo\\anaconda3\\lib\\site-packages\\flask_cors\\extension.py\", line 165, in wrapped_function\n",
      "    return cors_after_request(app.make_response(f(*args, **kwargs)))\n",
      "  File \"C:\\Users\\Lenovo\\anaconda3\\lib\\site-packages\\flask\\app.py\", line 1821, in handle_user_exception\n",
      "    reraise(exc_type, exc_value, tb)\n",
      "  File \"C:\\Users\\Lenovo\\anaconda3\\lib\\site-packages\\flask\\_compat.py\", line 39, in reraise\n",
      "    raise value\n",
      "  File \"C:\\Users\\Lenovo\\anaconda3\\lib\\site-packages\\flask\\app.py\", line 1950, in full_dispatch_request\n",
      "    rv = self.dispatch_request()\n",
      "  File \"C:\\Users\\Lenovo\\anaconda3\\lib\\site-packages\\flask\\app.py\", line 1936, in dispatch_request\n",
      "    return self.view_functions[rule.endpoint](**req.view_args)\n",
      "  File \"C:\\Users\\Lenovo\\anaconda3\\lib\\site-packages\\gradio\\networking.py\", line 92, in wrapper\n",
      "    return func(*args, **kwargs)\n",
      "  File \"C:\\Users\\Lenovo\\anaconda3\\lib\\site-packages\\gradio\\networking.py\", line 180, in predict\n",
      "    prediction, durations = app.interface.process(raw_input)\n",
      "  File \"C:\\Users\\Lenovo\\anaconda3\\lib\\site-packages\\gradio\\interface.py\", line 334, in process\n",
      "    predictions, durations = self.run_prediction(processed_input, return_duration=True)\n",
      "  File \"C:\\Users\\Lenovo\\anaconda3\\lib\\site-packages\\gradio\\interface.py\", line 307, in run_prediction\n",
      "    prediction = predict_fn(*processed_input)\n",
      "  File \"<ipython-input-3-f9d94fe16654>\", line 3, in inference\n",
      "    df = pd.DataFrame([[age, s, ch, cardio]],\n",
      "NameError: name 'pd' is not defined\n"
     ]
    },
    {
     "name": "stderr",
     "output_type": "stream",
     "text": [
      "[2021-09-12 11:30:33,165] ERROR in app: Exception on /api/predict/ [POST]\n",
      "Traceback (most recent call last):\n",
      "  File \"C:\\Users\\Lenovo\\anaconda3\\lib\\site-packages\\flask\\app.py\", line 2447, in wsgi_app\n",
      "    response = self.full_dispatch_request()\n",
      "  File \"C:\\Users\\Lenovo\\anaconda3\\lib\\site-packages\\flask\\app.py\", line 1952, in full_dispatch_request\n",
      "    rv = self.handle_user_exception(e)\n",
      "  File \"C:\\Users\\Lenovo\\anaconda3\\lib\\site-packages\\flask_cors\\extension.py\", line 165, in wrapped_function\n",
      "    return cors_after_request(app.make_response(f(*args, **kwargs)))\n",
      "  File \"C:\\Users\\Lenovo\\anaconda3\\lib\\site-packages\\flask\\app.py\", line 1821, in handle_user_exception\n",
      "    reraise(exc_type, exc_value, tb)\n",
      "  File \"C:\\Users\\Lenovo\\anaconda3\\lib\\site-packages\\flask\\_compat.py\", line 39, in reraise\n",
      "    raise value\n",
      "  File \"C:\\Users\\Lenovo\\anaconda3\\lib\\site-packages\\flask\\app.py\", line 1950, in full_dispatch_request\n",
      "    rv = self.dispatch_request()\n",
      "  File \"C:\\Users\\Lenovo\\anaconda3\\lib\\site-packages\\flask\\app.py\", line 1936, in dispatch_request\n",
      "    return self.view_functions[rule.endpoint](**req.view_args)\n",
      "  File \"C:\\Users\\Lenovo\\anaconda3\\lib\\site-packages\\gradio\\networking.py\", line 92, in wrapper\n",
      "    return func(*args, **kwargs)\n",
      "  File \"C:\\Users\\Lenovo\\anaconda3\\lib\\site-packages\\gradio\\networking.py\", line 180, in predict\n",
      "    prediction, durations = app.interface.process(raw_input)\n",
      "  File \"C:\\Users\\Lenovo\\anaconda3\\lib\\site-packages\\gradio\\interface.py\", line 334, in process\n",
      "    predictions, durations = self.run_prediction(processed_input, return_duration=True)\n",
      "  File \"C:\\Users\\Lenovo\\anaconda3\\lib\\site-packages\\gradio\\interface.py\", line 307, in run_prediction\n",
      "    prediction = predict_fn(*processed_input)\n",
      "  File \"<ipython-input-3-f9d94fe16654>\", line 3, in inference\n",
      "    df = pd.DataFrame([[age, s, ch, cardio]],\n",
      "NameError: name 'pd' is not defined\n",
      "[2021-09-12 11:30:33,179] ERROR in app: Exception on /api/predict/ [POST]\n",
      "Traceback (most recent call last):\n",
      "  File \"C:\\Users\\Lenovo\\anaconda3\\lib\\site-packages\\flask\\app.py\", line 2447, in wsgi_app\n",
      "    response = self.full_dispatch_request()\n",
      "  File \"C:\\Users\\Lenovo\\anaconda3\\lib\\site-packages\\flask\\app.py\", line 1952, in full_dispatch_request\n",
      "    rv = self.handle_user_exception(e)\n",
      "  File \"C:\\Users\\Lenovo\\anaconda3\\lib\\site-packages\\flask_cors\\extension.py\", line 165, in wrapped_function\n",
      "    return cors_after_request(app.make_response(f(*args, **kwargs)))\n",
      "  File \"C:\\Users\\Lenovo\\anaconda3\\lib\\site-packages\\flask\\app.py\", line 1821, in handle_user_exception\n",
      "    reraise(exc_type, exc_value, tb)\n",
      "  File \"C:\\Users\\Lenovo\\anaconda3\\lib\\site-packages\\flask\\_compat.py\", line 39, in reraise\n",
      "    raise value\n",
      "  File \"C:\\Users\\Lenovo\\anaconda3\\lib\\site-packages\\flask\\app.py\", line 1950, in full_dispatch_request\n",
      "    rv = self.dispatch_request()\n",
      "  File \"C:\\Users\\Lenovo\\anaconda3\\lib\\site-packages\\flask\\app.py\", line 1936, in dispatch_request\n",
      "    return self.view_functions[rule.endpoint](**req.view_args)\n",
      "  File \"C:\\Users\\Lenovo\\anaconda3\\lib\\site-packages\\gradio\\networking.py\", line 92, in wrapper\n",
      "    return func(*args, **kwargs)\n",
      "  File \"C:\\Users\\Lenovo\\anaconda3\\lib\\site-packages\\gradio\\networking.py\", line 180, in predict\n",
      "    prediction, durations = app.interface.process(raw_input)\n",
      "  File \"C:\\Users\\Lenovo\\anaconda3\\lib\\site-packages\\gradio\\interface.py\", line 334, in process\n",
      "    predictions, durations = self.run_prediction(processed_input, return_duration=True)\n",
      "  File \"C:\\Users\\Lenovo\\anaconda3\\lib\\site-packages\\gradio\\interface.py\", line 307, in run_prediction\n",
      "    prediction = predict_fn(*processed_input)\n",
      "  File \"<ipython-input-3-f9d94fe16654>\", line 3, in inference\n",
      "    df = pd.DataFrame([[age, s, ch, cardio]],\n",
      "NameError: name 'pd' is not defined\n",
      "[2021-09-12 11:30:33,192] ERROR in app: Exception on /api/predict/ [POST]\n",
      "Traceback (most recent call last):\n",
      "  File \"C:\\Users\\Lenovo\\anaconda3\\lib\\site-packages\\flask\\app.py\", line 2447, in wsgi_app\n",
      "    response = self.full_dispatch_request()\n",
      "  File \"C:\\Users\\Lenovo\\anaconda3\\lib\\site-packages\\flask\\app.py\", line 1952, in full_dispatch_request\n",
      "    rv = self.handle_user_exception(e)\n",
      "  File \"C:\\Users\\Lenovo\\anaconda3\\lib\\site-packages\\flask_cors\\extension.py\", line 165, in wrapped_function\n",
      "    return cors_after_request(app.make_response(f(*args, **kwargs)))\n",
      "  File \"C:\\Users\\Lenovo\\anaconda3\\lib\\site-packages\\flask\\app.py\", line 1821, in handle_user_exception\n",
      "    reraise(exc_type, exc_value, tb)\n",
      "  File \"C:\\Users\\Lenovo\\anaconda3\\lib\\site-packages\\flask\\_compat.py\", line 39, in reraise\n",
      "    raise value\n",
      "  File \"C:\\Users\\Lenovo\\anaconda3\\lib\\site-packages\\flask\\app.py\", line 1950, in full_dispatch_request\n",
      "    rv = self.dispatch_request()\n",
      "  File \"C:\\Users\\Lenovo\\anaconda3\\lib\\site-packages\\flask\\app.py\", line 1936, in dispatch_request\n",
      "    return self.view_functions[rule.endpoint](**req.view_args)\n",
      "  File \"C:\\Users\\Lenovo\\anaconda3\\lib\\site-packages\\gradio\\networking.py\", line 92, in wrapper\n",
      "    return func(*args, **kwargs)\n",
      "  File \"C:\\Users\\Lenovo\\anaconda3\\lib\\site-packages\\gradio\\networking.py\", line 180, in predict\n",
      "    prediction, durations = app.interface.process(raw_input)\n",
      "  File \"C:\\Users\\Lenovo\\anaconda3\\lib\\site-packages\\gradio\\interface.py\", line 334, in process\n",
      "    predictions, durations = self.run_prediction(processed_input, return_duration=True)\n",
      "  File \"C:\\Users\\Lenovo\\anaconda3\\lib\\site-packages\\gradio\\interface.py\", line 307, in run_prediction\n",
      "    prediction = predict_fn(*processed_input)\n",
      "  File \"<ipython-input-3-f9d94fe16654>\", line 3, in inference\n",
      "    df = pd.DataFrame([[age, s, ch, cardio]],\n",
      "NameError: name 'pd' is not defined\n",
      "[2021-09-12 11:30:33,198] ERROR in app: Exception on /api/predict/ [POST]\n",
      "Traceback (most recent call last):\n",
      "  File \"C:\\Users\\Lenovo\\anaconda3\\lib\\site-packages\\flask\\app.py\", line 2447, in wsgi_app\n",
      "    response = self.full_dispatch_request()\n",
      "  File \"C:\\Users\\Lenovo\\anaconda3\\lib\\site-packages\\flask\\app.py\", line 1952, in full_dispatch_request\n",
      "    rv = self.handle_user_exception(e)\n",
      "  File \"C:\\Users\\Lenovo\\anaconda3\\lib\\site-packages\\flask_cors\\extension.py\", line 165, in wrapped_function\n",
      "    return cors_after_request(app.make_response(f(*args, **kwargs)))\n",
      "  File \"C:\\Users\\Lenovo\\anaconda3\\lib\\site-packages\\flask\\app.py\", line 1821, in handle_user_exception\n",
      "    reraise(exc_type, exc_value, tb)\n",
      "  File \"C:\\Users\\Lenovo\\anaconda3\\lib\\site-packages\\flask\\_compat.py\", line 39, in reraise\n",
      "    raise value\n",
      "  File \"C:\\Users\\Lenovo\\anaconda3\\lib\\site-packages\\flask\\app.py\", line 1950, in full_dispatch_request\n",
      "    rv = self.dispatch_request()\n",
      "  File \"C:\\Users\\Lenovo\\anaconda3\\lib\\site-packages\\flask\\app.py\", line 1936, in dispatch_request\n",
      "    return self.view_functions[rule.endpoint](**req.view_args)\n",
      "  File \"C:\\Users\\Lenovo\\anaconda3\\lib\\site-packages\\gradio\\networking.py\", line 92, in wrapper\n",
      "    return func(*args, **kwargs)\n",
      "  File \"C:\\Users\\Lenovo\\anaconda3\\lib\\site-packages\\gradio\\networking.py\", line 180, in predict\n",
      "    prediction, durations = app.interface.process(raw_input)\n",
      "  File \"C:\\Users\\Lenovo\\anaconda3\\lib\\site-packages\\gradio\\interface.py\", line 334, in process\n",
      "    predictions, durations = self.run_prediction(processed_input, return_duration=True)\n",
      "  File \"C:\\Users\\Lenovo\\anaconda3\\lib\\site-packages\\gradio\\interface.py\", line 307, in run_prediction\n",
      "    prediction = predict_fn(*processed_input)\n",
      "  File \"<ipython-input-3-f9d94fe16654>\", line 3, in inference\n",
      "    df = pd.DataFrame([[age, s, ch, cardio]],\n",
      "NameError: name 'pd' is not defined\n",
      "[2021-09-12 11:30:33,206] ERROR in app: Exception on /api/predict/ [POST]\n",
      "Traceback (most recent call last):\n",
      "  File \"C:\\Users\\Lenovo\\anaconda3\\lib\\site-packages\\flask\\app.py\", line 2447, in wsgi_app\n",
      "    response = self.full_dispatch_request()\n",
      "  File \"C:\\Users\\Lenovo\\anaconda3\\lib\\site-packages\\flask\\app.py\", line 1952, in full_dispatch_request\n",
      "    rv = self.handle_user_exception(e)\n",
      "  File \"C:\\Users\\Lenovo\\anaconda3\\lib\\site-packages\\flask_cors\\extension.py\", line 165, in wrapped_function\n",
      "    return cors_after_request(app.make_response(f(*args, **kwargs)))\n",
      "  File \"C:\\Users\\Lenovo\\anaconda3\\lib\\site-packages\\flask\\app.py\", line 1821, in handle_user_exception\n",
      "    reraise(exc_type, exc_value, tb)\n",
      "  File \"C:\\Users\\Lenovo\\anaconda3\\lib\\site-packages\\flask\\_compat.py\", line 39, in reraise\n",
      "    raise value\n",
      "  File \"C:\\Users\\Lenovo\\anaconda3\\lib\\site-packages\\flask\\app.py\", line 1950, in full_dispatch_request\n",
      "    rv = self.dispatch_request()\n",
      "  File \"C:\\Users\\Lenovo\\anaconda3\\lib\\site-packages\\flask\\app.py\", line 1936, in dispatch_request\n",
      "    return self.view_functions[rule.endpoint](**req.view_args)\n",
      "  File \"C:\\Users\\Lenovo\\anaconda3\\lib\\site-packages\\gradio\\networking.py\", line 92, in wrapper\n",
      "    return func(*args, **kwargs)\n",
      "  File \"C:\\Users\\Lenovo\\anaconda3\\lib\\site-packages\\gradio\\networking.py\", line 180, in predict\n",
      "    prediction, durations = app.interface.process(raw_input)\n",
      "  File \"C:\\Users\\Lenovo\\anaconda3\\lib\\site-packages\\gradio\\interface.py\", line 334, in process\n",
      "    predictions, durations = self.run_prediction(processed_input, return_duration=True)\n",
      "  File \"C:\\Users\\Lenovo\\anaconda3\\lib\\site-packages\\gradio\\interface.py\", line 307, in run_prediction\n",
      "    prediction = predict_fn(*processed_input)\n",
      "  File \"<ipython-input-3-f9d94fe16654>\", line 3, in inference\n",
      "    df = pd.DataFrame([[age, s, ch, cardio]],\n",
      "NameError: name 'pd' is not defined\n"
     ]
    },
    {
     "name": "stderr",
     "output_type": "stream",
     "text": [
      "[2021-09-12 11:30:33,213] ERROR in app: Exception on /api/predict/ [POST]\n",
      "Traceback (most recent call last):\n",
      "  File \"C:\\Users\\Lenovo\\anaconda3\\lib\\site-packages\\flask\\app.py\", line 2447, in wsgi_app\n",
      "    response = self.full_dispatch_request()\n",
      "  File \"C:\\Users\\Lenovo\\anaconda3\\lib\\site-packages\\flask\\app.py\", line 1952, in full_dispatch_request\n",
      "    rv = self.handle_user_exception(e)\n",
      "  File \"C:\\Users\\Lenovo\\anaconda3\\lib\\site-packages\\flask_cors\\extension.py\", line 165, in wrapped_function\n",
      "    return cors_after_request(app.make_response(f(*args, **kwargs)))\n",
      "  File \"C:\\Users\\Lenovo\\anaconda3\\lib\\site-packages\\flask\\app.py\", line 1821, in handle_user_exception\n",
      "    reraise(exc_type, exc_value, tb)\n",
      "  File \"C:\\Users\\Lenovo\\anaconda3\\lib\\site-packages\\flask\\_compat.py\", line 39, in reraise\n",
      "    raise value\n",
      "  File \"C:\\Users\\Lenovo\\anaconda3\\lib\\site-packages\\flask\\app.py\", line 1950, in full_dispatch_request\n",
      "    rv = self.dispatch_request()\n",
      "  File \"C:\\Users\\Lenovo\\anaconda3\\lib\\site-packages\\flask\\app.py\", line 1936, in dispatch_request\n",
      "    return self.view_functions[rule.endpoint](**req.view_args)\n",
      "  File \"C:\\Users\\Lenovo\\anaconda3\\lib\\site-packages\\gradio\\networking.py\", line 92, in wrapper\n",
      "    return func(*args, **kwargs)\n",
      "  File \"C:\\Users\\Lenovo\\anaconda3\\lib\\site-packages\\gradio\\networking.py\", line 180, in predict\n",
      "    prediction, durations = app.interface.process(raw_input)\n",
      "  File \"C:\\Users\\Lenovo\\anaconda3\\lib\\site-packages\\gradio\\interface.py\", line 334, in process\n",
      "    predictions, durations = self.run_prediction(processed_input, return_duration=True)\n",
      "  File \"C:\\Users\\Lenovo\\anaconda3\\lib\\site-packages\\gradio\\interface.py\", line 307, in run_prediction\n",
      "    prediction = predict_fn(*processed_input)\n",
      "  File \"<ipython-input-3-f9d94fe16654>\", line 3, in inference\n",
      "    df = pd.DataFrame([[age, s, ch, cardio]],\n",
      "NameError: name 'pd' is not defined\n",
      "[2021-09-12 11:30:33,226] ERROR in app: Exception on /api/predict/ [POST]\n",
      "Traceback (most recent call last):\n",
      "  File \"C:\\Users\\Lenovo\\anaconda3\\lib\\site-packages\\flask\\app.py\", line 2447, in wsgi_app\n",
      "    response = self.full_dispatch_request()\n",
      "  File \"C:\\Users\\Lenovo\\anaconda3\\lib\\site-packages\\flask\\app.py\", line 1952, in full_dispatch_request\n",
      "    rv = self.handle_user_exception(e)\n",
      "  File \"C:\\Users\\Lenovo\\anaconda3\\lib\\site-packages\\flask_cors\\extension.py\", line 165, in wrapped_function\n",
      "    return cors_after_request(app.make_response(f(*args, **kwargs)))\n",
      "  File \"C:\\Users\\Lenovo\\anaconda3\\lib\\site-packages\\flask\\app.py\", line 1821, in handle_user_exception\n",
      "    reraise(exc_type, exc_value, tb)\n",
      "  File \"C:\\Users\\Lenovo\\anaconda3\\lib\\site-packages\\flask\\_compat.py\", line 39, in reraise\n",
      "    raise value\n",
      "  File \"C:\\Users\\Lenovo\\anaconda3\\lib\\site-packages\\flask\\app.py\", line 1950, in full_dispatch_request\n",
      "    rv = self.dispatch_request()\n",
      "  File \"C:\\Users\\Lenovo\\anaconda3\\lib\\site-packages\\flask\\app.py\", line 1936, in dispatch_request\n",
      "    return self.view_functions[rule.endpoint](**req.view_args)\n",
      "  File \"C:\\Users\\Lenovo\\anaconda3\\lib\\site-packages\\gradio\\networking.py\", line 92, in wrapper\n",
      "    return func(*args, **kwargs)\n",
      "  File \"C:\\Users\\Lenovo\\anaconda3\\lib\\site-packages\\gradio\\networking.py\", line 180, in predict\n",
      "    prediction, durations = app.interface.process(raw_input)\n",
      "  File \"C:\\Users\\Lenovo\\anaconda3\\lib\\site-packages\\gradio\\interface.py\", line 334, in process\n",
      "    predictions, durations = self.run_prediction(processed_input, return_duration=True)\n",
      "  File \"C:\\Users\\Lenovo\\anaconda3\\lib\\site-packages\\gradio\\interface.py\", line 307, in run_prediction\n",
      "    prediction = predict_fn(*processed_input)\n",
      "  File \"<ipython-input-3-f9d94fe16654>\", line 3, in inference\n",
      "    df = pd.DataFrame([[age, s, ch, cardio]],\n",
      "NameError: name 'pd' is not defined\n",
      "[2021-09-12 11:30:33,234] ERROR in app: Exception on /api/predict/ [POST]\n",
      "Traceback (most recent call last):\n",
      "  File \"C:\\Users\\Lenovo\\anaconda3\\lib\\site-packages\\flask\\app.py\", line 2447, in wsgi_app\n",
      "    response = self.full_dispatch_request()\n",
      "  File \"C:\\Users\\Lenovo\\anaconda3\\lib\\site-packages\\flask\\app.py\", line 1952, in full_dispatch_request\n",
      "    rv = self.handle_user_exception(e)\n",
      "  File \"C:\\Users\\Lenovo\\anaconda3\\lib\\site-packages\\flask_cors\\extension.py\", line 165, in wrapped_function\n",
      "    return cors_after_request(app.make_response(f(*args, **kwargs)))\n",
      "  File \"C:\\Users\\Lenovo\\anaconda3\\lib\\site-packages\\flask\\app.py\", line 1821, in handle_user_exception\n",
      "    reraise(exc_type, exc_value, tb)\n",
      "  File \"C:\\Users\\Lenovo\\anaconda3\\lib\\site-packages\\flask\\_compat.py\", line 39, in reraise\n",
      "    raise value\n",
      "  File \"C:\\Users\\Lenovo\\anaconda3\\lib\\site-packages\\flask\\app.py\", line 1950, in full_dispatch_request\n",
      "    rv = self.dispatch_request()\n",
      "  File \"C:\\Users\\Lenovo\\anaconda3\\lib\\site-packages\\flask\\app.py\", line 1936, in dispatch_request\n",
      "    return self.view_functions[rule.endpoint](**req.view_args)\n",
      "  File \"C:\\Users\\Lenovo\\anaconda3\\lib\\site-packages\\gradio\\networking.py\", line 92, in wrapper\n",
      "    return func(*args, **kwargs)\n",
      "  File \"C:\\Users\\Lenovo\\anaconda3\\lib\\site-packages\\gradio\\networking.py\", line 180, in predict\n",
      "    prediction, durations = app.interface.process(raw_input)\n",
      "  File \"C:\\Users\\Lenovo\\anaconda3\\lib\\site-packages\\gradio\\interface.py\", line 334, in process\n",
      "    predictions, durations = self.run_prediction(processed_input, return_duration=True)\n",
      "  File \"C:\\Users\\Lenovo\\anaconda3\\lib\\site-packages\\gradio\\interface.py\", line 307, in run_prediction\n",
      "    prediction = predict_fn(*processed_input)\n",
      "  File \"<ipython-input-3-f9d94fe16654>\", line 3, in inference\n",
      "    df = pd.DataFrame([[age, s, ch, cardio]],\n",
      "NameError: name 'pd' is not defined\n",
      "[2021-09-12 11:30:33,240] ERROR in app: Exception on /api/predict/ [POST]\n",
      "Traceback (most recent call last):\n",
      "  File \"C:\\Users\\Lenovo\\anaconda3\\lib\\site-packages\\flask\\app.py\", line 2447, in wsgi_app\n",
      "    response = self.full_dispatch_request()\n",
      "  File \"C:\\Users\\Lenovo\\anaconda3\\lib\\site-packages\\flask\\app.py\", line 1952, in full_dispatch_request\n",
      "    rv = self.handle_user_exception(e)\n",
      "  File \"C:\\Users\\Lenovo\\anaconda3\\lib\\site-packages\\flask_cors\\extension.py\", line 165, in wrapped_function\n",
      "    return cors_after_request(app.make_response(f(*args, **kwargs)))\n",
      "  File \"C:\\Users\\Lenovo\\anaconda3\\lib\\site-packages\\flask\\app.py\", line 1821, in handle_user_exception\n",
      "    reraise(exc_type, exc_value, tb)\n",
      "  File \"C:\\Users\\Lenovo\\anaconda3\\lib\\site-packages\\flask\\_compat.py\", line 39, in reraise\n",
      "    raise value\n",
      "  File \"C:\\Users\\Lenovo\\anaconda3\\lib\\site-packages\\flask\\app.py\", line 1950, in full_dispatch_request\n",
      "    rv = self.dispatch_request()\n",
      "  File \"C:\\Users\\Lenovo\\anaconda3\\lib\\site-packages\\flask\\app.py\", line 1936, in dispatch_request\n",
      "    return self.view_functions[rule.endpoint](**req.view_args)\n",
      "  File \"C:\\Users\\Lenovo\\anaconda3\\lib\\site-packages\\gradio\\networking.py\", line 92, in wrapper\n",
      "    return func(*args, **kwargs)\n",
      "  File \"C:\\Users\\Lenovo\\anaconda3\\lib\\site-packages\\gradio\\networking.py\", line 180, in predict\n",
      "    prediction, durations = app.interface.process(raw_input)\n",
      "  File \"C:\\Users\\Lenovo\\anaconda3\\lib\\site-packages\\gradio\\interface.py\", line 334, in process\n",
      "    predictions, durations = self.run_prediction(processed_input, return_duration=True)\n",
      "  File \"C:\\Users\\Lenovo\\anaconda3\\lib\\site-packages\\gradio\\interface.py\", line 307, in run_prediction\n",
      "    prediction = predict_fn(*processed_input)\n",
      "  File \"<ipython-input-3-f9d94fe16654>\", line 3, in inference\n",
      "    df = pd.DataFrame([[age, s, ch, cardio]],\n",
      "NameError: name 'pd' is not defined\n",
      "[2021-09-12 11:30:33,247] ERROR in app: Exception on /api/predict/ [POST]\n",
      "Traceback (most recent call last):\n",
      "  File \"C:\\Users\\Lenovo\\anaconda3\\lib\\site-packages\\flask\\app.py\", line 2447, in wsgi_app\n",
      "    response = self.full_dispatch_request()\n",
      "  File \"C:\\Users\\Lenovo\\anaconda3\\lib\\site-packages\\flask\\app.py\", line 1952, in full_dispatch_request\n",
      "    rv = self.handle_user_exception(e)\n",
      "  File \"C:\\Users\\Lenovo\\anaconda3\\lib\\site-packages\\flask_cors\\extension.py\", line 165, in wrapped_function\n",
      "    return cors_after_request(app.make_response(f(*args, **kwargs)))\n",
      "  File \"C:\\Users\\Lenovo\\anaconda3\\lib\\site-packages\\flask\\app.py\", line 1821, in handle_user_exception\n",
      "    reraise(exc_type, exc_value, tb)\n",
      "  File \"C:\\Users\\Lenovo\\anaconda3\\lib\\site-packages\\flask\\_compat.py\", line 39, in reraise\n",
      "    raise value\n",
      "  File \"C:\\Users\\Lenovo\\anaconda3\\lib\\site-packages\\flask\\app.py\", line 1950, in full_dispatch_request\n",
      "    rv = self.dispatch_request()\n",
      "  File \"C:\\Users\\Lenovo\\anaconda3\\lib\\site-packages\\flask\\app.py\", line 1936, in dispatch_request\n",
      "    return self.view_functions[rule.endpoint](**req.view_args)\n",
      "  File \"C:\\Users\\Lenovo\\anaconda3\\lib\\site-packages\\gradio\\networking.py\", line 92, in wrapper\n",
      "    return func(*args, **kwargs)\n",
      "  File \"C:\\Users\\Lenovo\\anaconda3\\lib\\site-packages\\gradio\\networking.py\", line 180, in predict\n",
      "    prediction, durations = app.interface.process(raw_input)\n",
      "  File \"C:\\Users\\Lenovo\\anaconda3\\lib\\site-packages\\gradio\\interface.py\", line 334, in process\n",
      "    predictions, durations = self.run_prediction(processed_input, return_duration=True)\n",
      "  File \"C:\\Users\\Lenovo\\anaconda3\\lib\\site-packages\\gradio\\interface.py\", line 307, in run_prediction\n",
      "    prediction = predict_fn(*processed_input)\n",
      "  File \"<ipython-input-3-f9d94fe16654>\", line 3, in inference\n",
      "    df = pd.DataFrame([[age, s, ch, cardio]],\n",
      "NameError: name 'pd' is not defined\n"
     ]
    },
    {
     "name": "stderr",
     "output_type": "stream",
     "text": [
      "[2021-09-12 11:30:33,254] ERROR in app: Exception on /api/predict/ [POST]\n",
      "Traceback (most recent call last):\n",
      "  File \"C:\\Users\\Lenovo\\anaconda3\\lib\\site-packages\\flask\\app.py\", line 2447, in wsgi_app\n",
      "    response = self.full_dispatch_request()\n",
      "  File \"C:\\Users\\Lenovo\\anaconda3\\lib\\site-packages\\flask\\app.py\", line 1952, in full_dispatch_request\n",
      "    rv = self.handle_user_exception(e)\n",
      "  File \"C:\\Users\\Lenovo\\anaconda3\\lib\\site-packages\\flask_cors\\extension.py\", line 165, in wrapped_function\n",
      "    return cors_after_request(app.make_response(f(*args, **kwargs)))\n",
      "  File \"C:\\Users\\Lenovo\\anaconda3\\lib\\site-packages\\flask\\app.py\", line 1821, in handle_user_exception\n",
      "    reraise(exc_type, exc_value, tb)\n",
      "  File \"C:\\Users\\Lenovo\\anaconda3\\lib\\site-packages\\flask\\_compat.py\", line 39, in reraise\n",
      "    raise value\n",
      "  File \"C:\\Users\\Lenovo\\anaconda3\\lib\\site-packages\\flask\\app.py\", line 1950, in full_dispatch_request\n",
      "    rv = self.dispatch_request()\n",
      "  File \"C:\\Users\\Lenovo\\anaconda3\\lib\\site-packages\\flask\\app.py\", line 1936, in dispatch_request\n",
      "    return self.view_functions[rule.endpoint](**req.view_args)\n",
      "  File \"C:\\Users\\Lenovo\\anaconda3\\lib\\site-packages\\gradio\\networking.py\", line 92, in wrapper\n",
      "    return func(*args, **kwargs)\n",
      "  File \"C:\\Users\\Lenovo\\anaconda3\\lib\\site-packages\\gradio\\networking.py\", line 180, in predict\n",
      "    prediction, durations = app.interface.process(raw_input)\n",
      "  File \"C:\\Users\\Lenovo\\anaconda3\\lib\\site-packages\\gradio\\interface.py\", line 334, in process\n",
      "    predictions, durations = self.run_prediction(processed_input, return_duration=True)\n",
      "  File \"C:\\Users\\Lenovo\\anaconda3\\lib\\site-packages\\gradio\\interface.py\", line 307, in run_prediction\n",
      "    prediction = predict_fn(*processed_input)\n",
      "  File \"<ipython-input-3-f9d94fe16654>\", line 3, in inference\n",
      "    df = pd.DataFrame([[age, s, ch, cardio]],\n",
      "NameError: name 'pd' is not defined\n",
      "[2021-09-12 11:30:33,261] ERROR in app: Exception on /api/predict/ [POST]\n",
      "Traceback (most recent call last):\n",
      "  File \"C:\\Users\\Lenovo\\anaconda3\\lib\\site-packages\\flask\\app.py\", line 2447, in wsgi_app\n",
      "    response = self.full_dispatch_request()\n",
      "  File \"C:\\Users\\Lenovo\\anaconda3\\lib\\site-packages\\flask\\app.py\", line 1952, in full_dispatch_request\n",
      "    rv = self.handle_user_exception(e)\n",
      "  File \"C:\\Users\\Lenovo\\anaconda3\\lib\\site-packages\\flask_cors\\extension.py\", line 165, in wrapped_function\n",
      "    return cors_after_request(app.make_response(f(*args, **kwargs)))\n",
      "  File \"C:\\Users\\Lenovo\\anaconda3\\lib\\site-packages\\flask\\app.py\", line 1821, in handle_user_exception\n",
      "    reraise(exc_type, exc_value, tb)\n",
      "  File \"C:\\Users\\Lenovo\\anaconda3\\lib\\site-packages\\flask\\_compat.py\", line 39, in reraise\n",
      "    raise value\n",
      "  File \"C:\\Users\\Lenovo\\anaconda3\\lib\\site-packages\\flask\\app.py\", line 1950, in full_dispatch_request\n",
      "    rv = self.dispatch_request()\n",
      "  File \"C:\\Users\\Lenovo\\anaconda3\\lib\\site-packages\\flask\\app.py\", line 1936, in dispatch_request\n",
      "    return self.view_functions[rule.endpoint](**req.view_args)\n",
      "  File \"C:\\Users\\Lenovo\\anaconda3\\lib\\site-packages\\gradio\\networking.py\", line 92, in wrapper\n",
      "    return func(*args, **kwargs)\n",
      "  File \"C:\\Users\\Lenovo\\anaconda3\\lib\\site-packages\\gradio\\networking.py\", line 180, in predict\n",
      "    prediction, durations = app.interface.process(raw_input)\n",
      "  File \"C:\\Users\\Lenovo\\anaconda3\\lib\\site-packages\\gradio\\interface.py\", line 334, in process\n",
      "    predictions, durations = self.run_prediction(processed_input, return_duration=True)\n",
      "  File \"C:\\Users\\Lenovo\\anaconda3\\lib\\site-packages\\gradio\\interface.py\", line 307, in run_prediction\n",
      "    prediction = predict_fn(*processed_input)\n",
      "  File \"<ipython-input-3-f9d94fe16654>\", line 3, in inference\n",
      "    df = pd.DataFrame([[age, s, ch, cardio]],\n",
      "NameError: name 'pd' is not defined\n",
      "[2021-09-12 11:30:33,275] ERROR in app: Exception on /api/predict/ [POST]\n",
      "Traceback (most recent call last):\n",
      "  File \"C:\\Users\\Lenovo\\anaconda3\\lib\\site-packages\\flask\\app.py\", line 2447, in wsgi_app\n",
      "    response = self.full_dispatch_request()\n",
      "  File \"C:\\Users\\Lenovo\\anaconda3\\lib\\site-packages\\flask\\app.py\", line 1952, in full_dispatch_request\n",
      "    rv = self.handle_user_exception(e)\n",
      "  File \"C:\\Users\\Lenovo\\anaconda3\\lib\\site-packages\\flask_cors\\extension.py\", line 165, in wrapped_function\n",
      "    return cors_after_request(app.make_response(f(*args, **kwargs)))\n",
      "  File \"C:\\Users\\Lenovo\\anaconda3\\lib\\site-packages\\flask\\app.py\", line 1821, in handle_user_exception\n",
      "    reraise(exc_type, exc_value, tb)\n",
      "  File \"C:\\Users\\Lenovo\\anaconda3\\lib\\site-packages\\flask\\_compat.py\", line 39, in reraise\n",
      "    raise value\n",
      "  File \"C:\\Users\\Lenovo\\anaconda3\\lib\\site-packages\\flask\\app.py\", line 1950, in full_dispatch_request\n",
      "    rv = self.dispatch_request()\n",
      "  File \"C:\\Users\\Lenovo\\anaconda3\\lib\\site-packages\\flask\\app.py\", line 1936, in dispatch_request\n",
      "    return self.view_functions[rule.endpoint](**req.view_args)\n",
      "  File \"C:\\Users\\Lenovo\\anaconda3\\lib\\site-packages\\gradio\\networking.py\", line 92, in wrapper\n",
      "    return func(*args, **kwargs)\n",
      "  File \"C:\\Users\\Lenovo\\anaconda3\\lib\\site-packages\\gradio\\networking.py\", line 180, in predict\n",
      "    prediction, durations = app.interface.process(raw_input)\n",
      "  File \"C:\\Users\\Lenovo\\anaconda3\\lib\\site-packages\\gradio\\interface.py\", line 334, in process\n",
      "    predictions, durations = self.run_prediction(processed_input, return_duration=True)\n",
      "  File \"C:\\Users\\Lenovo\\anaconda3\\lib\\site-packages\\gradio\\interface.py\", line 307, in run_prediction\n",
      "    prediction = predict_fn(*processed_input)\n",
      "  File \"<ipython-input-3-f9d94fe16654>\", line 3, in inference\n",
      "    df = pd.DataFrame([[age, s, ch, cardio]],\n",
      "NameError: name 'pd' is not defined\n",
      "[2021-09-12 11:30:33,282] ERROR in app: Exception on /api/predict/ [POST]\n",
      "Traceback (most recent call last):\n",
      "  File \"C:\\Users\\Lenovo\\anaconda3\\lib\\site-packages\\flask\\app.py\", line 2447, in wsgi_app\n",
      "    response = self.full_dispatch_request()\n",
      "  File \"C:\\Users\\Lenovo\\anaconda3\\lib\\site-packages\\flask\\app.py\", line 1952, in full_dispatch_request\n",
      "    rv = self.handle_user_exception(e)\n",
      "  File \"C:\\Users\\Lenovo\\anaconda3\\lib\\site-packages\\flask_cors\\extension.py\", line 165, in wrapped_function\n",
      "    return cors_after_request(app.make_response(f(*args, **kwargs)))\n",
      "  File \"C:\\Users\\Lenovo\\anaconda3\\lib\\site-packages\\flask\\app.py\", line 1821, in handle_user_exception\n",
      "    reraise(exc_type, exc_value, tb)\n",
      "  File \"C:\\Users\\Lenovo\\anaconda3\\lib\\site-packages\\flask\\_compat.py\", line 39, in reraise\n",
      "    raise value\n",
      "  File \"C:\\Users\\Lenovo\\anaconda3\\lib\\site-packages\\flask\\app.py\", line 1950, in full_dispatch_request\n",
      "    rv = self.dispatch_request()\n",
      "  File \"C:\\Users\\Lenovo\\anaconda3\\lib\\site-packages\\flask\\app.py\", line 1936, in dispatch_request\n",
      "    return self.view_functions[rule.endpoint](**req.view_args)\n",
      "  File \"C:\\Users\\Lenovo\\anaconda3\\lib\\site-packages\\gradio\\networking.py\", line 92, in wrapper\n",
      "    return func(*args, **kwargs)\n",
      "  File \"C:\\Users\\Lenovo\\anaconda3\\lib\\site-packages\\gradio\\networking.py\", line 180, in predict\n",
      "    prediction, durations = app.interface.process(raw_input)\n",
      "  File \"C:\\Users\\Lenovo\\anaconda3\\lib\\site-packages\\gradio\\interface.py\", line 334, in process\n",
      "    predictions, durations = self.run_prediction(processed_input, return_duration=True)\n",
      "  File \"C:\\Users\\Lenovo\\anaconda3\\lib\\site-packages\\gradio\\interface.py\", line 307, in run_prediction\n",
      "    prediction = predict_fn(*processed_input)\n",
      "  File \"<ipython-input-3-f9d94fe16654>\", line 3, in inference\n",
      "    df = pd.DataFrame([[age, s, ch, cardio]],\n",
      "NameError: name 'pd' is not defined\n",
      "[2021-09-12 11:30:33,289] ERROR in app: Exception on /api/predict/ [POST]\n",
      "Traceback (most recent call last):\n",
      "  File \"C:\\Users\\Lenovo\\anaconda3\\lib\\site-packages\\flask\\app.py\", line 2447, in wsgi_app\n",
      "    response = self.full_dispatch_request()\n",
      "  File \"C:\\Users\\Lenovo\\anaconda3\\lib\\site-packages\\flask\\app.py\", line 1952, in full_dispatch_request\n",
      "    rv = self.handle_user_exception(e)\n",
      "  File \"C:\\Users\\Lenovo\\anaconda3\\lib\\site-packages\\flask_cors\\extension.py\", line 165, in wrapped_function\n",
      "    return cors_after_request(app.make_response(f(*args, **kwargs)))\n",
      "  File \"C:\\Users\\Lenovo\\anaconda3\\lib\\site-packages\\flask\\app.py\", line 1821, in handle_user_exception\n",
      "    reraise(exc_type, exc_value, tb)\n",
      "  File \"C:\\Users\\Lenovo\\anaconda3\\lib\\site-packages\\flask\\_compat.py\", line 39, in reraise\n",
      "    raise value\n",
      "  File \"C:\\Users\\Lenovo\\anaconda3\\lib\\site-packages\\flask\\app.py\", line 1950, in full_dispatch_request\n",
      "    rv = self.dispatch_request()\n",
      "  File \"C:\\Users\\Lenovo\\anaconda3\\lib\\site-packages\\flask\\app.py\", line 1936, in dispatch_request\n",
      "    return self.view_functions[rule.endpoint](**req.view_args)\n",
      "  File \"C:\\Users\\Lenovo\\anaconda3\\lib\\site-packages\\gradio\\networking.py\", line 92, in wrapper\n",
      "    return func(*args, **kwargs)\n",
      "  File \"C:\\Users\\Lenovo\\anaconda3\\lib\\site-packages\\gradio\\networking.py\", line 180, in predict\n",
      "    prediction, durations = app.interface.process(raw_input)\n",
      "  File \"C:\\Users\\Lenovo\\anaconda3\\lib\\site-packages\\gradio\\interface.py\", line 334, in process\n",
      "    predictions, durations = self.run_prediction(processed_input, return_duration=True)\n",
      "  File \"C:\\Users\\Lenovo\\anaconda3\\lib\\site-packages\\gradio\\interface.py\", line 307, in run_prediction\n",
      "    prediction = predict_fn(*processed_input)\n",
      "  File \"<ipython-input-3-f9d94fe16654>\", line 3, in inference\n",
      "    df = pd.DataFrame([[age, s, ch, cardio]],\n",
      "NameError: name 'pd' is not defined\n"
     ]
    },
    {
     "name": "stderr",
     "output_type": "stream",
     "text": [
      "[2021-09-12 11:30:33,295] ERROR in app: Exception on /api/predict/ [POST]\n",
      "Traceback (most recent call last):\n",
      "  File \"C:\\Users\\Lenovo\\anaconda3\\lib\\site-packages\\flask\\app.py\", line 2447, in wsgi_app\n",
      "    response = self.full_dispatch_request()\n",
      "  File \"C:\\Users\\Lenovo\\anaconda3\\lib\\site-packages\\flask\\app.py\", line 1952, in full_dispatch_request\n",
      "    rv = self.handle_user_exception(e)\n",
      "  File \"C:\\Users\\Lenovo\\anaconda3\\lib\\site-packages\\flask_cors\\extension.py\", line 165, in wrapped_function\n",
      "    return cors_after_request(app.make_response(f(*args, **kwargs)))\n",
      "  File \"C:\\Users\\Lenovo\\anaconda3\\lib\\site-packages\\flask\\app.py\", line 1821, in handle_user_exception\n",
      "    reraise(exc_type, exc_value, tb)\n",
      "  File \"C:\\Users\\Lenovo\\anaconda3\\lib\\site-packages\\flask\\_compat.py\", line 39, in reraise\n",
      "    raise value\n",
      "  File \"C:\\Users\\Lenovo\\anaconda3\\lib\\site-packages\\flask\\app.py\", line 1950, in full_dispatch_request\n",
      "    rv = self.dispatch_request()\n",
      "  File \"C:\\Users\\Lenovo\\anaconda3\\lib\\site-packages\\flask\\app.py\", line 1936, in dispatch_request\n",
      "    return self.view_functions[rule.endpoint](**req.view_args)\n",
      "  File \"C:\\Users\\Lenovo\\anaconda3\\lib\\site-packages\\gradio\\networking.py\", line 92, in wrapper\n",
      "    return func(*args, **kwargs)\n",
      "  File \"C:\\Users\\Lenovo\\anaconda3\\lib\\site-packages\\gradio\\networking.py\", line 180, in predict\n",
      "    prediction, durations = app.interface.process(raw_input)\n",
      "  File \"C:\\Users\\Lenovo\\anaconda3\\lib\\site-packages\\gradio\\interface.py\", line 334, in process\n",
      "    predictions, durations = self.run_prediction(processed_input, return_duration=True)\n",
      "  File \"C:\\Users\\Lenovo\\anaconda3\\lib\\site-packages\\gradio\\interface.py\", line 307, in run_prediction\n",
      "    prediction = predict_fn(*processed_input)\n",
      "  File \"<ipython-input-3-f9d94fe16654>\", line 3, in inference\n",
      "    df = pd.DataFrame([[age, s, ch, cardio]],\n",
      "NameError: name 'pd' is not defined\n",
      "[2021-09-12 11:30:33,303] ERROR in app: Exception on /api/predict/ [POST]\n",
      "Traceback (most recent call last):\n",
      "  File \"C:\\Users\\Lenovo\\anaconda3\\lib\\site-packages\\flask\\app.py\", line 2447, in wsgi_app\n",
      "    response = self.full_dispatch_request()\n",
      "  File \"C:\\Users\\Lenovo\\anaconda3\\lib\\site-packages\\flask\\app.py\", line 1952, in full_dispatch_request\n",
      "    rv = self.handle_user_exception(e)\n",
      "  File \"C:\\Users\\Lenovo\\anaconda3\\lib\\site-packages\\flask_cors\\extension.py\", line 165, in wrapped_function\n",
      "    return cors_after_request(app.make_response(f(*args, **kwargs)))\n",
      "  File \"C:\\Users\\Lenovo\\anaconda3\\lib\\site-packages\\flask\\app.py\", line 1821, in handle_user_exception\n",
      "    reraise(exc_type, exc_value, tb)\n",
      "  File \"C:\\Users\\Lenovo\\anaconda3\\lib\\site-packages\\flask\\_compat.py\", line 39, in reraise\n",
      "    raise value\n",
      "  File \"C:\\Users\\Lenovo\\anaconda3\\lib\\site-packages\\flask\\app.py\", line 1950, in full_dispatch_request\n",
      "    rv = self.dispatch_request()\n",
      "  File \"C:\\Users\\Lenovo\\anaconda3\\lib\\site-packages\\flask\\app.py\", line 1936, in dispatch_request\n",
      "    return self.view_functions[rule.endpoint](**req.view_args)\n",
      "  File \"C:\\Users\\Lenovo\\anaconda3\\lib\\site-packages\\gradio\\networking.py\", line 92, in wrapper\n",
      "    return func(*args, **kwargs)\n",
      "  File \"C:\\Users\\Lenovo\\anaconda3\\lib\\site-packages\\gradio\\networking.py\", line 180, in predict\n",
      "    prediction, durations = app.interface.process(raw_input)\n",
      "  File \"C:\\Users\\Lenovo\\anaconda3\\lib\\site-packages\\gradio\\interface.py\", line 334, in process\n",
      "    predictions, durations = self.run_prediction(processed_input, return_duration=True)\n",
      "  File \"C:\\Users\\Lenovo\\anaconda3\\lib\\site-packages\\gradio\\interface.py\", line 307, in run_prediction\n",
      "    prediction = predict_fn(*processed_input)\n",
      "  File \"<ipython-input-3-f9d94fe16654>\", line 3, in inference\n",
      "    df = pd.DataFrame([[age, s, ch, cardio]],\n",
      "NameError: name 'pd' is not defined\n",
      "[2021-09-12 11:30:33,310] ERROR in app: Exception on /api/predict/ [POST]\n",
      "Traceback (most recent call last):\n",
      "  File \"C:\\Users\\Lenovo\\anaconda3\\lib\\site-packages\\flask\\app.py\", line 2447, in wsgi_app\n",
      "    response = self.full_dispatch_request()\n",
      "  File \"C:\\Users\\Lenovo\\anaconda3\\lib\\site-packages\\flask\\app.py\", line 1952, in full_dispatch_request\n",
      "    rv = self.handle_user_exception(e)\n",
      "  File \"C:\\Users\\Lenovo\\anaconda3\\lib\\site-packages\\flask_cors\\extension.py\", line 165, in wrapped_function\n",
      "    return cors_after_request(app.make_response(f(*args, **kwargs)))\n",
      "  File \"C:\\Users\\Lenovo\\anaconda3\\lib\\site-packages\\flask\\app.py\", line 1821, in handle_user_exception\n",
      "    reraise(exc_type, exc_value, tb)\n",
      "  File \"C:\\Users\\Lenovo\\anaconda3\\lib\\site-packages\\flask\\_compat.py\", line 39, in reraise\n",
      "    raise value\n",
      "  File \"C:\\Users\\Lenovo\\anaconda3\\lib\\site-packages\\flask\\app.py\", line 1950, in full_dispatch_request\n",
      "    rv = self.dispatch_request()\n",
      "  File \"C:\\Users\\Lenovo\\anaconda3\\lib\\site-packages\\flask\\app.py\", line 1936, in dispatch_request\n",
      "    return self.view_functions[rule.endpoint](**req.view_args)\n",
      "  File \"C:\\Users\\Lenovo\\anaconda3\\lib\\site-packages\\gradio\\networking.py\", line 92, in wrapper\n",
      "    return func(*args, **kwargs)\n",
      "  File \"C:\\Users\\Lenovo\\anaconda3\\lib\\site-packages\\gradio\\networking.py\", line 180, in predict\n",
      "    prediction, durations = app.interface.process(raw_input)\n",
      "  File \"C:\\Users\\Lenovo\\anaconda3\\lib\\site-packages\\gradio\\interface.py\", line 334, in process\n",
      "    predictions, durations = self.run_prediction(processed_input, return_duration=True)\n",
      "  File \"C:\\Users\\Lenovo\\anaconda3\\lib\\site-packages\\gradio\\interface.py\", line 307, in run_prediction\n",
      "    prediction = predict_fn(*processed_input)\n",
      "  File \"<ipython-input-3-f9d94fe16654>\", line 3, in inference\n",
      "    df = pd.DataFrame([[age, s, ch, cardio]],\n",
      "NameError: name 'pd' is not defined\n",
      "[2021-09-12 11:30:33,324] ERROR in app: Exception on /api/predict/ [POST]\n",
      "Traceback (most recent call last):\n",
      "  File \"C:\\Users\\Lenovo\\anaconda3\\lib\\site-packages\\flask\\app.py\", line 2447, in wsgi_app\n",
      "    response = self.full_dispatch_request()\n",
      "  File \"C:\\Users\\Lenovo\\anaconda3\\lib\\site-packages\\flask\\app.py\", line 1952, in full_dispatch_request\n",
      "    rv = self.handle_user_exception(e)\n",
      "  File \"C:\\Users\\Lenovo\\anaconda3\\lib\\site-packages\\flask_cors\\extension.py\", line 165, in wrapped_function\n",
      "    return cors_after_request(app.make_response(f(*args, **kwargs)))\n",
      "  File \"C:\\Users\\Lenovo\\anaconda3\\lib\\site-packages\\flask\\app.py\", line 1821, in handle_user_exception\n",
      "    reraise(exc_type, exc_value, tb)\n",
      "  File \"C:\\Users\\Lenovo\\anaconda3\\lib\\site-packages\\flask\\_compat.py\", line 39, in reraise\n",
      "    raise value\n",
      "  File \"C:\\Users\\Lenovo\\anaconda3\\lib\\site-packages\\flask\\app.py\", line 1950, in full_dispatch_request\n",
      "    rv = self.dispatch_request()\n",
      "  File \"C:\\Users\\Lenovo\\anaconda3\\lib\\site-packages\\flask\\app.py\", line 1936, in dispatch_request\n",
      "    return self.view_functions[rule.endpoint](**req.view_args)\n",
      "  File \"C:\\Users\\Lenovo\\anaconda3\\lib\\site-packages\\gradio\\networking.py\", line 92, in wrapper\n",
      "    return func(*args, **kwargs)\n",
      "  File \"C:\\Users\\Lenovo\\anaconda3\\lib\\site-packages\\gradio\\networking.py\", line 180, in predict\n",
      "    prediction, durations = app.interface.process(raw_input)\n",
      "  File \"C:\\Users\\Lenovo\\anaconda3\\lib\\site-packages\\gradio\\interface.py\", line 334, in process\n",
      "    predictions, durations = self.run_prediction(processed_input, return_duration=True)\n",
      "  File \"C:\\Users\\Lenovo\\anaconda3\\lib\\site-packages\\gradio\\interface.py\", line 307, in run_prediction\n",
      "    prediction = predict_fn(*processed_input)\n",
      "  File \"<ipython-input-3-f9d94fe16654>\", line 3, in inference\n",
      "    df = pd.DataFrame([[age, s, ch, cardio]],\n",
      "NameError: name 'pd' is not defined\n",
      "[2021-09-12 11:30:33,331] ERROR in app: Exception on /api/predict/ [POST]\n",
      "Traceback (most recent call last):\n",
      "  File \"C:\\Users\\Lenovo\\anaconda3\\lib\\site-packages\\flask\\app.py\", line 2447, in wsgi_app\n",
      "    response = self.full_dispatch_request()\n",
      "  File \"C:\\Users\\Lenovo\\anaconda3\\lib\\site-packages\\flask\\app.py\", line 1952, in full_dispatch_request\n",
      "    rv = self.handle_user_exception(e)\n",
      "  File \"C:\\Users\\Lenovo\\anaconda3\\lib\\site-packages\\flask_cors\\extension.py\", line 165, in wrapped_function\n",
      "    return cors_after_request(app.make_response(f(*args, **kwargs)))\n",
      "  File \"C:\\Users\\Lenovo\\anaconda3\\lib\\site-packages\\flask\\app.py\", line 1821, in handle_user_exception\n",
      "    reraise(exc_type, exc_value, tb)\n",
      "  File \"C:\\Users\\Lenovo\\anaconda3\\lib\\site-packages\\flask\\_compat.py\", line 39, in reraise\n",
      "    raise value\n",
      "  File \"C:\\Users\\Lenovo\\anaconda3\\lib\\site-packages\\flask\\app.py\", line 1950, in full_dispatch_request\n",
      "    rv = self.dispatch_request()\n",
      "  File \"C:\\Users\\Lenovo\\anaconda3\\lib\\site-packages\\flask\\app.py\", line 1936, in dispatch_request\n",
      "    return self.view_functions[rule.endpoint](**req.view_args)\n",
      "  File \"C:\\Users\\Lenovo\\anaconda3\\lib\\site-packages\\gradio\\networking.py\", line 92, in wrapper\n",
      "    return func(*args, **kwargs)\n",
      "  File \"C:\\Users\\Lenovo\\anaconda3\\lib\\site-packages\\gradio\\networking.py\", line 180, in predict\n",
      "    prediction, durations = app.interface.process(raw_input)\n",
      "  File \"C:\\Users\\Lenovo\\anaconda3\\lib\\site-packages\\gradio\\interface.py\", line 334, in process\n",
      "    predictions, durations = self.run_prediction(processed_input, return_duration=True)\n",
      "  File \"C:\\Users\\Lenovo\\anaconda3\\lib\\site-packages\\gradio\\interface.py\", line 307, in run_prediction\n",
      "    prediction = predict_fn(*processed_input)\n",
      "  File \"<ipython-input-3-f9d94fe16654>\", line 3, in inference\n",
      "    df = pd.DataFrame([[age, s, ch, cardio]],\n",
      "NameError: name 'pd' is not defined\n"
     ]
    },
    {
     "name": "stderr",
     "output_type": "stream",
     "text": [
      "[2021-09-12 11:30:33,338] ERROR in app: Exception on /api/predict/ [POST]\n",
      "Traceback (most recent call last):\n",
      "  File \"C:\\Users\\Lenovo\\anaconda3\\lib\\site-packages\\flask\\app.py\", line 2447, in wsgi_app\n",
      "    response = self.full_dispatch_request()\n",
      "  File \"C:\\Users\\Lenovo\\anaconda3\\lib\\site-packages\\flask\\app.py\", line 1952, in full_dispatch_request\n",
      "    rv = self.handle_user_exception(e)\n",
      "  File \"C:\\Users\\Lenovo\\anaconda3\\lib\\site-packages\\flask_cors\\extension.py\", line 165, in wrapped_function\n",
      "    return cors_after_request(app.make_response(f(*args, **kwargs)))\n",
      "  File \"C:\\Users\\Lenovo\\anaconda3\\lib\\site-packages\\flask\\app.py\", line 1821, in handle_user_exception\n",
      "    reraise(exc_type, exc_value, tb)\n",
      "  File \"C:\\Users\\Lenovo\\anaconda3\\lib\\site-packages\\flask\\_compat.py\", line 39, in reraise\n",
      "    raise value\n",
      "  File \"C:\\Users\\Lenovo\\anaconda3\\lib\\site-packages\\flask\\app.py\", line 1950, in full_dispatch_request\n",
      "    rv = self.dispatch_request()\n",
      "  File \"C:\\Users\\Lenovo\\anaconda3\\lib\\site-packages\\flask\\app.py\", line 1936, in dispatch_request\n",
      "    return self.view_functions[rule.endpoint](**req.view_args)\n",
      "  File \"C:\\Users\\Lenovo\\anaconda3\\lib\\site-packages\\gradio\\networking.py\", line 92, in wrapper\n",
      "    return func(*args, **kwargs)\n",
      "  File \"C:\\Users\\Lenovo\\anaconda3\\lib\\site-packages\\gradio\\networking.py\", line 180, in predict\n",
      "    prediction, durations = app.interface.process(raw_input)\n",
      "  File \"C:\\Users\\Lenovo\\anaconda3\\lib\\site-packages\\gradio\\interface.py\", line 334, in process\n",
      "    predictions, durations = self.run_prediction(processed_input, return_duration=True)\n",
      "  File \"C:\\Users\\Lenovo\\anaconda3\\lib\\site-packages\\gradio\\interface.py\", line 307, in run_prediction\n",
      "    prediction = predict_fn(*processed_input)\n",
      "  File \"<ipython-input-3-f9d94fe16654>\", line 3, in inference\n",
      "    df = pd.DataFrame([[age, s, ch, cardio]],\n",
      "NameError: name 'pd' is not defined\n",
      "[2021-09-12 11:30:33,344] ERROR in app: Exception on /api/predict/ [POST]\n",
      "Traceback (most recent call last):\n",
      "  File \"C:\\Users\\Lenovo\\anaconda3\\lib\\site-packages\\flask\\app.py\", line 2447, in wsgi_app\n",
      "    response = self.full_dispatch_request()\n",
      "  File \"C:\\Users\\Lenovo\\anaconda3\\lib\\site-packages\\flask\\app.py\", line 1952, in full_dispatch_request\n",
      "    rv = self.handle_user_exception(e)\n",
      "  File \"C:\\Users\\Lenovo\\anaconda3\\lib\\site-packages\\flask_cors\\extension.py\", line 165, in wrapped_function\n",
      "    return cors_after_request(app.make_response(f(*args, **kwargs)))\n",
      "  File \"C:\\Users\\Lenovo\\anaconda3\\lib\\site-packages\\flask\\app.py\", line 1821, in handle_user_exception\n",
      "    reraise(exc_type, exc_value, tb)\n",
      "  File \"C:\\Users\\Lenovo\\anaconda3\\lib\\site-packages\\flask\\_compat.py\", line 39, in reraise\n",
      "    raise value\n",
      "  File \"C:\\Users\\Lenovo\\anaconda3\\lib\\site-packages\\flask\\app.py\", line 1950, in full_dispatch_request\n",
      "    rv = self.dispatch_request()\n",
      "  File \"C:\\Users\\Lenovo\\anaconda3\\lib\\site-packages\\flask\\app.py\", line 1936, in dispatch_request\n",
      "    return self.view_functions[rule.endpoint](**req.view_args)\n",
      "  File \"C:\\Users\\Lenovo\\anaconda3\\lib\\site-packages\\gradio\\networking.py\", line 92, in wrapper\n",
      "    return func(*args, **kwargs)\n",
      "  File \"C:\\Users\\Lenovo\\anaconda3\\lib\\site-packages\\gradio\\networking.py\", line 180, in predict\n",
      "    prediction, durations = app.interface.process(raw_input)\n",
      "  File \"C:\\Users\\Lenovo\\anaconda3\\lib\\site-packages\\gradio\\interface.py\", line 334, in process\n",
      "    predictions, durations = self.run_prediction(processed_input, return_duration=True)\n",
      "  File \"C:\\Users\\Lenovo\\anaconda3\\lib\\site-packages\\gradio\\interface.py\", line 307, in run_prediction\n",
      "    prediction = predict_fn(*processed_input)\n",
      "  File \"<ipython-input-3-f9d94fe16654>\", line 3, in inference\n",
      "    df = pd.DataFrame([[age, s, ch, cardio]],\n",
      "NameError: name 'pd' is not defined\n",
      "[2021-09-12 11:30:33,351] ERROR in app: Exception on /api/predict/ [POST]\n",
      "Traceback (most recent call last):\n",
      "  File \"C:\\Users\\Lenovo\\anaconda3\\lib\\site-packages\\flask\\app.py\", line 2447, in wsgi_app\n",
      "    response = self.full_dispatch_request()\n",
      "  File \"C:\\Users\\Lenovo\\anaconda3\\lib\\site-packages\\flask\\app.py\", line 1952, in full_dispatch_request\n",
      "    rv = self.handle_user_exception(e)\n",
      "  File \"C:\\Users\\Lenovo\\anaconda3\\lib\\site-packages\\flask_cors\\extension.py\", line 165, in wrapped_function\n",
      "    return cors_after_request(app.make_response(f(*args, **kwargs)))\n",
      "  File \"C:\\Users\\Lenovo\\anaconda3\\lib\\site-packages\\flask\\app.py\", line 1821, in handle_user_exception\n",
      "    reraise(exc_type, exc_value, tb)\n",
      "  File \"C:\\Users\\Lenovo\\anaconda3\\lib\\site-packages\\flask\\_compat.py\", line 39, in reraise\n",
      "    raise value\n",
      "  File \"C:\\Users\\Lenovo\\anaconda3\\lib\\site-packages\\flask\\app.py\", line 1950, in full_dispatch_request\n",
      "    rv = self.dispatch_request()\n",
      "  File \"C:\\Users\\Lenovo\\anaconda3\\lib\\site-packages\\flask\\app.py\", line 1936, in dispatch_request\n",
      "    return self.view_functions[rule.endpoint](**req.view_args)\n",
      "  File \"C:\\Users\\Lenovo\\anaconda3\\lib\\site-packages\\gradio\\networking.py\", line 92, in wrapper\n",
      "    return func(*args, **kwargs)\n",
      "  File \"C:\\Users\\Lenovo\\anaconda3\\lib\\site-packages\\gradio\\networking.py\", line 180, in predict\n",
      "    prediction, durations = app.interface.process(raw_input)\n",
      "  File \"C:\\Users\\Lenovo\\anaconda3\\lib\\site-packages\\gradio\\interface.py\", line 334, in process\n",
      "    predictions, durations = self.run_prediction(processed_input, return_duration=True)\n",
      "  File \"C:\\Users\\Lenovo\\anaconda3\\lib\\site-packages\\gradio\\interface.py\", line 307, in run_prediction\n",
      "    prediction = predict_fn(*processed_input)\n",
      "  File \"<ipython-input-3-f9d94fe16654>\", line 3, in inference\n",
      "    df = pd.DataFrame([[age, s, ch, cardio]],\n",
      "NameError: name 'pd' is not defined\n",
      "[2021-09-12 11:30:33,358] ERROR in app: Exception on /api/predict/ [POST]\n",
      "Traceback (most recent call last):\n",
      "  File \"C:\\Users\\Lenovo\\anaconda3\\lib\\site-packages\\flask\\app.py\", line 2447, in wsgi_app\n",
      "    response = self.full_dispatch_request()\n",
      "  File \"C:\\Users\\Lenovo\\anaconda3\\lib\\site-packages\\flask\\app.py\", line 1952, in full_dispatch_request\n",
      "    rv = self.handle_user_exception(e)\n",
      "  File \"C:\\Users\\Lenovo\\anaconda3\\lib\\site-packages\\flask_cors\\extension.py\", line 165, in wrapped_function\n",
      "    return cors_after_request(app.make_response(f(*args, **kwargs)))\n",
      "  File \"C:\\Users\\Lenovo\\anaconda3\\lib\\site-packages\\flask\\app.py\", line 1821, in handle_user_exception\n",
      "    reraise(exc_type, exc_value, tb)\n",
      "  File \"C:\\Users\\Lenovo\\anaconda3\\lib\\site-packages\\flask\\_compat.py\", line 39, in reraise\n",
      "    raise value\n",
      "  File \"C:\\Users\\Lenovo\\anaconda3\\lib\\site-packages\\flask\\app.py\", line 1950, in full_dispatch_request\n",
      "    rv = self.dispatch_request()\n",
      "  File \"C:\\Users\\Lenovo\\anaconda3\\lib\\site-packages\\flask\\app.py\", line 1936, in dispatch_request\n",
      "    return self.view_functions[rule.endpoint](**req.view_args)\n",
      "  File \"C:\\Users\\Lenovo\\anaconda3\\lib\\site-packages\\gradio\\networking.py\", line 92, in wrapper\n",
      "    return func(*args, **kwargs)\n",
      "  File \"C:\\Users\\Lenovo\\anaconda3\\lib\\site-packages\\gradio\\networking.py\", line 180, in predict\n",
      "    prediction, durations = app.interface.process(raw_input)\n",
      "  File \"C:\\Users\\Lenovo\\anaconda3\\lib\\site-packages\\gradio\\interface.py\", line 334, in process\n",
      "    predictions, durations = self.run_prediction(processed_input, return_duration=True)\n",
      "  File \"C:\\Users\\Lenovo\\anaconda3\\lib\\site-packages\\gradio\\interface.py\", line 307, in run_prediction\n",
      "    prediction = predict_fn(*processed_input)\n",
      "  File \"<ipython-input-3-f9d94fe16654>\", line 3, in inference\n",
      "    df = pd.DataFrame([[age, s, ch, cardio]],\n",
      "NameError: name 'pd' is not defined\n",
      "[2021-09-12 11:30:33,364] ERROR in app: Exception on /api/predict/ [POST]\n",
      "Traceback (most recent call last):\n",
      "  File \"C:\\Users\\Lenovo\\anaconda3\\lib\\site-packages\\flask\\app.py\", line 2447, in wsgi_app\n",
      "    response = self.full_dispatch_request()\n",
      "  File \"C:\\Users\\Lenovo\\anaconda3\\lib\\site-packages\\flask\\app.py\", line 1952, in full_dispatch_request\n",
      "    rv = self.handle_user_exception(e)\n",
      "  File \"C:\\Users\\Lenovo\\anaconda3\\lib\\site-packages\\flask_cors\\extension.py\", line 165, in wrapped_function\n",
      "    return cors_after_request(app.make_response(f(*args, **kwargs)))\n",
      "  File \"C:\\Users\\Lenovo\\anaconda3\\lib\\site-packages\\flask\\app.py\", line 1821, in handle_user_exception\n",
      "    reraise(exc_type, exc_value, tb)\n",
      "  File \"C:\\Users\\Lenovo\\anaconda3\\lib\\site-packages\\flask\\_compat.py\", line 39, in reraise\n",
      "    raise value\n",
      "  File \"C:\\Users\\Lenovo\\anaconda3\\lib\\site-packages\\flask\\app.py\", line 1950, in full_dispatch_request\n",
      "    rv = self.dispatch_request()\n",
      "  File \"C:\\Users\\Lenovo\\anaconda3\\lib\\site-packages\\flask\\app.py\", line 1936, in dispatch_request\n",
      "    return self.view_functions[rule.endpoint](**req.view_args)\n",
      "  File \"C:\\Users\\Lenovo\\anaconda3\\lib\\site-packages\\gradio\\networking.py\", line 92, in wrapper\n",
      "    return func(*args, **kwargs)\n",
      "  File \"C:\\Users\\Lenovo\\anaconda3\\lib\\site-packages\\gradio\\networking.py\", line 180, in predict\n",
      "    prediction, durations = app.interface.process(raw_input)\n",
      "  File \"C:\\Users\\Lenovo\\anaconda3\\lib\\site-packages\\gradio\\interface.py\", line 334, in process\n",
      "    predictions, durations = self.run_prediction(processed_input, return_duration=True)\n",
      "  File \"C:\\Users\\Lenovo\\anaconda3\\lib\\site-packages\\gradio\\interface.py\", line 307, in run_prediction\n",
      "    prediction = predict_fn(*processed_input)\n",
      "  File \"<ipython-input-3-f9d94fe16654>\", line 3, in inference\n",
      "    df = pd.DataFrame([[age, s, ch, cardio]],\n",
      "NameError: name 'pd' is not defined\n"
     ]
    },
    {
     "name": "stderr",
     "output_type": "stream",
     "text": [
      "[2021-09-12 11:30:33,379] ERROR in app: Exception on /api/predict/ [POST]\n",
      "Traceback (most recent call last):\n",
      "  File \"C:\\Users\\Lenovo\\anaconda3\\lib\\site-packages\\flask\\app.py\", line 2447, in wsgi_app\n",
      "    response = self.full_dispatch_request()\n",
      "  File \"C:\\Users\\Lenovo\\anaconda3\\lib\\site-packages\\flask\\app.py\", line 1952, in full_dispatch_request\n",
      "    rv = self.handle_user_exception(e)\n",
      "  File \"C:\\Users\\Lenovo\\anaconda3\\lib\\site-packages\\flask_cors\\extension.py\", line 165, in wrapped_function\n",
      "    return cors_after_request(app.make_response(f(*args, **kwargs)))\n",
      "  File \"C:\\Users\\Lenovo\\anaconda3\\lib\\site-packages\\flask\\app.py\", line 1821, in handle_user_exception\n",
      "    reraise(exc_type, exc_value, tb)\n",
      "  File \"C:\\Users\\Lenovo\\anaconda3\\lib\\site-packages\\flask\\_compat.py\", line 39, in reraise\n",
      "    raise value\n",
      "  File \"C:\\Users\\Lenovo\\anaconda3\\lib\\site-packages\\flask\\app.py\", line 1950, in full_dispatch_request\n",
      "    rv = self.dispatch_request()\n",
      "  File \"C:\\Users\\Lenovo\\anaconda3\\lib\\site-packages\\flask\\app.py\", line 1936, in dispatch_request\n",
      "    return self.view_functions[rule.endpoint](**req.view_args)\n",
      "  File \"C:\\Users\\Lenovo\\anaconda3\\lib\\site-packages\\gradio\\networking.py\", line 92, in wrapper\n",
      "    return func(*args, **kwargs)\n",
      "  File \"C:\\Users\\Lenovo\\anaconda3\\lib\\site-packages\\gradio\\networking.py\", line 180, in predict\n",
      "    prediction, durations = app.interface.process(raw_input)\n",
      "  File \"C:\\Users\\Lenovo\\anaconda3\\lib\\site-packages\\gradio\\interface.py\", line 334, in process\n",
      "    predictions, durations = self.run_prediction(processed_input, return_duration=True)\n",
      "  File \"C:\\Users\\Lenovo\\anaconda3\\lib\\site-packages\\gradio\\interface.py\", line 307, in run_prediction\n",
      "    prediction = predict_fn(*processed_input)\n",
      "  File \"<ipython-input-3-f9d94fe16654>\", line 3, in inference\n",
      "    df = pd.DataFrame([[age, s, ch, cardio]],\n",
      "NameError: name 'pd' is not defined\n",
      "[2021-09-12 11:30:33,385] ERROR in app: Exception on /api/predict/ [POST]\n",
      "Traceback (most recent call last):\n",
      "  File \"C:\\Users\\Lenovo\\anaconda3\\lib\\site-packages\\flask\\app.py\", line 2447, in wsgi_app\n",
      "    response = self.full_dispatch_request()\n",
      "  File \"C:\\Users\\Lenovo\\anaconda3\\lib\\site-packages\\flask\\app.py\", line 1952, in full_dispatch_request\n",
      "    rv = self.handle_user_exception(e)\n",
      "  File \"C:\\Users\\Lenovo\\anaconda3\\lib\\site-packages\\flask_cors\\extension.py\", line 165, in wrapped_function\n",
      "    return cors_after_request(app.make_response(f(*args, **kwargs)))\n",
      "  File \"C:\\Users\\Lenovo\\anaconda3\\lib\\site-packages\\flask\\app.py\", line 1821, in handle_user_exception\n",
      "    reraise(exc_type, exc_value, tb)\n",
      "  File \"C:\\Users\\Lenovo\\anaconda3\\lib\\site-packages\\flask\\_compat.py\", line 39, in reraise\n",
      "    raise value\n",
      "  File \"C:\\Users\\Lenovo\\anaconda3\\lib\\site-packages\\flask\\app.py\", line 1950, in full_dispatch_request\n",
      "    rv = self.dispatch_request()\n",
      "  File \"C:\\Users\\Lenovo\\anaconda3\\lib\\site-packages\\flask\\app.py\", line 1936, in dispatch_request\n",
      "    return self.view_functions[rule.endpoint](**req.view_args)\n",
      "  File \"C:\\Users\\Lenovo\\anaconda3\\lib\\site-packages\\gradio\\networking.py\", line 92, in wrapper\n",
      "    return func(*args, **kwargs)\n",
      "  File \"C:\\Users\\Lenovo\\anaconda3\\lib\\site-packages\\gradio\\networking.py\", line 180, in predict\n",
      "    prediction, durations = app.interface.process(raw_input)\n",
      "  File \"C:\\Users\\Lenovo\\anaconda3\\lib\\site-packages\\gradio\\interface.py\", line 334, in process\n",
      "    predictions, durations = self.run_prediction(processed_input, return_duration=True)\n",
      "  File \"C:\\Users\\Lenovo\\anaconda3\\lib\\site-packages\\gradio\\interface.py\", line 307, in run_prediction\n",
      "    prediction = predict_fn(*processed_input)\n",
      "  File \"<ipython-input-3-f9d94fe16654>\", line 3, in inference\n",
      "    df = pd.DataFrame([[age, s, ch, cardio]],\n",
      "NameError: name 'pd' is not defined\n",
      "[2021-09-12 11:30:33,393] ERROR in app: Exception on /api/predict/ [POST]\n",
      "Traceback (most recent call last):\n",
      "  File \"C:\\Users\\Lenovo\\anaconda3\\lib\\site-packages\\flask\\app.py\", line 2447, in wsgi_app\n",
      "    response = self.full_dispatch_request()\n",
      "  File \"C:\\Users\\Lenovo\\anaconda3\\lib\\site-packages\\flask\\app.py\", line 1952, in full_dispatch_request\n",
      "    rv = self.handle_user_exception(e)\n",
      "  File \"C:\\Users\\Lenovo\\anaconda3\\lib\\site-packages\\flask_cors\\extension.py\", line 165, in wrapped_function\n",
      "    return cors_after_request(app.make_response(f(*args, **kwargs)))\n",
      "  File \"C:\\Users\\Lenovo\\anaconda3\\lib\\site-packages\\flask\\app.py\", line 1821, in handle_user_exception\n",
      "    reraise(exc_type, exc_value, tb)\n",
      "  File \"C:\\Users\\Lenovo\\anaconda3\\lib\\site-packages\\flask\\_compat.py\", line 39, in reraise\n",
      "    raise value\n",
      "  File \"C:\\Users\\Lenovo\\anaconda3\\lib\\site-packages\\flask\\app.py\", line 1950, in full_dispatch_request\n",
      "    rv = self.dispatch_request()\n",
      "  File \"C:\\Users\\Lenovo\\anaconda3\\lib\\site-packages\\flask\\app.py\", line 1936, in dispatch_request\n",
      "    return self.view_functions[rule.endpoint](**req.view_args)\n",
      "  File \"C:\\Users\\Lenovo\\anaconda3\\lib\\site-packages\\gradio\\networking.py\", line 92, in wrapper\n",
      "    return func(*args, **kwargs)\n",
      "  File \"C:\\Users\\Lenovo\\anaconda3\\lib\\site-packages\\gradio\\networking.py\", line 180, in predict\n",
      "    prediction, durations = app.interface.process(raw_input)\n",
      "  File \"C:\\Users\\Lenovo\\anaconda3\\lib\\site-packages\\gradio\\interface.py\", line 334, in process\n",
      "    predictions, durations = self.run_prediction(processed_input, return_duration=True)\n",
      "  File \"C:\\Users\\Lenovo\\anaconda3\\lib\\site-packages\\gradio\\interface.py\", line 307, in run_prediction\n",
      "    prediction = predict_fn(*processed_input)\n",
      "  File \"<ipython-input-3-f9d94fe16654>\", line 3, in inference\n",
      "    df = pd.DataFrame([[age, s, ch, cardio]],\n",
      "NameError: name 'pd' is not defined\n",
      "[2021-09-12 11:30:33,399] ERROR in app: Exception on /api/predict/ [POST]\n",
      "Traceback (most recent call last):\n",
      "  File \"C:\\Users\\Lenovo\\anaconda3\\lib\\site-packages\\flask\\app.py\", line 2447, in wsgi_app\n",
      "    response = self.full_dispatch_request()\n",
      "  File \"C:\\Users\\Lenovo\\anaconda3\\lib\\site-packages\\flask\\app.py\", line 1952, in full_dispatch_request\n",
      "    rv = self.handle_user_exception(e)\n",
      "  File \"C:\\Users\\Lenovo\\anaconda3\\lib\\site-packages\\flask_cors\\extension.py\", line 165, in wrapped_function\n",
      "    return cors_after_request(app.make_response(f(*args, **kwargs)))\n",
      "  File \"C:\\Users\\Lenovo\\anaconda3\\lib\\site-packages\\flask\\app.py\", line 1821, in handle_user_exception\n",
      "    reraise(exc_type, exc_value, tb)\n",
      "  File \"C:\\Users\\Lenovo\\anaconda3\\lib\\site-packages\\flask\\_compat.py\", line 39, in reraise\n",
      "    raise value\n",
      "  File \"C:\\Users\\Lenovo\\anaconda3\\lib\\site-packages\\flask\\app.py\", line 1950, in full_dispatch_request\n",
      "    rv = self.dispatch_request()\n",
      "  File \"C:\\Users\\Lenovo\\anaconda3\\lib\\site-packages\\flask\\app.py\", line 1936, in dispatch_request\n",
      "    return self.view_functions[rule.endpoint](**req.view_args)\n",
      "  File \"C:\\Users\\Lenovo\\anaconda3\\lib\\site-packages\\gradio\\networking.py\", line 92, in wrapper\n",
      "    return func(*args, **kwargs)\n",
      "  File \"C:\\Users\\Lenovo\\anaconda3\\lib\\site-packages\\gradio\\networking.py\", line 180, in predict\n",
      "    prediction, durations = app.interface.process(raw_input)\n",
      "  File \"C:\\Users\\Lenovo\\anaconda3\\lib\\site-packages\\gradio\\interface.py\", line 334, in process\n",
      "    predictions, durations = self.run_prediction(processed_input, return_duration=True)\n",
      "  File \"C:\\Users\\Lenovo\\anaconda3\\lib\\site-packages\\gradio\\interface.py\", line 307, in run_prediction\n",
      "    prediction = predict_fn(*processed_input)\n",
      "  File \"<ipython-input-3-f9d94fe16654>\", line 3, in inference\n",
      "    df = pd.DataFrame([[age, s, ch, cardio]],\n",
      "NameError: name 'pd' is not defined\n",
      "[2021-09-12 11:30:33,406] ERROR in app: Exception on /api/predict/ [POST]\n",
      "Traceback (most recent call last):\n",
      "  File \"C:\\Users\\Lenovo\\anaconda3\\lib\\site-packages\\flask\\app.py\", line 2447, in wsgi_app\n",
      "    response = self.full_dispatch_request()\n",
      "  File \"C:\\Users\\Lenovo\\anaconda3\\lib\\site-packages\\flask\\app.py\", line 1952, in full_dispatch_request\n",
      "    rv = self.handle_user_exception(e)\n",
      "  File \"C:\\Users\\Lenovo\\anaconda3\\lib\\site-packages\\flask_cors\\extension.py\", line 165, in wrapped_function\n",
      "    return cors_after_request(app.make_response(f(*args, **kwargs)))\n",
      "  File \"C:\\Users\\Lenovo\\anaconda3\\lib\\site-packages\\flask\\app.py\", line 1821, in handle_user_exception\n",
      "    reraise(exc_type, exc_value, tb)\n",
      "  File \"C:\\Users\\Lenovo\\anaconda3\\lib\\site-packages\\flask\\_compat.py\", line 39, in reraise\n",
      "    raise value\n",
      "  File \"C:\\Users\\Lenovo\\anaconda3\\lib\\site-packages\\flask\\app.py\", line 1950, in full_dispatch_request\n",
      "    rv = self.dispatch_request()\n",
      "  File \"C:\\Users\\Lenovo\\anaconda3\\lib\\site-packages\\flask\\app.py\", line 1936, in dispatch_request\n",
      "    return self.view_functions[rule.endpoint](**req.view_args)\n",
      "  File \"C:\\Users\\Lenovo\\anaconda3\\lib\\site-packages\\gradio\\networking.py\", line 92, in wrapper\n",
      "    return func(*args, **kwargs)\n",
      "  File \"C:\\Users\\Lenovo\\anaconda3\\lib\\site-packages\\gradio\\networking.py\", line 180, in predict\n",
      "    prediction, durations = app.interface.process(raw_input)\n",
      "  File \"C:\\Users\\Lenovo\\anaconda3\\lib\\site-packages\\gradio\\interface.py\", line 334, in process\n",
      "    predictions, durations = self.run_prediction(processed_input, return_duration=True)\n",
      "  File \"C:\\Users\\Lenovo\\anaconda3\\lib\\site-packages\\gradio\\interface.py\", line 307, in run_prediction\n",
      "    prediction = predict_fn(*processed_input)\n",
      "  File \"<ipython-input-3-f9d94fe16654>\", line 3, in inference\n",
      "    df = pd.DataFrame([[age, s, ch, cardio]],\n",
      "NameError: name 'pd' is not defined\n"
     ]
    },
    {
     "name": "stderr",
     "output_type": "stream",
     "text": [
      "[2021-09-12 11:30:33,413] ERROR in app: Exception on /api/predict/ [POST]\n",
      "Traceback (most recent call last):\n",
      "  File \"C:\\Users\\Lenovo\\anaconda3\\lib\\site-packages\\flask\\app.py\", line 2447, in wsgi_app\n",
      "    response = self.full_dispatch_request()\n",
      "  File \"C:\\Users\\Lenovo\\anaconda3\\lib\\site-packages\\flask\\app.py\", line 1952, in full_dispatch_request\n",
      "    rv = self.handle_user_exception(e)\n",
      "  File \"C:\\Users\\Lenovo\\anaconda3\\lib\\site-packages\\flask_cors\\extension.py\", line 165, in wrapped_function\n",
      "    return cors_after_request(app.make_response(f(*args, **kwargs)))\n",
      "  File \"C:\\Users\\Lenovo\\anaconda3\\lib\\site-packages\\flask\\app.py\", line 1821, in handle_user_exception\n",
      "    reraise(exc_type, exc_value, tb)\n",
      "  File \"C:\\Users\\Lenovo\\anaconda3\\lib\\site-packages\\flask\\_compat.py\", line 39, in reraise\n",
      "    raise value\n",
      "  File \"C:\\Users\\Lenovo\\anaconda3\\lib\\site-packages\\flask\\app.py\", line 1950, in full_dispatch_request\n",
      "    rv = self.dispatch_request()\n",
      "  File \"C:\\Users\\Lenovo\\anaconda3\\lib\\site-packages\\flask\\app.py\", line 1936, in dispatch_request\n",
      "    return self.view_functions[rule.endpoint](**req.view_args)\n",
      "  File \"C:\\Users\\Lenovo\\anaconda3\\lib\\site-packages\\gradio\\networking.py\", line 92, in wrapper\n",
      "    return func(*args, **kwargs)\n",
      "  File \"C:\\Users\\Lenovo\\anaconda3\\lib\\site-packages\\gradio\\networking.py\", line 180, in predict\n",
      "    prediction, durations = app.interface.process(raw_input)\n",
      "  File \"C:\\Users\\Lenovo\\anaconda3\\lib\\site-packages\\gradio\\interface.py\", line 334, in process\n",
      "    predictions, durations = self.run_prediction(processed_input, return_duration=True)\n",
      "  File \"C:\\Users\\Lenovo\\anaconda3\\lib\\site-packages\\gradio\\interface.py\", line 307, in run_prediction\n",
      "    prediction = predict_fn(*processed_input)\n",
      "  File \"<ipython-input-3-f9d94fe16654>\", line 3, in inference\n",
      "    df = pd.DataFrame([[age, s, ch, cardio]],\n",
      "NameError: name 'pd' is not defined\n",
      "[2021-09-12 11:30:33,420] ERROR in app: Exception on /api/predict/ [POST]\n",
      "Traceback (most recent call last):\n",
      "  File \"C:\\Users\\Lenovo\\anaconda3\\lib\\site-packages\\flask\\app.py\", line 2447, in wsgi_app\n",
      "    response = self.full_dispatch_request()\n",
      "  File \"C:\\Users\\Lenovo\\anaconda3\\lib\\site-packages\\flask\\app.py\", line 1952, in full_dispatch_request\n",
      "    rv = self.handle_user_exception(e)\n",
      "  File \"C:\\Users\\Lenovo\\anaconda3\\lib\\site-packages\\flask_cors\\extension.py\", line 165, in wrapped_function\n",
      "    return cors_after_request(app.make_response(f(*args, **kwargs)))\n",
      "  File \"C:\\Users\\Lenovo\\anaconda3\\lib\\site-packages\\flask\\app.py\", line 1821, in handle_user_exception\n",
      "    reraise(exc_type, exc_value, tb)\n",
      "  File \"C:\\Users\\Lenovo\\anaconda3\\lib\\site-packages\\flask\\_compat.py\", line 39, in reraise\n",
      "    raise value\n",
      "  File \"C:\\Users\\Lenovo\\anaconda3\\lib\\site-packages\\flask\\app.py\", line 1950, in full_dispatch_request\n",
      "    rv = self.dispatch_request()\n",
      "  File \"C:\\Users\\Lenovo\\anaconda3\\lib\\site-packages\\flask\\app.py\", line 1936, in dispatch_request\n",
      "    return self.view_functions[rule.endpoint](**req.view_args)\n",
      "  File \"C:\\Users\\Lenovo\\anaconda3\\lib\\site-packages\\gradio\\networking.py\", line 92, in wrapper\n",
      "    return func(*args, **kwargs)\n",
      "  File \"C:\\Users\\Lenovo\\anaconda3\\lib\\site-packages\\gradio\\networking.py\", line 180, in predict\n",
      "    prediction, durations = app.interface.process(raw_input)\n",
      "  File \"C:\\Users\\Lenovo\\anaconda3\\lib\\site-packages\\gradio\\interface.py\", line 334, in process\n",
      "    predictions, durations = self.run_prediction(processed_input, return_duration=True)\n",
      "  File \"C:\\Users\\Lenovo\\anaconda3\\lib\\site-packages\\gradio\\interface.py\", line 307, in run_prediction\n",
      "    prediction = predict_fn(*processed_input)\n",
      "  File \"<ipython-input-3-f9d94fe16654>\", line 3, in inference\n",
      "    df = pd.DataFrame([[age, s, ch, cardio]],\n",
      "NameError: name 'pd' is not defined\n",
      "[2021-09-12 11:30:33,434] ERROR in app: Exception on /api/predict/ [POST]\n",
      "Traceback (most recent call last):\n",
      "  File \"C:\\Users\\Lenovo\\anaconda3\\lib\\site-packages\\flask\\app.py\", line 2447, in wsgi_app\n",
      "    response = self.full_dispatch_request()\n",
      "  File \"C:\\Users\\Lenovo\\anaconda3\\lib\\site-packages\\flask\\app.py\", line 1952, in full_dispatch_request\n",
      "    rv = self.handle_user_exception(e)\n",
      "  File \"C:\\Users\\Lenovo\\anaconda3\\lib\\site-packages\\flask_cors\\extension.py\", line 165, in wrapped_function\n",
      "    return cors_after_request(app.make_response(f(*args, **kwargs)))\n",
      "  File \"C:\\Users\\Lenovo\\anaconda3\\lib\\site-packages\\flask\\app.py\", line 1821, in handle_user_exception\n",
      "    reraise(exc_type, exc_value, tb)\n",
      "  File \"C:\\Users\\Lenovo\\anaconda3\\lib\\site-packages\\flask\\_compat.py\", line 39, in reraise\n",
      "    raise value\n",
      "  File \"C:\\Users\\Lenovo\\anaconda3\\lib\\site-packages\\flask\\app.py\", line 1950, in full_dispatch_request\n",
      "    rv = self.dispatch_request()\n",
      "  File \"C:\\Users\\Lenovo\\anaconda3\\lib\\site-packages\\flask\\app.py\", line 1936, in dispatch_request\n",
      "    return self.view_functions[rule.endpoint](**req.view_args)\n",
      "  File \"C:\\Users\\Lenovo\\anaconda3\\lib\\site-packages\\gradio\\networking.py\", line 92, in wrapper\n",
      "    return func(*args, **kwargs)\n",
      "  File \"C:\\Users\\Lenovo\\anaconda3\\lib\\site-packages\\gradio\\networking.py\", line 180, in predict\n",
      "    prediction, durations = app.interface.process(raw_input)\n",
      "  File \"C:\\Users\\Lenovo\\anaconda3\\lib\\site-packages\\gradio\\interface.py\", line 334, in process\n",
      "    predictions, durations = self.run_prediction(processed_input, return_duration=True)\n",
      "  File \"C:\\Users\\Lenovo\\anaconda3\\lib\\site-packages\\gradio\\interface.py\", line 307, in run_prediction\n",
      "    prediction = predict_fn(*processed_input)\n",
      "  File \"<ipython-input-3-f9d94fe16654>\", line 3, in inference\n",
      "    df = pd.DataFrame([[age, s, ch, cardio]],\n",
      "NameError: name 'pd' is not defined\n",
      "[2021-09-12 11:30:33,442] ERROR in app: Exception on /api/predict/ [POST]\n",
      "Traceback (most recent call last):\n",
      "  File \"C:\\Users\\Lenovo\\anaconda3\\lib\\site-packages\\flask\\app.py\", line 2447, in wsgi_app\n",
      "    response = self.full_dispatch_request()\n",
      "  File \"C:\\Users\\Lenovo\\anaconda3\\lib\\site-packages\\flask\\app.py\", line 1952, in full_dispatch_request\n",
      "    rv = self.handle_user_exception(e)\n",
      "  File \"C:\\Users\\Lenovo\\anaconda3\\lib\\site-packages\\flask_cors\\extension.py\", line 165, in wrapped_function\n",
      "    return cors_after_request(app.make_response(f(*args, **kwargs)))\n",
      "  File \"C:\\Users\\Lenovo\\anaconda3\\lib\\site-packages\\flask\\app.py\", line 1821, in handle_user_exception\n",
      "    reraise(exc_type, exc_value, tb)\n",
      "  File \"C:\\Users\\Lenovo\\anaconda3\\lib\\site-packages\\flask\\_compat.py\", line 39, in reraise\n",
      "    raise value\n",
      "  File \"C:\\Users\\Lenovo\\anaconda3\\lib\\site-packages\\flask\\app.py\", line 1950, in full_dispatch_request\n",
      "    rv = self.dispatch_request()\n",
      "  File \"C:\\Users\\Lenovo\\anaconda3\\lib\\site-packages\\flask\\app.py\", line 1936, in dispatch_request\n",
      "    return self.view_functions[rule.endpoint](**req.view_args)\n",
      "  File \"C:\\Users\\Lenovo\\anaconda3\\lib\\site-packages\\gradio\\networking.py\", line 92, in wrapper\n",
      "    return func(*args, **kwargs)\n",
      "  File \"C:\\Users\\Lenovo\\anaconda3\\lib\\site-packages\\gradio\\networking.py\", line 180, in predict\n",
      "    prediction, durations = app.interface.process(raw_input)\n",
      "  File \"C:\\Users\\Lenovo\\anaconda3\\lib\\site-packages\\gradio\\interface.py\", line 334, in process\n",
      "    predictions, durations = self.run_prediction(processed_input, return_duration=True)\n",
      "  File \"C:\\Users\\Lenovo\\anaconda3\\lib\\site-packages\\gradio\\interface.py\", line 307, in run_prediction\n",
      "    prediction = predict_fn(*processed_input)\n",
      "  File \"<ipython-input-3-f9d94fe16654>\", line 3, in inference\n",
      "    df = pd.DataFrame([[age, s, ch, cardio]],\n",
      "NameError: name 'pd' is not defined\n",
      "[2021-09-12 11:30:44,020] ERROR in app: Exception on /api/predict/ [POST]\n",
      "Traceback (most recent call last):\n",
      "  File \"C:\\Users\\Lenovo\\anaconda3\\lib\\site-packages\\flask\\app.py\", line 2447, in wsgi_app\n",
      "    response = self.full_dispatch_request()\n",
      "  File \"C:\\Users\\Lenovo\\anaconda3\\lib\\site-packages\\flask\\app.py\", line 1952, in full_dispatch_request\n",
      "    rv = self.handle_user_exception(e)\n",
      "  File \"C:\\Users\\Lenovo\\anaconda3\\lib\\site-packages\\flask_cors\\extension.py\", line 165, in wrapped_function\n",
      "    return cors_after_request(app.make_response(f(*args, **kwargs)))\n",
      "  File \"C:\\Users\\Lenovo\\anaconda3\\lib\\site-packages\\flask\\app.py\", line 1821, in handle_user_exception\n",
      "    reraise(exc_type, exc_value, tb)\n",
      "  File \"C:\\Users\\Lenovo\\anaconda3\\lib\\site-packages\\flask\\_compat.py\", line 39, in reraise\n",
      "    raise value\n",
      "  File \"C:\\Users\\Lenovo\\anaconda3\\lib\\site-packages\\flask\\app.py\", line 1950, in full_dispatch_request\n",
      "    rv = self.dispatch_request()\n",
      "  File \"C:\\Users\\Lenovo\\anaconda3\\lib\\site-packages\\flask\\app.py\", line 1936, in dispatch_request\n",
      "    return self.view_functions[rule.endpoint](**req.view_args)\n",
      "  File \"C:\\Users\\Lenovo\\anaconda3\\lib\\site-packages\\gradio\\networking.py\", line 92, in wrapper\n",
      "    return func(*args, **kwargs)\n",
      "  File \"C:\\Users\\Lenovo\\anaconda3\\lib\\site-packages\\gradio\\networking.py\", line 180, in predict\n",
      "    prediction, durations = app.interface.process(raw_input)\n",
      "  File \"C:\\Users\\Lenovo\\anaconda3\\lib\\site-packages\\gradio\\interface.py\", line 334, in process\n",
      "    predictions, durations = self.run_prediction(processed_input, return_duration=True)\n",
      "  File \"C:\\Users\\Lenovo\\anaconda3\\lib\\site-packages\\gradio\\interface.py\", line 307, in run_prediction\n",
      "    prediction = predict_fn(*processed_input)\n",
      "  File \"<ipython-input-3-f9d94fe16654>\", line 3, in inference\n",
      "    df = pd.DataFrame([[age, s, ch, cardio]],\n",
      "NameError: name 'pd' is not defined\n"
     ]
    },
    {
     "name": "stderr",
     "output_type": "stream",
     "text": [
      "[2021-09-12 11:30:49,979] ERROR in app: Exception on /api/predict/ [POST]\n",
      "Traceback (most recent call last):\n",
      "  File \"C:\\Users\\Lenovo\\anaconda3\\lib\\site-packages\\flask\\app.py\", line 2447, in wsgi_app\n",
      "    response = self.full_dispatch_request()\n",
      "  File \"C:\\Users\\Lenovo\\anaconda3\\lib\\site-packages\\flask\\app.py\", line 1952, in full_dispatch_request\n",
      "    rv = self.handle_user_exception(e)\n",
      "  File \"C:\\Users\\Lenovo\\anaconda3\\lib\\site-packages\\flask_cors\\extension.py\", line 165, in wrapped_function\n",
      "    return cors_after_request(app.make_response(f(*args, **kwargs)))\n",
      "  File \"C:\\Users\\Lenovo\\anaconda3\\lib\\site-packages\\flask\\app.py\", line 1821, in handle_user_exception\n",
      "    reraise(exc_type, exc_value, tb)\n",
      "  File \"C:\\Users\\Lenovo\\anaconda3\\lib\\site-packages\\flask\\_compat.py\", line 39, in reraise\n",
      "    raise value\n",
      "  File \"C:\\Users\\Lenovo\\anaconda3\\lib\\site-packages\\flask\\app.py\", line 1950, in full_dispatch_request\n",
      "    rv = self.dispatch_request()\n",
      "  File \"C:\\Users\\Lenovo\\anaconda3\\lib\\site-packages\\flask\\app.py\", line 1936, in dispatch_request\n",
      "    return self.view_functions[rule.endpoint](**req.view_args)\n",
      "  File \"C:\\Users\\Lenovo\\anaconda3\\lib\\site-packages\\gradio\\networking.py\", line 92, in wrapper\n",
      "    return func(*args, **kwargs)\n",
      "  File \"C:\\Users\\Lenovo\\anaconda3\\lib\\site-packages\\gradio\\networking.py\", line 180, in predict\n",
      "    prediction, durations = app.interface.process(raw_input)\n",
      "  File \"C:\\Users\\Lenovo\\anaconda3\\lib\\site-packages\\gradio\\interface.py\", line 334, in process\n",
      "    predictions, durations = self.run_prediction(processed_input, return_duration=True)\n",
      "  File \"C:\\Users\\Lenovo\\anaconda3\\lib\\site-packages\\gradio\\interface.py\", line 307, in run_prediction\n",
      "    prediction = predict_fn(*processed_input)\n",
      "  File \"<ipython-input-3-f9d94fe16654>\", line 3, in inference\n",
      "    df = pd.DataFrame([[age, s, ch, cardio]],\n",
      "NameError: name 'pd' is not defined\n",
      "[2021-09-12 11:30:51,970] ERROR in app: Exception on /api/predict/ [POST]\n",
      "Traceback (most recent call last):\n",
      "  File \"C:\\Users\\Lenovo\\anaconda3\\lib\\site-packages\\flask\\app.py\", line 2447, in wsgi_app\n",
      "    response = self.full_dispatch_request()\n",
      "  File \"C:\\Users\\Lenovo\\anaconda3\\lib\\site-packages\\flask\\app.py\", line 1952, in full_dispatch_request\n",
      "    rv = self.handle_user_exception(e)\n",
      "  File \"C:\\Users\\Lenovo\\anaconda3\\lib\\site-packages\\flask_cors\\extension.py\", line 165, in wrapped_function\n",
      "    return cors_after_request(app.make_response(f(*args, **kwargs)))\n",
      "  File \"C:\\Users\\Lenovo\\anaconda3\\lib\\site-packages\\flask\\app.py\", line 1821, in handle_user_exception\n",
      "    reraise(exc_type, exc_value, tb)\n",
      "  File \"C:\\Users\\Lenovo\\anaconda3\\lib\\site-packages\\flask\\_compat.py\", line 39, in reraise\n",
      "    raise value\n",
      "  File \"C:\\Users\\Lenovo\\anaconda3\\lib\\site-packages\\flask\\app.py\", line 1950, in full_dispatch_request\n",
      "    rv = self.dispatch_request()\n",
      "  File \"C:\\Users\\Lenovo\\anaconda3\\lib\\site-packages\\flask\\app.py\", line 1936, in dispatch_request\n",
      "    return self.view_functions[rule.endpoint](**req.view_args)\n",
      "  File \"C:\\Users\\Lenovo\\anaconda3\\lib\\site-packages\\gradio\\networking.py\", line 92, in wrapper\n",
      "    return func(*args, **kwargs)\n",
      "  File \"C:\\Users\\Lenovo\\anaconda3\\lib\\site-packages\\gradio\\networking.py\", line 180, in predict\n",
      "    prediction, durations = app.interface.process(raw_input)\n",
      "  File \"C:\\Users\\Lenovo\\anaconda3\\lib\\site-packages\\gradio\\interface.py\", line 334, in process\n",
      "    predictions, durations = self.run_prediction(processed_input, return_duration=True)\n",
      "  File \"C:\\Users\\Lenovo\\anaconda3\\lib\\site-packages\\gradio\\interface.py\", line 307, in run_prediction\n",
      "    prediction = predict_fn(*processed_input)\n",
      "  File \"<ipython-input-3-f9d94fe16654>\", line 3, in inference\n",
      "    df = pd.DataFrame([[age, s, ch, cardio]],\n",
      "NameError: name 'pd' is not defined\n"
     ]
    }
   ],
   "source": [
    "def inference(age, sex, ch, cardio):\n",
    "    s = 0 if sex=='female' else 1\n",
    "    df = pd.DataFrame([[age, s, ch, cardio]], \n",
    "                      columns=['Age', 'Sex', 'Cholestoral (in mg/dl)', \n",
    "                               'Resting electrocardiographic results'])\n",
    "    df = st.transform(df)\n",
    "    pred = trainedmodel.predict_proba(df)[0]\n",
    "    res = {'No Heart Desease': pred[0], 'Has Heart Desease': pred[1]}\n",
    "    return res\n",
    "\n",
    "sex = gr.inputs.Radio(['female', 'male'], label=\"Sex\")\n",
    "age = gr.inputs.Slider(minimum=1, maximum=100, default=22, label=\"Age\")\n",
    "ch = gr.inputs.Slider(minimum=120, maximum=560, default=200, label=\"Cholestoral (in mg/dl)\")\n",
    "cardio = gr.inputs.Radio([0, 1, 2], label=\"Resting electrocardiographic results\")\n",
    "\n",
    "gr.Interface(inference, [age, sex, ch, cardio], \"label\", live=True).launch(share=True) #, debug=True Use in Colab"
   ]
  },
  {
   "cell_type": "code",
   "execution_count": null,
   "metadata": {},
   "outputs": [],
   "source": []
  }
 ],
 "metadata": {
  "kernelspec": {
   "display_name": "Python 3",
   "language": "python",
   "name": "python3"
  },
  "language_info": {
   "codemirror_mode": {
    "name": "ipython",
    "version": 3
   },
   "file_extension": ".py",
   "mimetype": "text/x-python",
   "name": "python",
   "nbconvert_exporter": "python",
   "pygments_lexer": "ipython3",
   "version": "3.8.5"
  }
 },
 "nbformat": 4,
 "nbformat_minor": 4
}
